Unknown command: 'run_gunicorn'
Type 'manage.py help' for usage.
Unknown command: 'run_gunicorn'
Type 'manage.py help' for usage.
Unknown command: 'run_gunicorn'
Type 'manage.py help' for usage.
Unknown command: 'run_gunicorn'
Type 'manage.py help' for usage.
Unknown command: 'run_gunicorn'
Type 'manage.py help' for usage.
Unknown command: 'run_gunicorn'
Type 'manage.py help' for usage.
Unknown command: 'run_gunicorn'
Type 'manage.py help' for usage.
Unknown command: 'run_gunicorn'
Type 'manage.py help' for usage.
Unknown command: 'run_gunicorn'
Type 'manage.py help' for usage.
Unknown command: 'run_gunicorn'
Type 'manage.py help' for usage.
Unknown command: 'run_gunicorn'
Type 'manage.py help' for usage.
Unknown command: 'run_gunicorn'
Type 'manage.py help' for usage.
Unknown command: 'run_gunicorn'
Type 'manage.py help' for usage.
2014-01-31 04:57:26 [15745] [INFO] Starting gunicorn 18.0
2014-01-31 04:57:26 [15745] [INFO] Listening at: http://127.0.0.1:8008 (15745)
2014-01-31 04:57:26 [15745] [INFO] Using worker: sync
2014-01-31 04:57:26 [15750] [INFO] Booting worker with pid: 15750
2014-01-31 04:57:26 [15750] [ERROR] Exception in worker process:
Traceback (most recent call last):
  File "/home/comunidad/local/lib/python2.7/site-packages/gunicorn/arbiter.py", line 495, in spawn_worker
    worker.init_process()
  File "/home/comunidad/local/lib/python2.7/site-packages/gunicorn/workers/base.py", line 106, in init_process
    self.wsgi = self.app.wsgi()
  File "/home/comunidad/local/lib/python2.7/site-packages/gunicorn/app/base.py", line 114, in wsgi
    self.callable = self.load()
  File "/home/comunidad/local/lib/python2.7/site-packages/gunicorn/app/djangoapp.py", line 142, in load
    return mod.make_command_wsgi_application(self.admin_media_path)
  File "/home/comunidad/local/lib/python2.7/site-packages/gunicorn/app/django_wsgi.py", line 113, in make_command_wsgi_application
    reload_django_settings()
  File "/home/comunidad/local/lib/python2.7/site-packages/gunicorn/app/django_wsgi.py", line 109, in reload_django_settings
    logging_config_func(settings.LOGGING)
  File "/usr/lib/python2.7/logging/config.py", line 803, in dictConfig
    dictConfigClass(config).configure()
  File "/usr/lib/python2.7/logging/config.py", line 509, in configure
    raise ValueError("dictionary doesn't specify a version")
ValueError: dictionary doesn't specify a version
Traceback (most recent call last):
  File "/home/comunidad/local/lib/python2.7/site-packages/gunicorn/arbiter.py", line 495, in spawn_worker
    worker.init_process()
  File "/home/comunidad/local/lib/python2.7/site-packages/gunicorn/workers/base.py", line 106, in init_process
    self.wsgi = self.app.wsgi()
  File "/home/comunidad/local/lib/python2.7/site-packages/gunicorn/app/base.py", line 114, in wsgi
    self.callable = self.load()
  File "/home/comunidad/local/lib/python2.7/site-packages/gunicorn/app/djangoapp.py", line 142, in load
    return mod.make_command_wsgi_application(self.admin_media_path)
  File "/home/comunidad/local/lib/python2.7/site-packages/gunicorn/app/django_wsgi.py", line 113, in make_command_wsgi_application
    reload_django_settings()
  File "/home/comunidad/local/lib/python2.7/site-packages/gunicorn/app/django_wsgi.py", line 109, in reload_django_settings
    logging_config_func(settings.LOGGING)
  File "/usr/lib/python2.7/logging/config.py", line 803, in dictConfig
    dictConfigClass(config).configure()
  File "/usr/lib/python2.7/logging/config.py", line 509, in configure
    raise ValueError("dictionary doesn't specify a version")
ValueError: dictionary doesn't specify a version
2014-01-31 04:57:26 [15750] [INFO] Worker exiting (pid: 15750)
2014-01-31 04:57:26 [15751] [INFO] Booting worker with pid: 15751
2014-01-31 04:57:26 [15751] [ERROR] Exception in worker process:
Traceback (most recent call last):
  File "/home/comunidad/local/lib/python2.7/site-packages/gunicorn/arbiter.py", line 495, in spawn_worker
    worker.init_process()
  File "/home/comunidad/local/lib/python2.7/site-packages/gunicorn/workers/base.py", line 106, in init_process
    self.wsgi = self.app.wsgi()
  File "/home/comunidad/local/lib/python2.7/site-packages/gunicorn/app/base.py", line 114, in wsgi
    self.callable = self.load()
  File "/home/comunidad/local/lib/python2.7/site-packages/gunicorn/app/djangoapp.py", line 142, in load
    return mod.make_command_wsgi_application(self.admin_media_path)
  File "/home/comunidad/local/lib/python2.7/site-packages/gunicorn/app/django_wsgi.py", line 113, in make_command_wsgi_application
    reload_django_settings()
  File "/home/comunidad/local/lib/python2.7/site-packages/gunicorn/app/django_wsgi.py", line 109, in reload_django_settings
    logging_config_func(settings.LOGGING)
  File "/usr/lib/python2.7/logging/config.py", line 803, in dictConfig
    dictConfigClass(config).configure()
  File "/usr/lib/python2.7/logging/config.py", line 509, in configure
    raise ValueError("dictionary doesn't specify a version")
ValueError: dictionary doesn't specify a version
Traceback (most recent call last):
  File "/home/comunidad/local/lib/python2.7/site-packages/gunicorn/arbiter.py", line 495, in spawn_worker
    worker.init_process()
  File "/home/comunidad/local/lib/python2.7/site-packages/gunicorn/workers/base.py", line 106, in init_process
    self.wsgi = self.app.wsgi()
  File "/home/comunidad/local/lib/python2.7/site-packages/gunicorn/app/base.py", line 114, in wsgi
    self.callable = self.load()
  File "/home/comunidad/local/lib/python2.7/site-packages/gunicorn/app/djangoapp.py", line 142, in load
    return mod.make_command_wsgi_application(self.admin_media_path)
  File "/home/comunidad/local/lib/python2.7/site-packages/gunicorn/app/django_wsgi.py", line 113, in make_command_wsgi_application
    reload_django_settings()
  File "/home/comunidad/local/lib/python2.7/site-packages/gunicorn/app/django_wsgi.py", line 109, in reload_django_settings
    logging_config_func(settings.LOGGING)
  File "/usr/lib/python2.7/logging/config.py", line 803, in dictConfig
    dictConfigClass(config).configure()
  File "/usr/lib/python2.7/logging/config.py", line 509, in configure
    raise ValueError("dictionary doesn't specify a version")
ValueError: dictionary doesn't specify a version
2014-01-31 04:57:26 [15751] [INFO] Worker exiting (pid: 15751)
2014-01-31 04:57:26 [15752] [INFO] Booting worker with pid: 15752
2014-01-31 04:57:26 [15752] [ERROR] Exception in worker process:
Traceback (most recent call last):
  File "/home/comunidad/local/lib/python2.7/site-packages/gunicorn/arbiter.py", line 495, in spawn_worker
    worker.init_process()
  File "/home/comunidad/local/lib/python2.7/site-packages/gunicorn/workers/base.py", line 106, in init_process
    self.wsgi = self.app.wsgi()
  File "/home/comunidad/local/lib/python2.7/site-packages/gunicorn/app/base.py", line 114, in wsgi
    self.callable = self.load()
  File "/home/comunidad/local/lib/python2.7/site-packages/gunicorn/app/djangoapp.py", line 142, in load
    return mod.make_command_wsgi_application(self.admin_media_path)
  File "/home/comunidad/local/lib/python2.7/site-packages/gunicorn/app/django_wsgi.py", line 113, in make_command_wsgi_application
    reload_django_settings()
  File "/home/comunidad/local/lib/python2.7/site-packages/gunicorn/app/django_wsgi.py", line 109, in reload_django_settings
    logging_config_func(settings.LOGGING)
  File "/usr/lib/python2.7/logging/config.py", line 803, in dictConfig
    dictConfigClass(config).configure()
  File "/usr/lib/python2.7/logging/config.py", line 509, in configure
    raise ValueError("dictionary doesn't specify a version")
ValueError: dictionary doesn't specify a version
Traceback (most recent call last):
  File "/home/comunidad/local/lib/python2.7/site-packages/gunicorn/arbiter.py", line 495, in spawn_worker
    worker.init_process()
  File "/home/comunidad/local/lib/python2.7/site-packages/gunicorn/workers/base.py", line 106, in init_process
    self.wsgi = self.app.wsgi()
  File "/home/comunidad/local/lib/python2.7/site-packages/gunicorn/app/base.py", line 114, in wsgi
    self.callable = self.load()
  File "/home/comunidad/local/lib/python2.7/site-packages/gunicorn/app/djangoapp.py", line 142, in load
    return mod.make_command_wsgi_application(self.admin_media_path)
  File "/home/comunidad/local/lib/python2.7/site-packages/gunicorn/app/django_wsgi.py", line 113, in make_command_wsgi_application
    reload_django_settings()
  File "/home/comunidad/local/lib/python2.7/site-packages/gunicorn/app/django_wsgi.py", line 109, in reload_django_settings
    logging_config_func(settings.LOGGING)
  File "/usr/lib/python2.7/logging/config.py", line 803, in dictConfig
    dictConfigClass(config).configure()
  File "/usr/lib/python2.7/logging/config.py", line 509, in configure
    raise ValueError("dictionary doesn't specify a version")
ValueError: dictionary doesn't specify a version
2014-01-31 04:57:26 [15752] [INFO] Worker exiting (pid: 15752)
2014-01-31 04:57:26 [15753] [INFO] Booting worker with pid: 15753
2014-01-31 04:57:26 [15753] [ERROR] Exception in worker process:
Traceback (most recent call last):
  File "/home/comunidad/local/lib/python2.7/site-packages/gunicorn/arbiter.py", line 495, in spawn_worker
    worker.init_process()
  File "/home/comunidad/local/lib/python2.7/site-packages/gunicorn/workers/base.py", line 106, in init_process
    self.wsgi = self.app.wsgi()
  File "/home/comunidad/local/lib/python2.7/site-packages/gunicorn/app/base.py", line 114, in wsgi
    self.callable = self.load()
  File "/home/comunidad/local/lib/python2.7/site-packages/gunicorn/app/djangoapp.py", line 142, in load
    return mod.make_command_wsgi_application(self.admin_media_path)
  File "/home/comunidad/local/lib/python2.7/site-packages/gunicorn/app/django_wsgi.py", line 113, in make_command_wsgi_application
    reload_django_settings()
  File "/home/comunidad/local/lib/python2.7/site-packages/gunicorn/app/django_wsgi.py", line 109, in reload_django_settings
    logging_config_func(settings.LOGGING)
  File "/usr/lib/python2.7/logging/config.py", line 803, in dictConfig
    dictConfigClass(config).configure()
  File "/usr/lib/python2.7/logging/config.py", line 509, in configure
    raise ValueError("dictionary doesn't specify a version")
ValueError: dictionary doesn't specify a version
Traceback (most recent call last):
  File "/home/comunidad/local/lib/python2.7/site-packages/gunicorn/arbiter.py", line 495, in spawn_worker
    worker.init_process()
  File "/home/comunidad/local/lib/python2.7/site-packages/gunicorn/workers/base.py", line 106, in init_process
    self.wsgi = self.app.wsgi()
  File "/home/comunidad/local/lib/python2.7/site-packages/gunicorn/app/base.py", line 114, in wsgi
    self.callable = self.load()
  File "/home/comunidad/local/lib/python2.7/site-packages/gunicorn/app/djangoapp.py", line 142, in load
    return mod.make_command_wsgi_application(self.admin_media_path)
  File "/home/comunidad/local/lib/python2.7/site-packages/gunicorn/app/django_wsgi.py", line 113, in make_command_wsgi_application
    reload_django_settings()
  File "/home/comunidad/local/lib/python2.7/site-packages/gunicorn/app/django_wsgi.py", line 109, in reload_django_settings
    logging_config_func(settings.LOGGING)
  File "/usr/lib/python2.7/logging/config.py", line 803, in dictConfig
    dictConfigClass(config).configure()
  File "/usr/lib/python2.7/logging/config.py", line 509, in configure
    raise ValueError("dictionary doesn't specify a version")
ValueError: dictionary doesn't specify a version
2014-01-31 04:57:26 [15753] [INFO] Worker exiting (pid: 15753)
2014-01-31 04:57:26 [15754] [INFO] Booting worker with pid: 15754
2014-01-31 04:57:26 [15754] [ERROR] Exception in worker process:
Traceback (most recent call last):
  File "/home/comunidad/local/lib/python2.7/site-packages/gunicorn/arbiter.py", line 495, in spawn_worker
    worker.init_process()
  File "/home/comunidad/local/lib/python2.7/site-packages/gunicorn/workers/base.py", line 106, in init_process
    self.wsgi = self.app.wsgi()
  File "/home/comunidad/local/lib/python2.7/site-packages/gunicorn/app/base.py", line 114, in wsgi
    self.callable = self.load()
  File "/home/comunidad/local/lib/python2.7/site-packages/gunicorn/app/djangoapp.py", line 142, in load
    return mod.make_command_wsgi_application(self.admin_media_path)
  File "/home/comunidad/local/lib/python2.7/site-packages/gunicorn/app/django_wsgi.py", line 113, in make_command_wsgi_application
    reload_django_settings()
  File "/home/comunidad/local/lib/python2.7/site-packages/gunicorn/app/django_wsgi.py", line 109, in reload_django_settings
    logging_config_func(settings.LOGGING)
  File "/usr/lib/python2.7/logging/config.py", line 803, in dictConfig
    dictConfigClass(config).configure()
  File "/usr/lib/python2.7/logging/config.py", line 509, in configure
    raise ValueError("dictionary doesn't specify a version")
ValueError: dictionary doesn't specify a version
Traceback (most recent call last):
  File "/home/comunidad/local/lib/python2.7/site-packages/gunicorn/arbiter.py", line 495, in spawn_worker
    worker.init_process()
  File "/home/comunidad/local/lib/python2.7/site-packages/gunicorn/workers/base.py", line 106, in init_process
    self.wsgi = self.app.wsgi()
  File "/home/comunidad/local/lib/python2.7/site-packages/gunicorn/app/base.py", line 114, in wsgi
    self.callable = self.load()
  File "/home/comunidad/local/lib/python2.7/site-packages/gunicorn/app/djangoapp.py", line 142, in load
    return mod.make_command_wsgi_application(self.admin_media_path)
  File "/home/comunidad/local/lib/python2.7/site-packages/gunicorn/app/django_wsgi.py", line 113, in make_command_wsgi_application
    reload_django_settings()
  File "/home/comunidad/local/lib/python2.7/site-packages/gunicorn/app/django_wsgi.py", line 109, in reload_django_settings
    logging_config_func(settings.LOGGING)
  File "/usr/lib/python2.7/logging/config.py", line 803, in dictConfig
    dictConfigClass(config).configure()
  File "/usr/lib/python2.7/logging/config.py", line 509, in configure
    raise ValueError("dictionary doesn't specify a version")
ValueError: dictionary doesn't specify a version
2014-01-31 04:57:26 [15754] [INFO] Worker exiting (pid: 15754)
2014-01-31 04:57:26 [15755] [INFO] Booting worker with pid: 15755
2014-01-31 04:57:26 [15755] [ERROR] Exception in worker process:
Traceback (most recent call last):
  File "/home/comunidad/local/lib/python2.7/site-packages/gunicorn/arbiter.py", line 495, in spawn_worker
    worker.init_process()
  File "/home/comunidad/local/lib/python2.7/site-packages/gunicorn/workers/base.py", line 106, in init_process
    self.wsgi = self.app.wsgi()
  File "/home/comunidad/local/lib/python2.7/site-packages/gunicorn/app/base.py", line 114, in wsgi
    self.callable = self.load()
  File "/home/comunidad/local/lib/python2.7/site-packages/gunicorn/app/djangoapp.py", line 142, in load
    return mod.make_command_wsgi_application(self.admin_media_path)
  File "/home/comunidad/local/lib/python2.7/site-packages/gunicorn/app/django_wsgi.py", line 113, in make_command_wsgi_application
    reload_django_settings()
  File "/home/comunidad/local/lib/python2.7/site-packages/gunicorn/app/django_wsgi.py", line 109, in reload_django_settings
    logging_config_func(settings.LOGGING)
  File "/usr/lib/python2.7/logging/config.py", line 803, in dictConfig
    dictConfigClass(config).configure()
  File "/usr/lib/python2.7/logging/config.py", line 509, in configure
    raise ValueError("dictionary doesn't specify a version")
ValueError: dictionary doesn't specify a version
Traceback (most recent call last):
  File "/home/comunidad/local/lib/python2.7/site-packages/gunicorn/arbiter.py", line 495, in spawn_worker
    worker.init_process()
  File "/home/comunidad/local/lib/python2.7/site-packages/gunicorn/workers/base.py", line 106, in init_process
    self.wsgi = self.app.wsgi()
  File "/home/comunidad/local/lib/python2.7/site-packages/gunicorn/app/base.py", line 114, in wsgi
    self.callable = self.load()
  File "/home/comunidad/local/lib/python2.7/site-packages/gunicorn/app/djangoapp.py", line 142, in load
    return mod.make_command_wsgi_application(self.admin_media_path)
  File "/home/comunidad/local/lib/python2.7/site-packages/gunicorn/app/django_wsgi.py", line 113, in make_command_wsgi_application
    reload_django_settings()
  File "/home/comunidad/local/lib/python2.7/site-packages/gunicorn/app/django_wsgi.py", line 109, in reload_django_settings
    logging_config_func(settings.LOGGING)
  File "/usr/lib/python2.7/logging/config.py", line 803, in dictConfig
    dictConfigClass(config).configure()
  File "/usr/lib/python2.7/logging/config.py", line 509, in configure
    raise ValueError("dictionary doesn't specify a version")
ValueError: dictionary doesn't specify a version
2014-01-31 04:57:26 [15755] [INFO] Worker exiting (pid: 15755)
2014-01-31 04:57:26 [15756] [INFO] Booting worker with pid: 15756
2014-01-31 04:57:26 [15756] [ERROR] Exception in worker process:
Traceback (most recent call last):
  File "/home/comunidad/local/lib/python2.7/site-packages/gunicorn/arbiter.py", line 495, in spawn_worker
    worker.init_process()
  File "/home/comunidad/local/lib/python2.7/site-packages/gunicorn/workers/base.py", line 106, in init_process
    self.wsgi = self.app.wsgi()
  File "/home/comunidad/local/lib/python2.7/site-packages/gunicorn/app/base.py", line 114, in wsgi
    self.callable = self.load()
  File "/home/comunidad/local/lib/python2.7/site-packages/gunicorn/app/djangoapp.py", line 142, in load
    return mod.make_command_wsgi_application(self.admin_media_path)
  File "/home/comunidad/local/lib/python2.7/site-packages/gunicorn/app/django_wsgi.py", line 113, in make_command_wsgi_application
    reload_django_settings()
  File "/home/comunidad/local/lib/python2.7/site-packages/gunicorn/app/django_wsgi.py", line 109, in reload_django_settings
    logging_config_func(settings.LOGGING)
  File "/usr/lib/python2.7/logging/config.py", line 803, in dictConfig
    dictConfigClass(config).configure()
  File "/usr/lib/python2.7/logging/config.py", line 509, in configure
    raise ValueError("dictionary doesn't specify a version")
ValueError: dictionary doesn't specify a version
Traceback (most recent call last):
  File "/home/comunidad/local/lib/python2.7/site-packages/gunicorn/arbiter.py", line 495, in spawn_worker
    worker.init_process()
  File "/home/comunidad/local/lib/python2.7/site-packages/gunicorn/workers/base.py", line 106, in init_process
    self.wsgi = self.app.wsgi()
  File "/home/comunidad/local/lib/python2.7/site-packages/gunicorn/app/base.py", line 114, in wsgi
    self.callable = self.load()
  File "/home/comunidad/local/lib/python2.7/site-packages/gunicorn/app/djangoapp.py", line 142, in load
    return mod.make_command_wsgi_application(self.admin_media_path)
  File "/home/comunidad/local/lib/python2.7/site-packages/gunicorn/app/django_wsgi.py", line 113, in make_command_wsgi_application
    reload_django_settings()
  File "/home/comunidad/local/lib/python2.7/site-packages/gunicorn/app/django_wsgi.py", line 109, in reload_django_settings
    logging_config_func(settings.LOGGING)
  File "/usr/lib/python2.7/logging/config.py", line 803, in dictConfig
    dictConfigClass(config).configure()
  File "/usr/lib/python2.7/logging/config.py", line 509, in configure
    raise ValueError("dictionary doesn't specify a version")
ValueError: dictionary doesn't specify a version
2014-01-31 04:57:26 [15756] [INFO] Worker exiting (pid: 15756)
2014-01-31 04:57:26 [15757] [INFO] Booting worker with pid: 15757
2014-01-31 04:57:26 [15757] [ERROR] Exception in worker process:
Traceback (most recent call last):
  File "/home/comunidad/local/lib/python2.7/site-packages/gunicorn/arbiter.py", line 495, in spawn_worker
    worker.init_process()
  File "/home/comunidad/local/lib/python2.7/site-packages/gunicorn/workers/base.py", line 106, in init_process
    self.wsgi = self.app.wsgi()
  File "/home/comunidad/local/lib/python2.7/site-packages/gunicorn/app/base.py", line 114, in wsgi
    self.callable = self.load()
  File "/home/comunidad/local/lib/python2.7/site-packages/gunicorn/app/djangoapp.py", line 142, in load
    return mod.make_command_wsgi_application(self.admin_media_path)
  File "/home/comunidad/local/lib/python2.7/site-packages/gunicorn/app/django_wsgi.py", line 113, in make_command_wsgi_application
    reload_django_settings()
  File "/home/comunidad/local/lib/python2.7/site-packages/gunicorn/app/django_wsgi.py", line 109, in reload_django_settings
    logging_config_func(settings.LOGGING)
  File "/usr/lib/python2.7/logging/config.py", line 803, in dictConfig
    dictConfigClass(config).configure()
  File "/usr/lib/python2.7/logging/config.py", line 509, in configure
    raise ValueError("dictionary doesn't specify a version")
ValueError: dictionary doesn't specify a version
Traceback (most recent call last):
  File "/home/comunidad/local/lib/python2.7/site-packages/gunicorn/arbiter.py", line 495, in spawn_worker
    worker.init_process()
  File "/home/comunidad/local/lib/python2.7/site-packages/gunicorn/workers/base.py", line 106, in init_process
    self.wsgi = self.app.wsgi()
  File "/home/comunidad/local/lib/python2.7/site-packages/gunicorn/app/base.py", line 114, in wsgi
    self.callable = self.load()
  File "/home/comunidad/local/lib/python2.7/site-packages/gunicorn/app/djangoapp.py", line 142, in load
    return mod.make_command_wsgi_application(self.admin_media_path)
  File "/home/comunidad/local/lib/python2.7/site-packages/gunicorn/app/django_wsgi.py", line 113, in make_command_wsgi_application
    reload_django_settings()
  File "/home/comunidad/local/lib/python2.7/site-packages/gunicorn/app/django_wsgi.py", line 109, in reload_django_settings
    logging_config_func(settings.LOGGING)
  File "/usr/lib/python2.7/logging/config.py", line 803, in dictConfig
    dictConfigClass(config).configure()
  File "/usr/lib/python2.7/logging/config.py", line 509, in configure
    raise ValueError("dictionary doesn't specify a version")
ValueError: dictionary doesn't specify a version
2014-01-31 04:57:26 [15757] [INFO] Worker exiting (pid: 15757)
Traceback (most recent call last):
  File "/home/comunidad/django-node.js-nginx/website/manage.py", line 10, in <module>
    execute_from_command_line(sys.argv)
  File "/home/comunidad/local/lib/python2.7/site-packages/django/core/management/__init__.py", line 399, in execute_from_command_line
    utility.execute()
  File "/home/comunidad/local/lib/python2.7/site-packages/django/core/management/__init__.py", line 392, in execute
    self.fetch_command(subcommand).run_from_argv(self.argv)
  File "/home/comunidad/local/lib/python2.7/site-packages/django/core/management/base.py", line 242, in run_from_argv
    self.execute(*args, **options.__dict__)
  File "/home/comunidad/local/lib/python2.7/site-packages/django/core/management/base.py", line 285, in execute
    output = self.handle(*args, **options)
  File "/home/comunidad/local/lib/python2.7/site-packages/gunicorn/management/commands/run_gunicorn.py", line 101, in handle
    DjangoApplicationCommand(options, admin_media_path).run()
  File "/home/comunidad/local/lib/python2.7/site-packages/gunicorn/app/base.py", line 143, in run
    Arbiter(self).run()
  File "/home/comunidad/local/lib/python2.7/site-packages/gunicorn/arbiter.py", line 203, in run
    self.halt(reason=inst.reason, exit_status=inst.exit_status)
  File "/home/comunidad/local/lib/python2.7/site-packages/gunicorn/arbiter.py", line 298, in halt
    self.stop()
  File "/home/comunidad/local/lib/python2.7/site-packages/gunicorn/arbiter.py", line 341, in stop
    self.reap_workers()
  File "/home/comunidad/local/lib/python2.7/site-packages/gunicorn/arbiter.py", line 452, in reap_workers
    raise HaltServer(reason, self.WORKER_BOOT_ERROR)
gunicorn.errors.HaltServer: <HaltServer 'Worker failed to boot.' 3>
2014-01-31 04:57:28 [15762] [INFO] Starting gunicorn 18.0
2014-01-31 04:57:28 [15762] [INFO] Listening at: http://127.0.0.1:8008 (15762)
2014-01-31 04:57:28 [15762] [INFO] Using worker: sync
2014-01-31 04:57:28 [15767] [INFO] Booting worker with pid: 15767
2014-01-31 04:57:28 [15767] [ERROR] Exception in worker process:
Traceback (most recent call last):
  File "/home/comunidad/local/lib/python2.7/site-packages/gunicorn/arbiter.py", line 495, in spawn_worker
    worker.init_process()
  File "/home/comunidad/local/lib/python2.7/site-packages/gunicorn/workers/base.py", line 106, in init_process
    self.wsgi = self.app.wsgi()
  File "/home/comunidad/local/lib/python2.7/site-packages/gunicorn/app/base.py", line 114, in wsgi
    self.callable = self.load()
  File "/home/comunidad/local/lib/python2.7/site-packages/gunicorn/app/djangoapp.py", line 142, in load
    return mod.make_command_wsgi_application(self.admin_media_path)
  File "/home/comunidad/local/lib/python2.7/site-packages/gunicorn/app/django_wsgi.py", line 113, in make_command_wsgi_application
    reload_django_settings()
  File "/home/comunidad/local/lib/python2.7/site-packages/gunicorn/app/django_wsgi.py", line 109, in reload_django_settings
    logging_config_func(settings.LOGGING)
  File "/usr/lib/python2.7/logging/config.py", line 803, in dictConfig
    dictConfigClass(config).configure()
  File "/usr/lib/python2.7/logging/config.py", line 509, in configure
    raise ValueError("dictionary doesn't specify a version")
ValueError: dictionary doesn't specify a version
Traceback (most recent call last):
  File "/home/comunidad/local/lib/python2.7/site-packages/gunicorn/arbiter.py", line 495, in spawn_worker
    worker.init_process()
  File "/home/comunidad/local/lib/python2.7/site-packages/gunicorn/workers/base.py", line 106, in init_process
    self.wsgi = self.app.wsgi()
  File "/home/comunidad/local/lib/python2.7/site-packages/gunicorn/app/base.py", line 114, in wsgi
    self.callable = self.load()
  File "/home/comunidad/local/lib/python2.7/site-packages/gunicorn/app/djangoapp.py", line 142, in load
    return mod.make_command_wsgi_application(self.admin_media_path)
  File "/home/comunidad/local/lib/python2.7/site-packages/gunicorn/app/django_wsgi.py", line 113, in make_command_wsgi_application
    reload_django_settings()
  File "/home/comunidad/local/lib/python2.7/site-packages/gunicorn/app/django_wsgi.py", line 109, in reload_django_settings
    logging_config_func(settings.LOGGING)
  File "/usr/lib/python2.7/logging/config.py", line 803, in dictConfig
    dictConfigClass(config).configure()
  File "/usr/lib/python2.7/logging/config.py", line 509, in configure
    raise ValueError("dictionary doesn't specify a version")
ValueError: dictionary doesn't specify a version
2014-01-31 04:57:28 [15767] [INFO] Worker exiting (pid: 15767)
2014-01-31 04:57:28 [15768] [INFO] Booting worker with pid: 15768
2014-01-31 04:57:28 [15768] [ERROR] Exception in worker process:
Traceback (most recent call last):
  File "/home/comunidad/local/lib/python2.7/site-packages/gunicorn/arbiter.py", line 495, in spawn_worker
    worker.init_process()
  File "/home/comunidad/local/lib/python2.7/site-packages/gunicorn/workers/base.py", line 106, in init_process
    self.wsgi = self.app.wsgi()
  File "/home/comunidad/local/lib/python2.7/site-packages/gunicorn/app/base.py", line 114, in wsgi
    self.callable = self.load()
  File "/home/comunidad/local/lib/python2.7/site-packages/gunicorn/app/djangoapp.py", line 142, in load
    return mod.make_command_wsgi_application(self.admin_media_path)
  File "/home/comunidad/local/lib/python2.7/site-packages/gunicorn/app/django_wsgi.py", line 113, in make_command_wsgi_application
    reload_django_settings()
  File "/home/comunidad/local/lib/python2.7/site-packages/gunicorn/app/django_wsgi.py", line 109, in reload_django_settings
    logging_config_func(settings.LOGGING)
  File "/usr/lib/python2.7/logging/config.py", line 803, in dictConfig
    dictConfigClass(config).configure()
  File "/usr/lib/python2.7/logging/config.py", line 509, in configure
    raise ValueError("dictionary doesn't specify a version")
ValueError: dictionary doesn't specify a version
Traceback (most recent call last):
  File "/home/comunidad/local/lib/python2.7/site-packages/gunicorn/arbiter.py", line 495, in spawn_worker
    worker.init_process()
  File "/home/comunidad/local/lib/python2.7/site-packages/gunicorn/workers/base.py", line 106, in init_process
    self.wsgi = self.app.wsgi()
  File "/home/comunidad/local/lib/python2.7/site-packages/gunicorn/app/base.py", line 114, in wsgi
    self.callable = self.load()
  File "/home/comunidad/local/lib/python2.7/site-packages/gunicorn/app/djangoapp.py", line 142, in load
    return mod.make_command_wsgi_application(self.admin_media_path)
  File "/home/comunidad/local/lib/python2.7/site-packages/gunicorn/app/django_wsgi.py", line 113, in make_command_wsgi_application
    reload_django_settings()
  File "/home/comunidad/local/lib/python2.7/site-packages/gunicorn/app/django_wsgi.py", line 109, in reload_django_settings
    logging_config_func(settings.LOGGING)
  File "/usr/lib/python2.7/logging/config.py", line 803, in dictConfig
    dictConfigClass(config).configure()
  File "/usr/lib/python2.7/logging/config.py", line 509, in configure
    raise ValueError("dictionary doesn't specify a version")
ValueError: dictionary doesn't specify a version
2014-01-31 04:57:28 [15768] [INFO] Worker exiting (pid: 15768)
2014-01-31 04:57:28 [15769] [INFO] Booting worker with pid: 15769
2014-01-31 04:57:28 [15769] [ERROR] Exception in worker process:
Traceback (most recent call last):
  File "/home/comunidad/local/lib/python2.7/site-packages/gunicorn/arbiter.py", line 495, in spawn_worker
    worker.init_process()
  File "/home/comunidad/local/lib/python2.7/site-packages/gunicorn/workers/base.py", line 106, in init_process
    self.wsgi = self.app.wsgi()
  File "/home/comunidad/local/lib/python2.7/site-packages/gunicorn/app/base.py", line 114, in wsgi
    self.callable = self.load()
  File "/home/comunidad/local/lib/python2.7/site-packages/gunicorn/app/djangoapp.py", line 142, in load
    return mod.make_command_wsgi_application(self.admin_media_path)
  File "/home/comunidad/local/lib/python2.7/site-packages/gunicorn/app/django_wsgi.py", line 113, in make_command_wsgi_application
    reload_django_settings()
  File "/home/comunidad/local/lib/python2.7/site-packages/gunicorn/app/django_wsgi.py", line 109, in reload_django_settings
    logging_config_func(settings.LOGGING)
  File "/usr/lib/python2.7/logging/config.py", line 803, in dictConfig
    dictConfigClass(config).configure()
  File "/usr/lib/python2.7/logging/config.py", line 509, in configure
    raise ValueError("dictionary doesn't specify a version")
ValueError: dictionary doesn't specify a version
Traceback (most recent call last):
  File "/home/comunidad/local/lib/python2.7/site-packages/gunicorn/arbiter.py", line 495, in spawn_worker
    worker.init_process()
  File "/home/comunidad/local/lib/python2.7/site-packages/gunicorn/workers/base.py", line 106, in init_process
    self.wsgi = self.app.wsgi()
  File "/home/comunidad/local/lib/python2.7/site-packages/gunicorn/app/base.py", line 114, in wsgi
    self.callable = self.load()
  File "/home/comunidad/local/lib/python2.7/site-packages/gunicorn/app/djangoapp.py", line 142, in load
    return mod.make_command_wsgi_application(self.admin_media_path)
  File "/home/comunidad/local/lib/python2.7/site-packages/gunicorn/app/django_wsgi.py", line 113, in make_command_wsgi_application
    reload_django_settings()
  File "/home/comunidad/local/lib/python2.7/site-packages/gunicorn/app/django_wsgi.py", line 109, in reload_django_settings
    logging_config_func(settings.LOGGING)
  File "/usr/lib/python2.7/logging/config.py", line 803, in dictConfig
    dictConfigClass(config).configure()
  File "/usr/lib/python2.7/logging/config.py", line 509, in configure
    raise ValueError("dictionary doesn't specify a version")
ValueError: dictionary doesn't specify a version
2014-01-31 04:57:28 [15769] [INFO] Worker exiting (pid: 15769)
2014-01-31 04:57:28 [15770] [INFO] Booting worker with pid: 15770
2014-01-31 04:57:28 [15770] [ERROR] Exception in worker process:
Traceback (most recent call last):
  File "/home/comunidad/local/lib/python2.7/site-packages/gunicorn/arbiter.py", line 495, in spawn_worker
    worker.init_process()
  File "/home/comunidad/local/lib/python2.7/site-packages/gunicorn/workers/base.py", line 106, in init_process
    self.wsgi = self.app.wsgi()
  File "/home/comunidad/local/lib/python2.7/site-packages/gunicorn/app/base.py", line 114, in wsgi
    self.callable = self.load()
  File "/home/comunidad/local/lib/python2.7/site-packages/gunicorn/app/djangoapp.py", line 142, in load
    return mod.make_command_wsgi_application(self.admin_media_path)
  File "/home/comunidad/local/lib/python2.7/site-packages/gunicorn/app/django_wsgi.py", line 113, in make_command_wsgi_application
    reload_django_settings()
  File "/home/comunidad/local/lib/python2.7/site-packages/gunicorn/app/django_wsgi.py", line 109, in reload_django_settings
    logging_config_func(settings.LOGGING)
  File "/usr/lib/python2.7/logging/config.py", line 803, in dictConfig
    dictConfigClass(config).configure()
  File "/usr/lib/python2.7/logging/config.py", line 509, in configure
    raise ValueError("dictionary doesn't specify a version")
ValueError: dictionary doesn't specify a version
Traceback (most recent call last):
  File "/home/comunidad/local/lib/python2.7/site-packages/gunicorn/arbiter.py", line 495, in spawn_worker
    worker.init_process()
  File "/home/comunidad/local/lib/python2.7/site-packages/gunicorn/workers/base.py", line 106, in init_process
    self.wsgi = self.app.wsgi()
  File "/home/comunidad/local/lib/python2.7/site-packages/gunicorn/app/base.py", line 114, in wsgi
    self.callable = self.load()
  File "/home/comunidad/local/lib/python2.7/site-packages/gunicorn/app/djangoapp.py", line 142, in load
    return mod.make_command_wsgi_application(self.admin_media_path)
  File "/home/comunidad/local/lib/python2.7/site-packages/gunicorn/app/django_wsgi.py", line 113, in make_command_wsgi_application
    reload_django_settings()
  File "/home/comunidad/local/lib/python2.7/site-packages/gunicorn/app/django_wsgi.py", line 109, in reload_django_settings
    logging_config_func(settings.LOGGING)
  File "/usr/lib/python2.7/logging/config.py", line 803, in dictConfig
    dictConfigClass(config).configure()
  File "/usr/lib/python2.7/logging/config.py", line 509, in configure
    raise ValueError("dictionary doesn't specify a version")
ValueError: dictionary doesn't specify a version
2014-01-31 04:57:28 [15770] [INFO] Worker exiting (pid: 15770)
2014-01-31 04:57:28 [15771] [INFO] Booting worker with pid: 15771
2014-01-31 04:57:28 [15771] [ERROR] Exception in worker process:
Traceback (most recent call last):
  File "/home/comunidad/local/lib/python2.7/site-packages/gunicorn/arbiter.py", line 495, in spawn_worker
    worker.init_process()
  File "/home/comunidad/local/lib/python2.7/site-packages/gunicorn/workers/base.py", line 106, in init_process
    self.wsgi = self.app.wsgi()
  File "/home/comunidad/local/lib/python2.7/site-packages/gunicorn/app/base.py", line 114, in wsgi
    self.callable = self.load()
  File "/home/comunidad/local/lib/python2.7/site-packages/gunicorn/app/djangoapp.py", line 142, in load
    return mod.make_command_wsgi_application(self.admin_media_path)
  File "/home/comunidad/local/lib/python2.7/site-packages/gunicorn/app/django_wsgi.py", line 113, in make_command_wsgi_application
    reload_django_settings()
  File "/home/comunidad/local/lib/python2.7/site-packages/gunicorn/app/django_wsgi.py", line 109, in reload_django_settings
    logging_config_func(settings.LOGGING)
  File "/usr/lib/python2.7/logging/config.py", line 803, in dictConfig
    dictConfigClass(config).configure()
  File "/usr/lib/python2.7/logging/config.py", line 509, in configure
    raise ValueError("dictionary doesn't specify a version")
ValueError: dictionary doesn't specify a version
Traceback (most recent call last):
  File "/home/comunidad/local/lib/python2.7/site-packages/gunicorn/arbiter.py", line 495, in spawn_worker
    worker.init_process()
  File "/home/comunidad/local/lib/python2.7/site-packages/gunicorn/workers/base.py", line 106, in init_process
    self.wsgi = self.app.wsgi()
  File "/home/comunidad/local/lib/python2.7/site-packages/gunicorn/app/base.py", line 114, in wsgi
    self.callable = self.load()
  File "/home/comunidad/local/lib/python2.7/site-packages/gunicorn/app/djangoapp.py", line 142, in load
    return mod.make_command_wsgi_application(self.admin_media_path)
  File "/home/comunidad/local/lib/python2.7/site-packages/gunicorn/app/django_wsgi.py", line 113, in make_command_wsgi_application
    reload_django_settings()
  File "/home/comunidad/local/lib/python2.7/site-packages/gunicorn/app/django_wsgi.py", line 109, in reload_django_settings
    logging_config_func(settings.LOGGING)
  File "/usr/lib/python2.7/logging/config.py", line 803, in dictConfig
    dictConfigClass(config).configure()
  File "/usr/lib/python2.7/logging/config.py", line 509, in configure
    raise ValueError("dictionary doesn't specify a version")
ValueError: dictionary doesn't specify a version
2014-01-31 04:57:28 [15771] [INFO] Worker exiting (pid: 15771)
2014-01-31 04:57:28 [15772] [INFO] Booting worker with pid: 15772
2014-01-31 04:57:28 [15772] [ERROR] Exception in worker process:
Traceback (most recent call last):
  File "/home/comunidad/local/lib/python2.7/site-packages/gunicorn/arbiter.py", line 495, in spawn_worker
    worker.init_process()
  File "/home/comunidad/local/lib/python2.7/site-packages/gunicorn/workers/base.py", line 106, in init_process
    self.wsgi = self.app.wsgi()
  File "/home/comunidad/local/lib/python2.7/site-packages/gunicorn/app/base.py", line 114, in wsgi
    self.callable = self.load()
  File "/home/comunidad/local/lib/python2.7/site-packages/gunicorn/app/djangoapp.py", line 142, in load
    return mod.make_command_wsgi_application(self.admin_media_path)
  File "/home/comunidad/local/lib/python2.7/site-packages/gunicorn/app/django_wsgi.py", line 113, in make_command_wsgi_application
    reload_django_settings()
  File "/home/comunidad/local/lib/python2.7/site-packages/gunicorn/app/django_wsgi.py", line 109, in reload_django_settings
    logging_config_func(settings.LOGGING)
  File "/usr/lib/python2.7/logging/config.py", line 803, in dictConfig
    dictConfigClass(config).configure()
  File "/usr/lib/python2.7/logging/config.py", line 509, in configure
    raise ValueError("dictionary doesn't specify a version")
ValueError: dictionary doesn't specify a version
Traceback (most recent call last):
  File "/home/comunidad/local/lib/python2.7/site-packages/gunicorn/arbiter.py", line 495, in spawn_worker
    worker.init_process()
  File "/home/comunidad/local/lib/python2.7/site-packages/gunicorn/workers/base.py", line 106, in init_process
    self.wsgi = self.app.wsgi()
  File "/home/comunidad/local/lib/python2.7/site-packages/gunicorn/app/base.py", line 114, in wsgi
    self.callable = self.load()
  File "/home/comunidad/local/lib/python2.7/site-packages/gunicorn/app/djangoapp.py", line 142, in load
    return mod.make_command_wsgi_application(self.admin_media_path)
  File "/home/comunidad/local/lib/python2.7/site-packages/gunicorn/app/django_wsgi.py", line 113, in make_command_wsgi_application
    reload_django_settings()
  File "/home/comunidad/local/lib/python2.7/site-packages/gunicorn/app/django_wsgi.py", line 109, in reload_django_settings
    logging_config_func(settings.LOGGING)
  File "/usr/lib/python2.7/logging/config.py", line 803, in dictConfig
    dictConfigClass(config).configure()
  File "/usr/lib/python2.7/logging/config.py", line 509, in configure
    raise ValueError("dictionary doesn't specify a version")
ValueError: dictionary doesn't specify a version
2014-01-31 04:57:28 [15772] [INFO] Worker exiting (pid: 15772)
2014-01-31 04:57:28 [15773] [INFO] Booting worker with pid: 15773
2014-01-31 04:57:28 [15773] [ERROR] Exception in worker process:
Traceback (most recent call last):
  File "/home/comunidad/local/lib/python2.7/site-packages/gunicorn/arbiter.py", line 495, in spawn_worker
    worker.init_process()
  File "/home/comunidad/local/lib/python2.7/site-packages/gunicorn/workers/base.py", line 106, in init_process
    self.wsgi = self.app.wsgi()
  File "/home/comunidad/local/lib/python2.7/site-packages/gunicorn/app/base.py", line 114, in wsgi
    self.callable = self.load()
  File "/home/comunidad/local/lib/python2.7/site-packages/gunicorn/app/djangoapp.py", line 142, in load
    return mod.make_command_wsgi_application(self.admin_media_path)
  File "/home/comunidad/local/lib/python2.7/site-packages/gunicorn/app/django_wsgi.py", line 113, in make_command_wsgi_application
    reload_django_settings()
  File "/home/comunidad/local/lib/python2.7/site-packages/gunicorn/app/django_wsgi.py", line 109, in reload_django_settings
    logging_config_func(settings.LOGGING)
  File "/usr/lib/python2.7/logging/config.py", line 803, in dictConfig
    dictConfigClass(config).configure()
  File "/usr/lib/python2.7/logging/config.py", line 509, in configure
    raise ValueError("dictionary doesn't specify a version")
ValueError: dictionary doesn't specify a version
Traceback (most recent call last):
  File "/home/comunidad/local/lib/python2.7/site-packages/gunicorn/arbiter.py", line 495, in spawn_worker
    worker.init_process()
  File "/home/comunidad/local/lib/python2.7/site-packages/gunicorn/workers/base.py", line 106, in init_process
    self.wsgi = self.app.wsgi()
  File "/home/comunidad/local/lib/python2.7/site-packages/gunicorn/app/base.py", line 114, in wsgi
    self.callable = self.load()
  File "/home/comunidad/local/lib/python2.7/site-packages/gunicorn/app/djangoapp.py", line 142, in load
    return mod.make_command_wsgi_application(self.admin_media_path)
  File "/home/comunidad/local/lib/python2.7/site-packages/gunicorn/app/django_wsgi.py", line 113, in make_command_wsgi_application
    reload_django_settings()
  File "/home/comunidad/local/lib/python2.7/site-packages/gunicorn/app/django_wsgi.py", line 109, in reload_django_settings
    logging_config_func(settings.LOGGING)
  File "/usr/lib/python2.7/logging/config.py", line 803, in dictConfig
    dictConfigClass(config).configure()
  File "/usr/lib/python2.7/logging/config.py", line 509, in configure
    raise ValueError("dictionary doesn't specify a version")
ValueError: dictionary doesn't specify a version
2014-01-31 04:57:28 [15773] [INFO] Worker exiting (pid: 15773)
2014-01-31 04:57:28 [15774] [INFO] Booting worker with pid: 15774
Traceback (most recent call last):
  File "/home/comunidad/django-node.js-nginx/website/manage.py", line 10, in <module>
    execute_from_command_line(sys.argv)
  File "/home/comunidad/local/lib/python2.7/site-packages/django/core/management/__init__.py", line 399, in execute_from_command_line
    utility.execute()
2014-01-31 04:57:28 [15774] [ERROR] Exception in worker process:
Traceback (most recent call last):
  File "/home/comunidad/local/lib/python2.7/site-packages/gunicorn/arbiter.py", line 495, in spawn_worker
    worker.init_process()
  File "/home/comunidad/local/lib/python2.7/site-packages/gunicorn/workers/base.py", line 106, in init_process
    self.wsgi = self.app.wsgi()
  File "/home/comunidad/local/lib/python2.7/site-packages/gunicorn/app/base.py", line 114, in wsgi
    self.callable = self.load()
  File "/home/comunidad/local/lib/python2.7/site-packages/gunicorn/app/djangoapp.py", line 142, in load
    return mod.make_command_wsgi_application(self.admin_media_path)
  File "/home/comunidad/local/lib/python2.7/site-packages/gunicorn/app/django_wsgi.py", line 113, in make_command_wsgi_application
    reload_django_settings()
  File "/home/comunidad/local/lib/python2.7/site-packages/gunicorn/app/django_wsgi.py", line 109, in reload_django_settings
    logging_config_func(settings.LOGGING)
  File "/usr/lib/python2.7/logging/config.py", line 803, in dictConfig
    dictConfigClass(config).configure()
  File "/usr/lib/python2.7/logging/config.py", line 509, in configure
    raise ValueError("dictionary doesn't specify a version")
ValueError: dictionary doesn't specify a version
Traceback (most recent call last):
  File "/home/comunidad/local/lib/python2.7/site-packages/gunicorn/arbiter.py", line 495, in spawn_worker
    worker.init_process()
  File "/home/comunidad/local/lib/python2.7/site-packages/gunicorn/workers/base.py", line 106, in init_process
    self.wsgi = self.app.wsgi()
  File "/home/comunidad/local/lib/python2.7/site-packages/gunicorn/app/base.py", line 114, in wsgi
    self.callable = self.load()
  File "/home/comunidad/local/lib/python2.7/site-packages/gunicorn/app/djangoapp.py", line 142, in load
    return mod.make_command_wsgi_application(self.admin_media_path)
  File "/home/comunidad/local/lib/python2.7/site-packages/gunicorn/app/django_wsgi.py", line 113, in make_command_wsgi_application
    reload_django_settings()
  File "/home/comunidad/local/lib/python2.7/site-packages/gunicorn/app/django_wsgi.py", line 109, in reload_django_settings
    logging_config_func(settings.LOGGING)
  File "/usr/lib/python2.7/logging/config.py", line 803, in dictConfig
    dictConfigClass(config).configure()
  File "/usr/lib/python2.7/logging/config.py", line 509, in configure
    raise ValueError("dictionary doesn't specify a version")
ValueError: dictionary doesn't specify a version
  File "/home/comunidad/local/lib/python2.7/site-packages/django/core/management/__init__.py", line 392, in execute
2014-01-31 04:57:28 [15774] [INFO] Worker exiting (pid: 15774)
    self.fetch_command(subcommand).run_from_argv(self.argv)
  File "/home/comunidad/local/lib/python2.7/site-packages/django/core/management/base.py", line 242, in run_from_argv
    self.execute(*args, **options.__dict__)
  File "/home/comunidad/local/lib/python2.7/site-packages/django/core/management/base.py", line 285, in execute
    output = self.handle(*args, **options)
  File "/home/comunidad/local/lib/python2.7/site-packages/gunicorn/management/commands/run_gunicorn.py", line 101, in handle
    DjangoApplicationCommand(options, admin_media_path).run()
  File "/home/comunidad/local/lib/python2.7/site-packages/gunicorn/app/base.py", line 143, in run
    Arbiter(self).run()
  File "/home/comunidad/local/lib/python2.7/site-packages/gunicorn/arbiter.py", line 203, in run
    self.halt(reason=inst.reason, exit_status=inst.exit_status)
  File "/home/comunidad/local/lib/python2.7/site-packages/gunicorn/arbiter.py", line 298, in halt
    self.stop()
  File "/home/comunidad/local/lib/python2.7/site-packages/gunicorn/arbiter.py", line 341, in stop
    self.reap_workers()
  File "/home/comunidad/local/lib/python2.7/site-packages/gunicorn/arbiter.py", line 452, in reap_workers
    raise HaltServer(reason, self.WORKER_BOOT_ERROR)
gunicorn.errors.HaltServer: <HaltServer 'Worker failed to boot.' 3>
2014-01-31 04:57:30 [15776] [INFO] Starting gunicorn 18.0
2014-01-31 04:57:30 [15776] [INFO] Listening at: http://127.0.0.1:8008 (15776)
2014-01-31 04:57:30 [15776] [INFO] Using worker: sync
2014-01-31 04:57:30 [15781] [INFO] Booting worker with pid: 15781
2014-01-31 04:57:30 [15781] [ERROR] Exception in worker process:
Traceback (most recent call last):
  File "/home/comunidad/local/lib/python2.7/site-packages/gunicorn/arbiter.py", line 495, in spawn_worker
    worker.init_process()
  File "/home/comunidad/local/lib/python2.7/site-packages/gunicorn/workers/base.py", line 106, in init_process
    self.wsgi = self.app.wsgi()
  File "/home/comunidad/local/lib/python2.7/site-packages/gunicorn/app/base.py", line 114, in wsgi
    self.callable = self.load()
  File "/home/comunidad/local/lib/python2.7/site-packages/gunicorn/app/djangoapp.py", line 142, in load
    return mod.make_command_wsgi_application(self.admin_media_path)
  File "/home/comunidad/local/lib/python2.7/site-packages/gunicorn/app/django_wsgi.py", line 113, in make_command_wsgi_application
    reload_django_settings()
  File "/home/comunidad/local/lib/python2.7/site-packages/gunicorn/app/django_wsgi.py", line 109, in reload_django_settings
    logging_config_func(settings.LOGGING)
  File "/usr/lib/python2.7/logging/config.py", line 803, in dictConfig
    dictConfigClass(config).configure()
  File "/usr/lib/python2.7/logging/config.py", line 509, in configure
    raise ValueError("dictionary doesn't specify a version")
ValueError: dictionary doesn't specify a version
Traceback (most recent call last):
  File "/home/comunidad/local/lib/python2.7/site-packages/gunicorn/arbiter.py", line 495, in spawn_worker
    worker.init_process()
  File "/home/comunidad/local/lib/python2.7/site-packages/gunicorn/workers/base.py", line 106, in init_process
    self.wsgi = self.app.wsgi()
  File "/home/comunidad/local/lib/python2.7/site-packages/gunicorn/app/base.py", line 114, in wsgi
    self.callable = self.load()
  File "/home/comunidad/local/lib/python2.7/site-packages/gunicorn/app/djangoapp.py", line 142, in load
    return mod.make_command_wsgi_application(self.admin_media_path)
  File "/home/comunidad/local/lib/python2.7/site-packages/gunicorn/app/django_wsgi.py", line 113, in make_command_wsgi_application
    reload_django_settings()
  File "/home/comunidad/local/lib/python2.7/site-packages/gunicorn/app/django_wsgi.py", line 109, in reload_django_settings
    logging_config_func(settings.LOGGING)
  File "/usr/lib/python2.7/logging/config.py", line 803, in dictConfig
    dictConfigClass(config).configure()
  File "/usr/lib/python2.7/logging/config.py", line 509, in configure
    raise ValueError("dictionary doesn't specify a version")
ValueError: dictionary doesn't specify a version
2014-01-31 04:57:30 [15781] [INFO] Worker exiting (pid: 15781)
2014-01-31 04:57:30 [15782] [INFO] Booting worker with pid: 15782
2014-01-31 04:57:30 [15782] [ERROR] Exception in worker process:
Traceback (most recent call last):
  File "/home/comunidad/local/lib/python2.7/site-packages/gunicorn/arbiter.py", line 495, in spawn_worker
    worker.init_process()
  File "/home/comunidad/local/lib/python2.7/site-packages/gunicorn/workers/base.py", line 106, in init_process
    self.wsgi = self.app.wsgi()
  File "/home/comunidad/local/lib/python2.7/site-packages/gunicorn/app/base.py", line 114, in wsgi
    self.callable = self.load()
  File "/home/comunidad/local/lib/python2.7/site-packages/gunicorn/app/djangoapp.py", line 142, in load
    return mod.make_command_wsgi_application(self.admin_media_path)
  File "/home/comunidad/local/lib/python2.7/site-packages/gunicorn/app/django_wsgi.py", line 113, in make_command_wsgi_application
    reload_django_settings()
  File "/home/comunidad/local/lib/python2.7/site-packages/gunicorn/app/django_wsgi.py", line 109, in reload_django_settings
    logging_config_func(settings.LOGGING)
  File "/usr/lib/python2.7/logging/config.py", line 803, in dictConfig
    dictConfigClass(config).configure()
  File "/usr/lib/python2.7/logging/config.py", line 509, in configure
    raise ValueError("dictionary doesn't specify a version")
ValueError: dictionary doesn't specify a version
Traceback (most recent call last):
  File "/home/comunidad/local/lib/python2.7/site-packages/gunicorn/arbiter.py", line 495, in spawn_worker
    worker.init_process()
  File "/home/comunidad/local/lib/python2.7/site-packages/gunicorn/workers/base.py", line 106, in init_process
    self.wsgi = self.app.wsgi()
  File "/home/comunidad/local/lib/python2.7/site-packages/gunicorn/app/base.py", line 114, in wsgi
    self.callable = self.load()
  File "/home/comunidad/local/lib/python2.7/site-packages/gunicorn/app/djangoapp.py", line 142, in load
    return mod.make_command_wsgi_application(self.admin_media_path)
  File "/home/comunidad/local/lib/python2.7/site-packages/gunicorn/app/django_wsgi.py", line 113, in make_command_wsgi_application
    reload_django_settings()
  File "/home/comunidad/local/lib/python2.7/site-packages/gunicorn/app/django_wsgi.py", line 109, in reload_django_settings
    logging_config_func(settings.LOGGING)
  File "/usr/lib/python2.7/logging/config.py", line 803, in dictConfig
    dictConfigClass(config).configure()
  File "/usr/lib/python2.7/logging/config.py", line 509, in configure
    raise ValueError("dictionary doesn't specify a version")
ValueError: dictionary doesn't specify a version
2014-01-31 04:57:30 [15782] [INFO] Worker exiting (pid: 15782)
2014-01-31 04:57:30 [15783] [INFO] Booting worker with pid: 15783
2014-01-31 04:57:30 [15783] [ERROR] Exception in worker process:
Traceback (most recent call last):
  File "/home/comunidad/local/lib/python2.7/site-packages/gunicorn/arbiter.py", line 495, in spawn_worker
    worker.init_process()
  File "/home/comunidad/local/lib/python2.7/site-packages/gunicorn/workers/base.py", line 106, in init_process
    self.wsgi = self.app.wsgi()
  File "/home/comunidad/local/lib/python2.7/site-packages/gunicorn/app/base.py", line 114, in wsgi
    self.callable = self.load()
  File "/home/comunidad/local/lib/python2.7/site-packages/gunicorn/app/djangoapp.py", line 142, in load
    return mod.make_command_wsgi_application(self.admin_media_path)
  File "/home/comunidad/local/lib/python2.7/site-packages/gunicorn/app/django_wsgi.py", line 113, in make_command_wsgi_application
    reload_django_settings()
  File "/home/comunidad/local/lib/python2.7/site-packages/gunicorn/app/django_wsgi.py", line 109, in reload_django_settings
    logging_config_func(settings.LOGGING)
  File "/usr/lib/python2.7/logging/config.py", line 803, in dictConfig
    dictConfigClass(config).configure()
  File "/usr/lib/python2.7/logging/config.py", line 509, in configure
    raise ValueError("dictionary doesn't specify a version")
ValueError: dictionary doesn't specify a version
Traceback (most recent call last):
  File "/home/comunidad/local/lib/python2.7/site-packages/gunicorn/arbiter.py", line 495, in spawn_worker
    worker.init_process()
  File "/home/comunidad/local/lib/python2.7/site-packages/gunicorn/workers/base.py", line 106, in init_process
    self.wsgi = self.app.wsgi()
  File "/home/comunidad/local/lib/python2.7/site-packages/gunicorn/app/base.py", line 114, in wsgi
    self.callable = self.load()
  File "/home/comunidad/local/lib/python2.7/site-packages/gunicorn/app/djangoapp.py", line 142, in load
    return mod.make_command_wsgi_application(self.admin_media_path)
  File "/home/comunidad/local/lib/python2.7/site-packages/gunicorn/app/django_wsgi.py", line 113, in make_command_wsgi_application
    reload_django_settings()
  File "/home/comunidad/local/lib/python2.7/site-packages/gunicorn/app/django_wsgi.py", line 109, in reload_django_settings
    logging_config_func(settings.LOGGING)
  File "/usr/lib/python2.7/logging/config.py", line 803, in dictConfig
    dictConfigClass(config).configure()
  File "/usr/lib/python2.7/logging/config.py", line 509, in configure
    raise ValueError("dictionary doesn't specify a version")
ValueError: dictionary doesn't specify a version
2014-01-31 04:57:30 [15783] [INFO] Worker exiting (pid: 15783)
2014-01-31 04:57:30 [15784] [INFO] Booting worker with pid: 15784
2014-01-31 04:57:30 [15784] [ERROR] Exception in worker process:
Traceback (most recent call last):
  File "/home/comunidad/local/lib/python2.7/site-packages/gunicorn/arbiter.py", line 495, in spawn_worker
    worker.init_process()
  File "/home/comunidad/local/lib/python2.7/site-packages/gunicorn/workers/base.py", line 106, in init_process
    self.wsgi = self.app.wsgi()
  File "/home/comunidad/local/lib/python2.7/site-packages/gunicorn/app/base.py", line 114, in wsgi
    self.callable = self.load()
  File "/home/comunidad/local/lib/python2.7/site-packages/gunicorn/app/djangoapp.py", line 142, in load
    return mod.make_command_wsgi_application(self.admin_media_path)
  File "/home/comunidad/local/lib/python2.7/site-packages/gunicorn/app/django_wsgi.py", line 113, in make_command_wsgi_application
    reload_django_settings()
  File "/home/comunidad/local/lib/python2.7/site-packages/gunicorn/app/django_wsgi.py", line 109, in reload_django_settings
    logging_config_func(settings.LOGGING)
  File "/usr/lib/python2.7/logging/config.py", line 803, in dictConfig
    dictConfigClass(config).configure()
  File "/usr/lib/python2.7/logging/config.py", line 509, in configure
    raise ValueError("dictionary doesn't specify a version")
ValueError: dictionary doesn't specify a version
Traceback (most recent call last):
  File "/home/comunidad/local/lib/python2.7/site-packages/gunicorn/arbiter.py", line 495, in spawn_worker
    worker.init_process()
  File "/home/comunidad/local/lib/python2.7/site-packages/gunicorn/workers/base.py", line 106, in init_process
    self.wsgi = self.app.wsgi()
  File "/home/comunidad/local/lib/python2.7/site-packages/gunicorn/app/base.py", line 114, in wsgi
    self.callable = self.load()
  File "/home/comunidad/local/lib/python2.7/site-packages/gunicorn/app/djangoapp.py", line 142, in load
    return mod.make_command_wsgi_application(self.admin_media_path)
  File "/home/comunidad/local/lib/python2.7/site-packages/gunicorn/app/django_wsgi.py", line 113, in make_command_wsgi_application
    reload_django_settings()
  File "/home/comunidad/local/lib/python2.7/site-packages/gunicorn/app/django_wsgi.py", line 109, in reload_django_settings
    logging_config_func(settings.LOGGING)
  File "/usr/lib/python2.7/logging/config.py", line 803, in dictConfig
    dictConfigClass(config).configure()
  File "/usr/lib/python2.7/logging/config.py", line 509, in configure
    raise ValueError("dictionary doesn't specify a version")
ValueError: dictionary doesn't specify a version
2014-01-31 04:57:30 [15784] [INFO] Worker exiting (pid: 15784)
2014-01-31 04:57:30 [15785] [INFO] Booting worker with pid: 15785
2014-01-31 04:57:30 [15785] [ERROR] Exception in worker process:
Traceback (most recent call last):
  File "/home/comunidad/local/lib/python2.7/site-packages/gunicorn/arbiter.py", line 495, in spawn_worker
    worker.init_process()
  File "/home/comunidad/local/lib/python2.7/site-packages/gunicorn/workers/base.py", line 106, in init_process
    self.wsgi = self.app.wsgi()
  File "/home/comunidad/local/lib/python2.7/site-packages/gunicorn/app/base.py", line 114, in wsgi
    self.callable = self.load()
  File "/home/comunidad/local/lib/python2.7/site-packages/gunicorn/app/djangoapp.py", line 142, in load
    return mod.make_command_wsgi_application(self.admin_media_path)
  File "/home/comunidad/local/lib/python2.7/site-packages/gunicorn/app/django_wsgi.py", line 113, in make_command_wsgi_application
    reload_django_settings()
  File "/home/comunidad/local/lib/python2.7/site-packages/gunicorn/app/django_wsgi.py", line 109, in reload_django_settings
    logging_config_func(settings.LOGGING)
  File "/usr/lib/python2.7/logging/config.py", line 803, in dictConfig
    dictConfigClass(config).configure()
  File "/usr/lib/python2.7/logging/config.py", line 509, in configure
    raise ValueError("dictionary doesn't specify a version")
ValueError: dictionary doesn't specify a version
Traceback (most recent call last):
  File "/home/comunidad/local/lib/python2.7/site-packages/gunicorn/arbiter.py", line 495, in spawn_worker
    worker.init_process()
  File "/home/comunidad/local/lib/python2.7/site-packages/gunicorn/workers/base.py", line 106, in init_process
    self.wsgi = self.app.wsgi()
  File "/home/comunidad/local/lib/python2.7/site-packages/gunicorn/app/base.py", line 114, in wsgi
    self.callable = self.load()
  File "/home/comunidad/local/lib/python2.7/site-packages/gunicorn/app/djangoapp.py", line 142, in load
    return mod.make_command_wsgi_application(self.admin_media_path)
  File "/home/comunidad/local/lib/python2.7/site-packages/gunicorn/app/django_wsgi.py", line 113, in make_command_wsgi_application
    reload_django_settings()
  File "/home/comunidad/local/lib/python2.7/site-packages/gunicorn/app/django_wsgi.py", line 109, in reload_django_settings
    logging_config_func(settings.LOGGING)
  File "/usr/lib/python2.7/logging/config.py", line 803, in dictConfig
    dictConfigClass(config).configure()
  File "/usr/lib/python2.7/logging/config.py", line 509, in configure
    raise ValueError("dictionary doesn't specify a version")
ValueError: dictionary doesn't specify a version
2014-01-31 04:57:30 [15785] [INFO] Worker exiting (pid: 15785)
2014-01-31 04:57:30 [15786] [INFO] Booting worker with pid: 15786
2014-01-31 04:57:30 [15786] [ERROR] Exception in worker process:
Traceback (most recent call last):
  File "/home/comunidad/local/lib/python2.7/site-packages/gunicorn/arbiter.py", line 495, in spawn_worker
    worker.init_process()
  File "/home/comunidad/local/lib/python2.7/site-packages/gunicorn/workers/base.py", line 106, in init_process
    self.wsgi = self.app.wsgi()
  File "/home/comunidad/local/lib/python2.7/site-packages/gunicorn/app/base.py", line 114, in wsgi
    self.callable = self.load()
  File "/home/comunidad/local/lib/python2.7/site-packages/gunicorn/app/djangoapp.py", line 142, in load
    return mod.make_command_wsgi_application(self.admin_media_path)
  File "/home/comunidad/local/lib/python2.7/site-packages/gunicorn/app/django_wsgi.py", line 113, in make_command_wsgi_application
    reload_django_settings()
  File "/home/comunidad/local/lib/python2.7/site-packages/gunicorn/app/django_wsgi.py", line 109, in reload_django_settings
    logging_config_func(settings.LOGGING)
  File "/usr/lib/python2.7/logging/config.py", line 803, in dictConfig
    dictConfigClass(config).configure()
  File "/usr/lib/python2.7/logging/config.py", line 509, in configure
    raise ValueError("dictionary doesn't specify a version")
ValueError: dictionary doesn't specify a version
Traceback (most recent call last):
  File "/home/comunidad/local/lib/python2.7/site-packages/gunicorn/arbiter.py", line 495, in spawn_worker
    worker.init_process()
  File "/home/comunidad/local/lib/python2.7/site-packages/gunicorn/workers/base.py", line 106, in init_process
    self.wsgi = self.app.wsgi()
  File "/home/comunidad/local/lib/python2.7/site-packages/gunicorn/app/base.py", line 114, in wsgi
    self.callable = self.load()
  File "/home/comunidad/local/lib/python2.7/site-packages/gunicorn/app/djangoapp.py", line 142, in load
    return mod.make_command_wsgi_application(self.admin_media_path)
  File "/home/comunidad/local/lib/python2.7/site-packages/gunicorn/app/django_wsgi.py", line 113, in make_command_wsgi_application
    reload_django_settings()
  File "/home/comunidad/local/lib/python2.7/site-packages/gunicorn/app/django_wsgi.py", line 109, in reload_django_settings
    logging_config_func(settings.LOGGING)
  File "/usr/lib/python2.7/logging/config.py", line 803, in dictConfig
    dictConfigClass(config).configure()
  File "/usr/lib/python2.7/logging/config.py", line 509, in configure
    raise ValueError("dictionary doesn't specify a version")
ValueError: dictionary doesn't specify a version
2014-01-31 04:57:30 [15786] [INFO] Worker exiting (pid: 15786)
2014-01-31 04:57:30 [15787] [INFO] Booting worker with pid: 15787
2014-01-31 04:57:30 [15787] [ERROR] Exception in worker process:
Traceback (most recent call last):
  File "/home/comunidad/local/lib/python2.7/site-packages/gunicorn/arbiter.py", line 495, in spawn_worker
    worker.init_process()
  File "/home/comunidad/local/lib/python2.7/site-packages/gunicorn/workers/base.py", line 106, in init_process
    self.wsgi = self.app.wsgi()
  File "/home/comunidad/local/lib/python2.7/site-packages/gunicorn/app/base.py", line 114, in wsgi
    self.callable = self.load()
  File "/home/comunidad/local/lib/python2.7/site-packages/gunicorn/app/djangoapp.py", line 142, in load
    return mod.make_command_wsgi_application(self.admin_media_path)
  File "/home/comunidad/local/lib/python2.7/site-packages/gunicorn/app/django_wsgi.py", line 113, in make_command_wsgi_application
    reload_django_settings()
  File "/home/comunidad/local/lib/python2.7/site-packages/gunicorn/app/django_wsgi.py", line 109, in reload_django_settings
    logging_config_func(settings.LOGGING)
  File "/usr/lib/python2.7/logging/config.py", line 803, in dictConfig
    dictConfigClass(config).configure()
  File "/usr/lib/python2.7/logging/config.py", line 509, in configure
    raise ValueError("dictionary doesn't specify a version")
ValueError: dictionary doesn't specify a version
Traceback (most recent call last):
  File "/home/comunidad/local/lib/python2.7/site-packages/gunicorn/arbiter.py", line 495, in spawn_worker
    worker.init_process()
  File "/home/comunidad/local/lib/python2.7/site-packages/gunicorn/workers/base.py", line 106, in init_process
    self.wsgi = self.app.wsgi()
  File "/home/comunidad/local/lib/python2.7/site-packages/gunicorn/app/base.py", line 114, in wsgi
    self.callable = self.load()
  File "/home/comunidad/local/lib/python2.7/site-packages/gunicorn/app/djangoapp.py", line 142, in load
    return mod.make_command_wsgi_application(self.admin_media_path)
  File "/home/comunidad/local/lib/python2.7/site-packages/gunicorn/app/django_wsgi.py", line 113, in make_command_wsgi_application
    reload_django_settings()
  File "/home/comunidad/local/lib/python2.7/site-packages/gunicorn/app/django_wsgi.py", line 109, in reload_django_settings
    logging_config_func(settings.LOGGING)
  File "/usr/lib/python2.7/logging/config.py", line 803, in dictConfig
    dictConfigClass(config).configure()
  File "/usr/lib/python2.7/logging/config.py", line 509, in configure
    raise ValueError("dictionary doesn't specify a version")
ValueError: dictionary doesn't specify a version
2014-01-31 04:57:30 [15787] [INFO] Worker exiting (pid: 15787)
2014-01-31 04:57:30 [15788] [INFO] Booting worker with pid: 15788
2014-01-31 04:57:30 [15788] [ERROR] Exception in worker process:
Traceback (most recent call last):
  File "/home/comunidad/local/lib/python2.7/site-packages/gunicorn/arbiter.py", line 495, in spawn_worker
    worker.init_process()
  File "/home/comunidad/local/lib/python2.7/site-packages/gunicorn/workers/base.py", line 106, in init_process
    self.wsgi = self.app.wsgi()
  File "/home/comunidad/local/lib/python2.7/site-packages/gunicorn/app/base.py", line 114, in wsgi
    self.callable = self.load()
  File "/home/comunidad/local/lib/python2.7/site-packages/gunicorn/app/djangoapp.py", line 142, in load
    return mod.make_command_wsgi_application(self.admin_media_path)
  File "/home/comunidad/local/lib/python2.7/site-packages/gunicorn/app/django_wsgi.py", line 113, in make_command_wsgi_application
    reload_django_settings()
  File "/home/comunidad/local/lib/python2.7/site-packages/gunicorn/app/django_wsgi.py", line 109, in reload_django_settings
    logging_config_func(settings.LOGGING)
  File "/usr/lib/python2.7/logging/config.py", line 803, in dictConfig
    dictConfigClass(config).configure()
  File "/usr/lib/python2.7/logging/config.py", line 509, in configure
    raise ValueError("dictionary doesn't specify a version")
ValueError: dictionary doesn't specify a version
Traceback (most recent call last):
  File "/home/comunidad/local/lib/python2.7/site-packages/gunicorn/arbiter.py", line 495, in spawn_worker
    worker.init_process()
  File "/home/comunidad/local/lib/python2.7/site-packages/gunicorn/workers/base.py", line 106, in init_process
    self.wsgi = self.app.wsgi()
  File "/home/comunidad/local/lib/python2.7/site-packages/gunicorn/app/base.py", line 114, in wsgi
    self.callable = self.load()
  File "/home/comunidad/local/lib/python2.7/site-packages/gunicorn/app/djangoapp.py", line 142, in load
    return mod.make_command_wsgi_application(self.admin_media_path)
  File "/home/comunidad/local/lib/python2.7/site-packages/gunicorn/app/django_wsgi.py", line 113, in make_command_wsgi_application
    reload_django_settings()
  File "/home/comunidad/local/lib/python2.7/site-packages/gunicorn/app/django_wsgi.py", line 109, in reload_django_settings
    logging_config_func(settings.LOGGING)
  File "/usr/lib/python2.7/logging/config.py", line 803, in dictConfig
    dictConfigClass(config).configure()
  File "/usr/lib/python2.7/logging/config.py", line 509, in configure
    raise ValueError("dictionary doesn't specify a version")
ValueError: dictionary doesn't specify a version
2014-01-31 04:57:30 [15788] [INFO] Worker exiting (pid: 15788)
Traceback (most recent call last):
  File "/home/comunidad/django-node.js-nginx/website/manage.py", line 10, in <module>
    execute_from_command_line(sys.argv)
  File "/home/comunidad/local/lib/python2.7/site-packages/django/core/management/__init__.py", line 399, in execute_from_command_line
    utility.execute()
  File "/home/comunidad/local/lib/python2.7/site-packages/django/core/management/__init__.py", line 392, in execute
    self.fetch_command(subcommand).run_from_argv(self.argv)
  File "/home/comunidad/local/lib/python2.7/site-packages/django/core/management/base.py", line 242, in run_from_argv
    self.execute(*args, **options.__dict__)
  File "/home/comunidad/local/lib/python2.7/site-packages/django/core/management/base.py", line 285, in execute
    output = self.handle(*args, **options)
  File "/home/comunidad/local/lib/python2.7/site-packages/gunicorn/management/commands/run_gunicorn.py", line 101, in handle
    DjangoApplicationCommand(options, admin_media_path).run()
  File "/home/comunidad/local/lib/python2.7/site-packages/gunicorn/app/base.py", line 143, in run
    Arbiter(self).run()
  File "/home/comunidad/local/lib/python2.7/site-packages/gunicorn/arbiter.py", line 203, in run
    self.halt(reason=inst.reason, exit_status=inst.exit_status)
  File "/home/comunidad/local/lib/python2.7/site-packages/gunicorn/arbiter.py", line 298, in halt
    self.stop()
  File "/home/comunidad/local/lib/python2.7/site-packages/gunicorn/arbiter.py", line 341, in stop
    self.reap_workers()
  File "/home/comunidad/local/lib/python2.7/site-packages/gunicorn/arbiter.py", line 452, in reap_workers
    raise HaltServer(reason, self.WORKER_BOOT_ERROR)
gunicorn.errors.HaltServer: <HaltServer 'Worker failed to boot.' 3>
2014-01-31 04:57:34 [15792] [INFO] Starting gunicorn 18.0
2014-01-31 04:57:34 [15792] [INFO] Listening at: http://127.0.0.1:8008 (15792)
2014-01-31 04:57:34 [15792] [INFO] Using worker: sync
2014-01-31 04:57:34 [15797] [INFO] Booting worker with pid: 15797
2014-01-31 04:57:34 [15798] [INFO] Booting worker with pid: 15798
2014-01-31 04:57:34 [15797] [ERROR] Exception in worker process:
Traceback (most recent call last):
  File "/home/comunidad/local/lib/python2.7/site-packages/gunicorn/arbiter.py", line 495, in spawn_worker
    worker.init_process()
  File "/home/comunidad/local/lib/python2.7/site-packages/gunicorn/workers/base.py", line 106, in init_process
    self.wsgi = self.app.wsgi()
  File "/home/comunidad/local/lib/python2.7/site-packages/gunicorn/app/base.py", line 114, in wsgi
    self.callable = self.load()
  File "/home/comunidad/local/lib/python2.7/site-packages/gunicorn/app/djangoapp.py", line 142, in load
    return mod.make_command_wsgi_application(self.admin_media_path)
  File "/home/comunidad/local/lib/python2.7/site-packages/gunicorn/app/django_wsgi.py", line 113, in make_command_wsgi_application
    reload_django_settings()
  File "/home/comunidad/local/lib/python2.7/site-packages/gunicorn/app/django_wsgi.py", line 109, in reload_django_settings
    logging_config_func(settings.LOGGING)
  File "/usr/lib/python2.7/logging/config.py", line 803, in dictConfig
    dictConfigClass(config).configure()
  File "/usr/lib/python2.7/logging/config.py", line 509, in configure
    raise ValueError("dictionary doesn't specify a version")
ValueError: dictionary doesn't specify a version
Traceback (most recent call last):
  File "/home/comunidad/local/lib/python2.7/site-packages/gunicorn/arbiter.py", line 495, in spawn_worker
    worker.init_process()
  File "/home/comunidad/local/lib/python2.7/site-packages/gunicorn/workers/base.py", line 106, in init_process
    self.wsgi = self.app.wsgi()
  File "/home/comunidad/local/lib/python2.7/site-packages/gunicorn/app/base.py", line 114, in wsgi
    self.callable = self.load()
  File "/home/comunidad/local/lib/python2.7/site-packages/gunicorn/app/djangoapp.py", line 142, in load
    return mod.make_command_wsgi_application(self.admin_media_path)
  File "/home/comunidad/local/lib/python2.7/site-packages/gunicorn/app/django_wsgi.py", line 113, in make_command_wsgi_application
    reload_django_settings()
  File "/home/comunidad/local/lib/python2.7/site-packages/gunicorn/app/django_wsgi.py", line 109, in reload_django_settings
    logging_config_func(settings.LOGGING)
  File "/usr/lib/python2.7/logging/config.py", line 803, in dictConfig
    dictConfigClass(config).configure()
  File "/usr/lib/python2.7/logging/config.py", line 509, in configure
    raise ValueError("dictionary doesn't specify a version")
ValueError: dictionary doesn't specify a version
2014-01-31 04:57:34 [15797] [INFO] Worker exiting (pid: 15797)
2014-01-31 04:57:34 [15798] [ERROR] Exception in worker process:
Traceback (most recent call last):
  File "/home/comunidad/local/lib/python2.7/site-packages/gunicorn/arbiter.py", line 495, in spawn_worker
    worker.init_process()
  File "/home/comunidad/local/lib/python2.7/site-packages/gunicorn/workers/base.py", line 106, in init_process
    self.wsgi = self.app.wsgi()
  File "/home/comunidad/local/lib/python2.7/site-packages/gunicorn/app/base.py", line 114, in wsgi
    self.callable = self.load()
  File "/home/comunidad/local/lib/python2.7/site-packages/gunicorn/app/djangoapp.py", line 142, in load
    return mod.make_command_wsgi_application(self.admin_media_path)
  File "/home/comunidad/local/lib/python2.7/site-packages/gunicorn/app/django_wsgi.py", line 113, in make_command_wsgi_application
    reload_django_settings()
  File "/home/comunidad/local/lib/python2.7/site-packages/gunicorn/app/django_wsgi.py", line 109, in reload_django_settings
    logging_config_func(settings.LOGGING)
  File "/usr/lib/python2.7/logging/config.py", line 803, in dictConfig
    dictConfigClass(config).configure()
  File "/usr/lib/python2.7/logging/config.py", line 509, in configure
    raise ValueError("dictionary doesn't specify a version")
ValueError: dictionary doesn't specify a version
Traceback (most recent call last):
  File "/home/comunidad/local/lib/python2.7/site-packages/gunicorn/arbiter.py", line 495, in spawn_worker
    worker.init_process()
  File "/home/comunidad/local/lib/python2.7/site-packages/gunicorn/workers/base.py", line 106, in init_process
    self.wsgi = self.app.wsgi()
  File "/home/comunidad/local/lib/python2.7/site-packages/gunicorn/app/base.py", line 114, in wsgi
    self.callable = self.load()
  File "/home/comunidad/local/lib/python2.7/site-packages/gunicorn/app/djangoapp.py", line 142, in load
    return mod.make_command_wsgi_application(self.admin_media_path)
  File "/home/comunidad/local/lib/python2.7/site-packages/gunicorn/app/django_wsgi.py", line 113, in make_command_wsgi_application
    reload_django_settings()
  File "/home/comunidad/local/lib/python2.7/site-packages/gunicorn/app/django_wsgi.py", line 109, in reload_django_settings
    logging_config_func(settings.LOGGING)
  File "/usr/lib/python2.7/logging/config.py", line 803, in dictConfig
    dictConfigClass(config).configure()
  File "/usr/lib/python2.7/logging/config.py", line 509, in configure
    raise ValueError("dictionary doesn't specify a version")
ValueError: dictionary doesn't specify a version
2014-01-31 04:57:34 [15798] [INFO] Worker exiting (pid: 15798)
2014-01-31 04:57:34 [15799] [INFO] Booting worker with pid: 15799
2014-01-31 04:57:34 [15800] [INFO] Booting worker with pid: 15800
2014-01-31 04:57:34 [15799] [ERROR] Exception in worker process:
Traceback (most recent call last):
  File "/home/comunidad/local/lib/python2.7/site-packages/gunicorn/arbiter.py", line 495, in spawn_worker
    worker.init_process()
  File "/home/comunidad/local/lib/python2.7/site-packages/gunicorn/workers/base.py", line 106, in init_process
    self.wsgi = self.app.wsgi()
  File "/home/comunidad/local/lib/python2.7/site-packages/gunicorn/app/base.py", line 114, in wsgi
    self.callable = self.load()
  File "/home/comunidad/local/lib/python2.7/site-packages/gunicorn/app/djangoapp.py", line 142, in load
    return mod.make_command_wsgi_application(self.admin_media_path)
  File "/home/comunidad/local/lib/python2.7/site-packages/gunicorn/app/django_wsgi.py", line 113, in make_command_wsgi_application
    reload_django_settings()
  File "/home/comunidad/local/lib/python2.7/site-packages/gunicorn/app/django_wsgi.py", line 109, in reload_django_settings
    logging_config_func(settings.LOGGING)
  File "/usr/lib/python2.7/logging/config.py", line 803, in dictConfig
    dictConfigClass(config).configure()
  File "/usr/lib/python2.7/logging/config.py", line 509, in configure
    raise ValueError("dictionary doesn't specify a version")
ValueError: dictionary doesn't specify a version
Traceback (most recent call last):
  File "/home/comunidad/local/lib/python2.7/site-packages/gunicorn/arbiter.py", line 495, in spawn_worker
    worker.init_process()
  File "/home/comunidad/local/lib/python2.7/site-packages/gunicorn/workers/base.py", line 106, in init_process
    self.wsgi = self.app.wsgi()
  File "/home/comunidad/local/lib/python2.7/site-packages/gunicorn/app/base.py", line 114, in wsgi
    self.callable = self.load()
  File "/home/comunidad/local/lib/python2.7/site-packages/gunicorn/app/djangoapp.py", line 142, in load
    return mod.make_command_wsgi_application(self.admin_media_path)
  File "/home/comunidad/local/lib/python2.7/site-packages/gunicorn/app/django_wsgi.py", line 113, in make_command_wsgi_application
    reload_django_settings()
  File "/home/comunidad/local/lib/python2.7/site-packages/gunicorn/app/django_wsgi.py", line 109, in reload_django_settings
    logging_config_func(settings.LOGGING)
  File "/usr/lib/python2.7/logging/config.py", line 803, in dictConfig
    dictConfigClass(config).configure()
  File "/usr/lib/python2.7/logging/config.py", line 509, in configure
    raise ValueError("dictionary doesn't specify a version")
ValueError: dictionary doesn't specify a version
2014-01-31 04:57:34 [15799] [INFO] Worker exiting (pid: 15799)
2014-01-31 04:57:34 [15800] [ERROR] Exception in worker process:
Traceback (most recent call last):
  File "/home/comunidad/local/lib/python2.7/site-packages/gunicorn/arbiter.py", line 495, in spawn_worker
    worker.init_process()
  File "/home/comunidad/local/lib/python2.7/site-packages/gunicorn/workers/base.py", line 106, in init_process
    self.wsgi = self.app.wsgi()
  File "/home/comunidad/local/lib/python2.7/site-packages/gunicorn/app/base.py", line 114, in wsgi
    self.callable = self.load()
  File "/home/comunidad/local/lib/python2.7/site-packages/gunicorn/app/djangoapp.py", line 142, in load
    return mod.make_command_wsgi_application(self.admin_media_path)
  File "/home/comunidad/local/lib/python2.7/site-packages/gunicorn/app/django_wsgi.py", line 113, in make_command_wsgi_application
    reload_django_settings()
  File "/home/comunidad/local/lib/python2.7/site-packages/gunicorn/app/django_wsgi.py", line 109, in reload_django_settings
    logging_config_func(settings.LOGGING)
  File "/usr/lib/python2.7/logging/config.py", line 803, in dictConfig
    dictConfigClass(config).configure()
  File "/usr/lib/python2.7/logging/config.py", line 509, in configure
    raise ValueError("dictionary doesn't specify a version")
ValueError: dictionary doesn't specify a version
Traceback (most recent call last):
  File "/home/comunidad/local/lib/python2.7/site-packages/gunicorn/arbiter.py", line 495, in spawn_worker
    worker.init_process()
  File "/home/comunidad/local/lib/python2.7/site-packages/gunicorn/workers/base.py", line 106, in init_process
    self.wsgi = self.app.wsgi()
  File "/home/comunidad/local/lib/python2.7/site-packages/gunicorn/app/base.py", line 114, in wsgi
    self.callable = self.load()
  File "/home/comunidad/local/lib/python2.7/site-packages/gunicorn/app/djangoapp.py", line 142, in load
    return mod.make_command_wsgi_application(self.admin_media_path)
  File "/home/comunidad/local/lib/python2.7/site-packages/gunicorn/app/django_wsgi.py", line 113, in make_command_wsgi_application
    reload_django_settings()
  File "/home/comunidad/local/lib/python2.7/site-packages/gunicorn/app/django_wsgi.py", line 109, in reload_django_settings
    logging_config_func(settings.LOGGING)
  File "/usr/lib/python2.7/logging/config.py", line 803, in dictConfig
    dictConfigClass(config).configure()
  File "/usr/lib/python2.7/logging/config.py", line 509, in configure
    raise ValueError("dictionary doesn't specify a version")
ValueError: dictionary doesn't specify a version
2014-01-31 04:57:34 [15800] [INFO] Worker exiting (pid: 15800)
2014-01-31 04:57:34 [15801] [INFO] Booting worker with pid: 15801
2014-01-31 04:57:34 [15802] [INFO] Booting worker with pid: 15802
2014-01-31 04:57:34 [15801] [ERROR] Exception in worker process:
Traceback (most recent call last):
  File "/home/comunidad/local/lib/python2.7/site-packages/gunicorn/arbiter.py", line 495, in spawn_worker
    worker.init_process()
  File "/home/comunidad/local/lib/python2.7/site-packages/gunicorn/workers/base.py", line 106, in init_process
    self.wsgi = self.app.wsgi()
  File "/home/comunidad/local/lib/python2.7/site-packages/gunicorn/app/base.py", line 114, in wsgi
    self.callable = self.load()
  File "/home/comunidad/local/lib/python2.7/site-packages/gunicorn/app/djangoapp.py", line 142, in load
    return mod.make_command_wsgi_application(self.admin_media_path)
  File "/home/comunidad/local/lib/python2.7/site-packages/gunicorn/app/django_wsgi.py", line 113, in make_command_wsgi_application
    reload_django_settings()
  File "/home/comunidad/local/lib/python2.7/site-packages/gunicorn/app/django_wsgi.py", line 109, in reload_django_settings
    logging_config_func(settings.LOGGING)
  File "/usr/lib/python2.7/logging/config.py", line 803, in dictConfig
    dictConfigClass(config).configure()
  File "/usr/lib/python2.7/logging/config.py", line 509, in configure
    raise ValueError("dictionary doesn't specify a version")
ValueError: dictionary doesn't specify a version
Traceback (most recent call last):
  File "/home/comunidad/local/lib/python2.7/site-packages/gunicorn/arbiter.py", line 495, in spawn_worker
    worker.init_process()
  File "/home/comunidad/local/lib/python2.7/site-packages/gunicorn/workers/base.py", line 106, in init_process
    self.wsgi = self.app.wsgi()
  File "/home/comunidad/local/lib/python2.7/site-packages/gunicorn/app/base.py", line 114, in wsgi
    self.callable = self.load()
  File "/home/comunidad/local/lib/python2.7/site-packages/gunicorn/app/djangoapp.py", line 142, in load
    return mod.make_command_wsgi_application(self.admin_media_path)
  File "/home/comunidad/local/lib/python2.7/site-packages/gunicorn/app/django_wsgi.py", line 113, in make_command_wsgi_application
    reload_django_settings()
  File "/home/comunidad/local/lib/python2.7/site-packages/gunicorn/app/django_wsgi.py", line 109, in reload_django_settings
    logging_config_func(settings.LOGGING)
  File "/usr/lib/python2.7/logging/config.py", line 803, in dictConfig
    dictConfigClass(config).configure()
  File "/usr/lib/python2.7/logging/config.py", line 509, in configure
    raise ValueError("dictionary doesn't specify a version")
ValueError: dictionary doesn't specify a version
2014-01-31 04:57:34 [15801] [INFO] Worker exiting (pid: 15801)
2014-01-31 04:57:34 [15802] [ERROR] Exception in worker process:
Traceback (most recent call last):
  File "/home/comunidad/local/lib/python2.7/site-packages/gunicorn/arbiter.py", line 495, in spawn_worker
    worker.init_process()
  File "/home/comunidad/local/lib/python2.7/site-packages/gunicorn/workers/base.py", line 106, in init_process
    self.wsgi = self.app.wsgi()
  File "/home/comunidad/local/lib/python2.7/site-packages/gunicorn/app/base.py", line 114, in wsgi
    self.callable = self.load()
  File "/home/comunidad/local/lib/python2.7/site-packages/gunicorn/app/djangoapp.py", line 142, in load
    return mod.make_command_wsgi_application(self.admin_media_path)
  File "/home/comunidad/local/lib/python2.7/site-packages/gunicorn/app/django_wsgi.py", line 113, in make_command_wsgi_application
    reload_django_settings()
  File "/home/comunidad/local/lib/python2.7/site-packages/gunicorn/app/django_wsgi.py", line 109, in reload_django_settings
    logging_config_func(settings.LOGGING)
  File "/usr/lib/python2.7/logging/config.py", line 803, in dictConfig
    dictConfigClass(config).configure()
  File "/usr/lib/python2.7/logging/config.py", line 509, in configure
    raise ValueError("dictionary doesn't specify a version")
ValueError: dictionary doesn't specify a version
Traceback (most recent call last):
  File "/home/comunidad/local/lib/python2.7/site-packages/gunicorn/arbiter.py", line 495, in spawn_worker
    worker.init_process()
  File "/home/comunidad/local/lib/python2.7/site-packages/gunicorn/workers/base.py", line 106, in init_process
    self.wsgi = self.app.wsgi()
  File "/home/comunidad/local/lib/python2.7/site-packages/gunicorn/app/base.py", line 114, in wsgi
    self.callable = self.load()
  File "/home/comunidad/local/lib/python2.7/site-packages/gunicorn/app/djangoapp.py", line 142, in load
    return mod.make_command_wsgi_application(self.admin_media_path)
  File "/home/comunidad/local/lib/python2.7/site-packages/gunicorn/app/django_wsgi.py", line 113, in make_command_wsgi_application
    reload_django_settings()
  File "/home/comunidad/local/lib/python2.7/site-packages/gunicorn/app/django_wsgi.py", line 109, in reload_django_settings
    logging_config_func(settings.LOGGING)
  File "/usr/lib/python2.7/logging/config.py", line 803, in dictConfig
    dictConfigClass(config).configure()
  File "/usr/lib/python2.7/logging/config.py", line 509, in configure
    raise ValueError("dictionary doesn't specify a version")
ValueError: dictionary doesn't specify a version
2014-01-31 04:57:34 [15802] [INFO] Worker exiting (pid: 15802)
2014-01-31 04:57:34 [15803] [INFO] Booting worker with pid: 15803
2014-01-31 04:57:34 [15804] [INFO] Booting worker with pid: 15804
2014-01-31 04:57:34 [15803] [ERROR] Exception in worker process:
Traceback (most recent call last):
  File "/home/comunidad/local/lib/python2.7/site-packages/gunicorn/arbiter.py", line 495, in spawn_worker
    worker.init_process()
  File "/home/comunidad/local/lib/python2.7/site-packages/gunicorn/workers/base.py", line 106, in init_process
    self.wsgi = self.app.wsgi()
  File "/home/comunidad/local/lib/python2.7/site-packages/gunicorn/app/base.py", line 114, in wsgi
    self.callable = self.load()
  File "/home/comunidad/local/lib/python2.7/site-packages/gunicorn/app/djangoapp.py", line 142, in load
    return mod.make_command_wsgi_application(self.admin_media_path)
  File "/home/comunidad/local/lib/python2.7/site-packages/gunicorn/app/django_wsgi.py", line 113, in make_command_wsgi_application
    reload_django_settings()
  File "/home/comunidad/local/lib/python2.7/site-packages/gunicorn/app/django_wsgi.py", line 109, in reload_django_settings
    logging_config_func(settings.LOGGING)
  File "/usr/lib/python2.7/logging/config.py", line 803, in dictConfig
    dictConfigClass(config).configure()
  File "/usr/lib/python2.7/logging/config.py", line 509, in configure
    raise ValueError("dictionary doesn't specify a version")
ValueError: dictionary doesn't specify a version
Traceback (most recent call last):
  File "/home/comunidad/local/lib/python2.7/site-packages/gunicorn/arbiter.py", line 495, in spawn_worker
    worker.init_process()
  File "/home/comunidad/local/lib/python2.7/site-packages/gunicorn/workers/base.py", line 106, in init_process
    self.wsgi = self.app.wsgi()
  File "/home/comunidad/local/lib/python2.7/site-packages/gunicorn/app/base.py", line 114, in wsgi
    self.callable = self.load()
  File "/home/comunidad/local/lib/python2.7/site-packages/gunicorn/app/djangoapp.py", line 142, in load
    return mod.make_command_wsgi_application(self.admin_media_path)
  File "/home/comunidad/local/lib/python2.7/site-packages/gunicorn/app/django_wsgi.py", line 113, in make_command_wsgi_application
    reload_django_settings()
  File "/home/comunidad/local/lib/python2.7/site-packages/gunicorn/app/django_wsgi.py", line 109, in reload_django_settings
    logging_config_func(settings.LOGGING)
  File "/usr/lib/python2.7/logging/config.py", line 803, in dictConfig
    dictConfigClass(config).configure()
  File "/usr/lib/python2.7/logging/config.py", line 509, in configure
    raise ValueError("dictionary doesn't specify a version")
ValueError: dictionary doesn't specify a version
2014-01-31 04:57:34 [15803] [INFO] Worker exiting (pid: 15803)
2014-01-31 04:57:34 [15804] [ERROR] Exception in worker process:
Traceback (most recent call last):
  File "/home/comunidad/local/lib/python2.7/site-packages/gunicorn/arbiter.py", line 495, in spawn_worker
    worker.init_process()
  File "/home/comunidad/local/lib/python2.7/site-packages/gunicorn/workers/base.py", line 106, in init_process
    self.wsgi = self.app.wsgi()
  File "/home/comunidad/local/lib/python2.7/site-packages/gunicorn/app/base.py", line 114, in wsgi
    self.callable = self.load()
  File "/home/comunidad/local/lib/python2.7/site-packages/gunicorn/app/djangoapp.py", line 142, in load
    return mod.make_command_wsgi_application(self.admin_media_path)
  File "/home/comunidad/local/lib/python2.7/site-packages/gunicorn/app/django_wsgi.py", line 113, in make_command_wsgi_application
    reload_django_settings()
  File "/home/comunidad/local/lib/python2.7/site-packages/gunicorn/app/django_wsgi.py", line 109, in reload_django_settings
    logging_config_func(settings.LOGGING)
  File "/usr/lib/python2.7/logging/config.py", line 803, in dictConfig
    dictConfigClass(config).configure()
  File "/usr/lib/python2.7/logging/config.py", line 509, in configure
    raise ValueError("dictionary doesn't specify a version")
ValueError: dictionary doesn't specify a version
Traceback (most recent call last):
  File "/home/comunidad/local/lib/python2.7/site-packages/gunicorn/arbiter.py", line 495, in spawn_worker
    worker.init_process()
  File "/home/comunidad/local/lib/python2.7/site-packages/gunicorn/workers/base.py", line 106, in init_process
    self.wsgi = self.app.wsgi()
  File "/home/comunidad/local/lib/python2.7/site-packages/gunicorn/app/base.py", line 114, in wsgi
    self.callable = self.load()
  File "/home/comunidad/local/lib/python2.7/site-packages/gunicorn/app/djangoapp.py", line 142, in load
    return mod.make_command_wsgi_application(self.admin_media_path)
  File "/home/comunidad/local/lib/python2.7/site-packages/gunicorn/app/django_wsgi.py", line 113, in make_command_wsgi_application
    reload_django_settings()
  File "/home/comunidad/local/lib/python2.7/site-packages/gunicorn/app/django_wsgi.py", line 109, in reload_django_settings
    logging_config_func(settings.LOGGING)
  File "/usr/lib/python2.7/logging/config.py", line 803, in dictConfig
    dictConfigClass(config).configure()
  File "/usr/lib/python2.7/logging/config.py", line 509, in configure
    raise ValueError("dictionary doesn't specify a version")
ValueError: dictionary doesn't specify a version
2014-01-31 04:57:34 [15804] [INFO] Worker exiting (pid: 15804)
Traceback (most recent call last):
  File "/home/comunidad/django-node.js-nginx/website/manage.py", line 10, in <module>
    execute_from_command_line(sys.argv)
  File "/home/comunidad/local/lib/python2.7/site-packages/django/core/management/__init__.py", line 399, in execute_from_command_line
    utility.execute()
  File "/home/comunidad/local/lib/python2.7/site-packages/django/core/management/__init__.py", line 392, in execute
    self.fetch_command(subcommand).run_from_argv(self.argv)
  File "/home/comunidad/local/lib/python2.7/site-packages/django/core/management/base.py", line 242, in run_from_argv
    self.execute(*args, **options.__dict__)
  File "/home/comunidad/local/lib/python2.7/site-packages/django/core/management/base.py", line 285, in execute
    output = self.handle(*args, **options)
  File "/home/comunidad/local/lib/python2.7/site-packages/gunicorn/management/commands/run_gunicorn.py", line 101, in handle
    DjangoApplicationCommand(options, admin_media_path).run()
  File "/home/comunidad/local/lib/python2.7/site-packages/gunicorn/app/base.py", line 143, in run
    Arbiter(self).run()
  File "/home/comunidad/local/lib/python2.7/site-packages/gunicorn/arbiter.py", line 203, in run
    self.halt(reason=inst.reason, exit_status=inst.exit_status)
  File "/home/comunidad/local/lib/python2.7/site-packages/gunicorn/arbiter.py", line 298, in halt
    self.stop()
  File "/home/comunidad/local/lib/python2.7/site-packages/gunicorn/arbiter.py", line 341, in stop
    self.reap_workers()
  File "/home/comunidad/local/lib/python2.7/site-packages/gunicorn/arbiter.py", line 452, in reap_workers
    raise HaltServer(reason, self.WORKER_BOOT_ERROR)
gunicorn.errors.HaltServer: <HaltServer 'Worker failed to boot.' 3>
2014-01-31 04:58:21 [15810] [INFO] Starting gunicorn 18.0
2014-01-31 04:58:21 [15810] [INFO] Listening at: http://127.0.0.1:8008 (15810)
2014-01-31 04:58:21 [15810] [INFO] Using worker: sync
2014-01-31 04:58:21 [15815] [INFO] Booting worker with pid: 15815
2014-01-31 04:58:21 [15815] [ERROR] Exception in worker process:
Traceback (most recent call last):
  File "/home/comunidad/local/lib/python2.7/site-packages/gunicorn/arbiter.py", line 495, in spawn_worker
    worker.init_process()
  File "/home/comunidad/local/lib/python2.7/site-packages/gunicorn/workers/base.py", line 106, in init_process
    self.wsgi = self.app.wsgi()
  File "/home/comunidad/local/lib/python2.7/site-packages/gunicorn/app/base.py", line 114, in wsgi
    self.callable = self.load()
  File "/home/comunidad/local/lib/python2.7/site-packages/gunicorn/app/djangoapp.py", line 142, in load
    return mod.make_command_wsgi_application(self.admin_media_path)
  File "/home/comunidad/local/lib/python2.7/site-packages/gunicorn/app/django_wsgi.py", line 113, in make_command_wsgi_application
    reload_django_settings()
  File "/home/comunidad/local/lib/python2.7/site-packages/gunicorn/app/django_wsgi.py", line 109, in reload_django_settings
    logging_config_func(settings.LOGGING)
  File "/usr/lib/python2.7/logging/config.py", line 803, in dictConfig
    dictConfigClass(config).configure()
  File "/usr/lib/python2.7/logging/config.py", line 509, in configure
    raise ValueError("dictionary doesn't specify a version")
ValueError: dictionary doesn't specify a version
Traceback (most recent call last):
  File "/home/comunidad/local/lib/python2.7/site-packages/gunicorn/arbiter.py", line 495, in spawn_worker
    worker.init_process()
  File "/home/comunidad/local/lib/python2.7/site-packages/gunicorn/workers/base.py", line 106, in init_process
    self.wsgi = self.app.wsgi()
  File "/home/comunidad/local/lib/python2.7/site-packages/gunicorn/app/base.py", line 114, in wsgi
    self.callable = self.load()
  File "/home/comunidad/local/lib/python2.7/site-packages/gunicorn/app/djangoapp.py", line 142, in load
    return mod.make_command_wsgi_application(self.admin_media_path)
  File "/home/comunidad/local/lib/python2.7/site-packages/gunicorn/app/django_wsgi.py", line 113, in make_command_wsgi_application
    reload_django_settings()
  File "/home/comunidad/local/lib/python2.7/site-packages/gunicorn/app/django_wsgi.py", line 109, in reload_django_settings
    logging_config_func(settings.LOGGING)
  File "/usr/lib/python2.7/logging/config.py", line 803, in dictConfig
    dictConfigClass(config).configure()
  File "/usr/lib/python2.7/logging/config.py", line 509, in configure
    raise ValueError("dictionary doesn't specify a version")
ValueError: dictionary doesn't specify a version
2014-01-31 04:58:21 [15815] [INFO] Worker exiting (pid: 15815)
2014-01-31 04:58:21 [15816] [INFO] Booting worker with pid: 15816
2014-01-31 04:58:21 [15816] [ERROR] Exception in worker process:
Traceback (most recent call last):
  File "/home/comunidad/local/lib/python2.7/site-packages/gunicorn/arbiter.py", line 495, in spawn_worker
    worker.init_process()
  File "/home/comunidad/local/lib/python2.7/site-packages/gunicorn/workers/base.py", line 106, in init_process
    self.wsgi = self.app.wsgi()
  File "/home/comunidad/local/lib/python2.7/site-packages/gunicorn/app/base.py", line 114, in wsgi
    self.callable = self.load()
  File "/home/comunidad/local/lib/python2.7/site-packages/gunicorn/app/djangoapp.py", line 142, in load
    return mod.make_command_wsgi_application(self.admin_media_path)
  File "/home/comunidad/local/lib/python2.7/site-packages/gunicorn/app/django_wsgi.py", line 113, in make_command_wsgi_application
    reload_django_settings()
  File "/home/comunidad/local/lib/python2.7/site-packages/gunicorn/app/django_wsgi.py", line 109, in reload_django_settings
    logging_config_func(settings.LOGGING)
  File "/usr/lib/python2.7/logging/config.py", line 803, in dictConfig
    dictConfigClass(config).configure()
  File "/usr/lib/python2.7/logging/config.py", line 509, in configure
    raise ValueError("dictionary doesn't specify a version")
ValueError: dictionary doesn't specify a version
Traceback (most recent call last):
  File "/home/comunidad/local/lib/python2.7/site-packages/gunicorn/arbiter.py", line 495, in spawn_worker
    worker.init_process()
  File "/home/comunidad/local/lib/python2.7/site-packages/gunicorn/workers/base.py", line 106, in init_process
    self.wsgi = self.app.wsgi()
  File "/home/comunidad/local/lib/python2.7/site-packages/gunicorn/app/base.py", line 114, in wsgi
    self.callable = self.load()
  File "/home/comunidad/local/lib/python2.7/site-packages/gunicorn/app/djangoapp.py", line 142, in load
    return mod.make_command_wsgi_application(self.admin_media_path)
  File "/home/comunidad/local/lib/python2.7/site-packages/gunicorn/app/django_wsgi.py", line 113, in make_command_wsgi_application
    reload_django_settings()
  File "/home/comunidad/local/lib/python2.7/site-packages/gunicorn/app/django_wsgi.py", line 109, in reload_django_settings
    logging_config_func(settings.LOGGING)
  File "/usr/lib/python2.7/logging/config.py", line 803, in dictConfig
    dictConfigClass(config).configure()
  File "/usr/lib/python2.7/logging/config.py", line 509, in configure
    raise ValueError("dictionary doesn't specify a version")
ValueError: dictionary doesn't specify a version
2014-01-31 04:58:21 [15816] [INFO] Worker exiting (pid: 15816)
2014-01-31 04:58:21 [15817] [INFO] Booting worker with pid: 15817
2014-01-31 04:58:21 [15817] [ERROR] Exception in worker process:
Traceback (most recent call last):
  File "/home/comunidad/local/lib/python2.7/site-packages/gunicorn/arbiter.py", line 495, in spawn_worker
    worker.init_process()
  File "/home/comunidad/local/lib/python2.7/site-packages/gunicorn/workers/base.py", line 106, in init_process
    self.wsgi = self.app.wsgi()
  File "/home/comunidad/local/lib/python2.7/site-packages/gunicorn/app/base.py", line 114, in wsgi
    self.callable = self.load()
  File "/home/comunidad/local/lib/python2.7/site-packages/gunicorn/app/djangoapp.py", line 142, in load
    return mod.make_command_wsgi_application(self.admin_media_path)
  File "/home/comunidad/local/lib/python2.7/site-packages/gunicorn/app/django_wsgi.py", line 113, in make_command_wsgi_application
    reload_django_settings()
  File "/home/comunidad/local/lib/python2.7/site-packages/gunicorn/app/django_wsgi.py", line 109, in reload_django_settings
    logging_config_func(settings.LOGGING)
  File "/usr/lib/python2.7/logging/config.py", line 803, in dictConfig
    dictConfigClass(config).configure()
  File "/usr/lib/python2.7/logging/config.py", line 509, in configure
    raise ValueError("dictionary doesn't specify a version")
ValueError: dictionary doesn't specify a version
Traceback (most recent call last):
  File "/home/comunidad/local/lib/python2.7/site-packages/gunicorn/arbiter.py", line 495, in spawn_worker
    worker.init_process()
  File "/home/comunidad/local/lib/python2.7/site-packages/gunicorn/workers/base.py", line 106, in init_process
    self.wsgi = self.app.wsgi()
  File "/home/comunidad/local/lib/python2.7/site-packages/gunicorn/app/base.py", line 114, in wsgi
    self.callable = self.load()
  File "/home/comunidad/local/lib/python2.7/site-packages/gunicorn/app/djangoapp.py", line 142, in load
    return mod.make_command_wsgi_application(self.admin_media_path)
  File "/home/comunidad/local/lib/python2.7/site-packages/gunicorn/app/django_wsgi.py", line 113, in make_command_wsgi_application
    reload_django_settings()
  File "/home/comunidad/local/lib/python2.7/site-packages/gunicorn/app/django_wsgi.py", line 109, in reload_django_settings
    logging_config_func(settings.LOGGING)
  File "/usr/lib/python2.7/logging/config.py", line 803, in dictConfig
    dictConfigClass(config).configure()
  File "/usr/lib/python2.7/logging/config.py", line 509, in configure
    raise ValueError("dictionary doesn't specify a version")
ValueError: dictionary doesn't specify a version
2014-01-31 04:58:21 [15817] [INFO] Worker exiting (pid: 15817)
2014-01-31 04:58:21 [15818] [INFO] Booting worker with pid: 15818
2014-01-31 04:58:21 [15818] [ERROR] Exception in worker process:
Traceback (most recent call last):
  File "/home/comunidad/local/lib/python2.7/site-packages/gunicorn/arbiter.py", line 495, in spawn_worker
    worker.init_process()
  File "/home/comunidad/local/lib/python2.7/site-packages/gunicorn/workers/base.py", line 106, in init_process
    self.wsgi = self.app.wsgi()
  File "/home/comunidad/local/lib/python2.7/site-packages/gunicorn/app/base.py", line 114, in wsgi
    self.callable = self.load()
  File "/home/comunidad/local/lib/python2.7/site-packages/gunicorn/app/djangoapp.py", line 142, in load
    return mod.make_command_wsgi_application(self.admin_media_path)
  File "/home/comunidad/local/lib/python2.7/site-packages/gunicorn/app/django_wsgi.py", line 113, in make_command_wsgi_application
    reload_django_settings()
  File "/home/comunidad/local/lib/python2.7/site-packages/gunicorn/app/django_wsgi.py", line 109, in reload_django_settings
    logging_config_func(settings.LOGGING)
  File "/usr/lib/python2.7/logging/config.py", line 803, in dictConfig
    dictConfigClass(config).configure()
  File "/usr/lib/python2.7/logging/config.py", line 509, in configure
    raise ValueError("dictionary doesn't specify a version")
ValueError: dictionary doesn't specify a version
Traceback (most recent call last):
  File "/home/comunidad/local/lib/python2.7/site-packages/gunicorn/arbiter.py", line 495, in spawn_worker
    worker.init_process()
  File "/home/comunidad/local/lib/python2.7/site-packages/gunicorn/workers/base.py", line 106, in init_process
    self.wsgi = self.app.wsgi()
  File "/home/comunidad/local/lib/python2.7/site-packages/gunicorn/app/base.py", line 114, in wsgi
    self.callable = self.load()
  File "/home/comunidad/local/lib/python2.7/site-packages/gunicorn/app/djangoapp.py", line 142, in load
    return mod.make_command_wsgi_application(self.admin_media_path)
  File "/home/comunidad/local/lib/python2.7/site-packages/gunicorn/app/django_wsgi.py", line 113, in make_command_wsgi_application
    reload_django_settings()
  File "/home/comunidad/local/lib/python2.7/site-packages/gunicorn/app/django_wsgi.py", line 109, in reload_django_settings
    logging_config_func(settings.LOGGING)
  File "/usr/lib/python2.7/logging/config.py", line 803, in dictConfig
    dictConfigClass(config).configure()
  File "/usr/lib/python2.7/logging/config.py", line 509, in configure
    raise ValueError("dictionary doesn't specify a version")
ValueError: dictionary doesn't specify a version
2014-01-31 04:58:21 [15818] [INFO] Worker exiting (pid: 15818)
2014-01-31 04:58:21 [15819] [INFO] Booting worker with pid: 15819
2014-01-31 04:58:21 [15819] [ERROR] Exception in worker process:
Traceback (most recent call last):
  File "/home/comunidad/local/lib/python2.7/site-packages/gunicorn/arbiter.py", line 495, in spawn_worker
    worker.init_process()
  File "/home/comunidad/local/lib/python2.7/site-packages/gunicorn/workers/base.py", line 106, in init_process
    self.wsgi = self.app.wsgi()
  File "/home/comunidad/local/lib/python2.7/site-packages/gunicorn/app/base.py", line 114, in wsgi
    self.callable = self.load()
  File "/home/comunidad/local/lib/python2.7/site-packages/gunicorn/app/djangoapp.py", line 142, in load
    return mod.make_command_wsgi_application(self.admin_media_path)
  File "/home/comunidad/local/lib/python2.7/site-packages/gunicorn/app/django_wsgi.py", line 113, in make_command_wsgi_application
    reload_django_settings()
  File "/home/comunidad/local/lib/python2.7/site-packages/gunicorn/app/django_wsgi.py", line 109, in reload_django_settings
    logging_config_func(settings.LOGGING)
  File "/usr/lib/python2.7/logging/config.py", line 803, in dictConfig
    dictConfigClass(config).configure()
  File "/usr/lib/python2.7/logging/config.py", line 509, in configure
    raise ValueError("dictionary doesn't specify a version")
ValueError: dictionary doesn't specify a version
Traceback (most recent call last):
  File "/home/comunidad/local/lib/python2.7/site-packages/gunicorn/arbiter.py", line 495, in spawn_worker
    worker.init_process()
  File "/home/comunidad/local/lib/python2.7/site-packages/gunicorn/workers/base.py", line 106, in init_process
    self.wsgi = self.app.wsgi()
  File "/home/comunidad/local/lib/python2.7/site-packages/gunicorn/app/base.py", line 114, in wsgi
    self.callable = self.load()
  File "/home/comunidad/local/lib/python2.7/site-packages/gunicorn/app/djangoapp.py", line 142, in load
    return mod.make_command_wsgi_application(self.admin_media_path)
  File "/home/comunidad/local/lib/python2.7/site-packages/gunicorn/app/django_wsgi.py", line 113, in make_command_wsgi_application
    reload_django_settings()
  File "/home/comunidad/local/lib/python2.7/site-packages/gunicorn/app/django_wsgi.py", line 109, in reload_django_settings
    logging_config_func(settings.LOGGING)
  File "/usr/lib/python2.7/logging/config.py", line 803, in dictConfig
    dictConfigClass(config).configure()
  File "/usr/lib/python2.7/logging/config.py", line 509, in configure
    raise ValueError("dictionary doesn't specify a version")
ValueError: dictionary doesn't specify a version
2014-01-31 04:58:21 [15819] [INFO] Worker exiting (pid: 15819)
2014-01-31 04:58:21 [15820] [INFO] Booting worker with pid: 15820
2014-01-31 04:58:21 [15820] [ERROR] Exception in worker process:
Traceback (most recent call last):
  File "/home/comunidad/local/lib/python2.7/site-packages/gunicorn/arbiter.py", line 495, in spawn_worker
    worker.init_process()
  File "/home/comunidad/local/lib/python2.7/site-packages/gunicorn/workers/base.py", line 106, in init_process
    self.wsgi = self.app.wsgi()
  File "/home/comunidad/local/lib/python2.7/site-packages/gunicorn/app/base.py", line 114, in wsgi
    self.callable = self.load()
  File "/home/comunidad/local/lib/python2.7/site-packages/gunicorn/app/djangoapp.py", line 142, in load
    return mod.make_command_wsgi_application(self.admin_media_path)
  File "/home/comunidad/local/lib/python2.7/site-packages/gunicorn/app/django_wsgi.py", line 113, in make_command_wsgi_application
    reload_django_settings()
  File "/home/comunidad/local/lib/python2.7/site-packages/gunicorn/app/django_wsgi.py", line 109, in reload_django_settings
    logging_config_func(settings.LOGGING)
  File "/usr/lib/python2.7/logging/config.py", line 803, in dictConfig
    dictConfigClass(config).configure()
  File "/usr/lib/python2.7/logging/config.py", line 509, in configure
    raise ValueError("dictionary doesn't specify a version")
ValueError: dictionary doesn't specify a version
Traceback (most recent call last):
  File "/home/comunidad/local/lib/python2.7/site-packages/gunicorn/arbiter.py", line 495, in spawn_worker
    worker.init_process()
  File "/home/comunidad/local/lib/python2.7/site-packages/gunicorn/workers/base.py", line 106, in init_process
    self.wsgi = self.app.wsgi()
  File "/home/comunidad/local/lib/python2.7/site-packages/gunicorn/app/base.py", line 114, in wsgi
    self.callable = self.load()
  File "/home/comunidad/local/lib/python2.7/site-packages/gunicorn/app/djangoapp.py", line 142, in load
    return mod.make_command_wsgi_application(self.admin_media_path)
  File "/home/comunidad/local/lib/python2.7/site-packages/gunicorn/app/django_wsgi.py", line 113, in make_command_wsgi_application
    reload_django_settings()
  File "/home/comunidad/local/lib/python2.7/site-packages/gunicorn/app/django_wsgi.py", line 109, in reload_django_settings
    logging_config_func(settings.LOGGING)
  File "/usr/lib/python2.7/logging/config.py", line 803, in dictConfig
    dictConfigClass(config).configure()
  File "/usr/lib/python2.7/logging/config.py", line 509, in configure
    raise ValueError("dictionary doesn't specify a version")
ValueError: dictionary doesn't specify a version
2014-01-31 04:58:21 [15820] [INFO] Worker exiting (pid: 15820)
2014-01-31 04:58:21 [15821] [INFO] Booting worker with pid: 15821
2014-01-31 04:58:21 [15821] [ERROR] Exception in worker process:
Traceback (most recent call last):
  File "/home/comunidad/local/lib/python2.7/site-packages/gunicorn/arbiter.py", line 495, in spawn_worker
    worker.init_process()
  File "/home/comunidad/local/lib/python2.7/site-packages/gunicorn/workers/base.py", line 106, in init_process
    self.wsgi = self.app.wsgi()
  File "/home/comunidad/local/lib/python2.7/site-packages/gunicorn/app/base.py", line 114, in wsgi
    self.callable = self.load()
  File "/home/comunidad/local/lib/python2.7/site-packages/gunicorn/app/djangoapp.py", line 142, in load
    return mod.make_command_wsgi_application(self.admin_media_path)
  File "/home/comunidad/local/lib/python2.7/site-packages/gunicorn/app/django_wsgi.py", line 113, in make_command_wsgi_application
    reload_django_settings()
  File "/home/comunidad/local/lib/python2.7/site-packages/gunicorn/app/django_wsgi.py", line 109, in reload_django_settings
    logging_config_func(settings.LOGGING)
  File "/usr/lib/python2.7/logging/config.py", line 803, in dictConfig
    dictConfigClass(config).configure()
  File "/usr/lib/python2.7/logging/config.py", line 509, in configure
    raise ValueError("dictionary doesn't specify a version")
ValueError: dictionary doesn't specify a version
Traceback (most recent call last):
  File "/home/comunidad/local/lib/python2.7/site-packages/gunicorn/arbiter.py", line 495, in spawn_worker
    worker.init_process()
  File "/home/comunidad/local/lib/python2.7/site-packages/gunicorn/workers/base.py", line 106, in init_process
    self.wsgi = self.app.wsgi()
  File "/home/comunidad/local/lib/python2.7/site-packages/gunicorn/app/base.py", line 114, in wsgi
    self.callable = self.load()
  File "/home/comunidad/local/lib/python2.7/site-packages/gunicorn/app/djangoapp.py", line 142, in load
    return mod.make_command_wsgi_application(self.admin_media_path)
  File "/home/comunidad/local/lib/python2.7/site-packages/gunicorn/app/django_wsgi.py", line 113, in make_command_wsgi_application
    reload_django_settings()
  File "/home/comunidad/local/lib/python2.7/site-packages/gunicorn/app/django_wsgi.py", line 109, in reload_django_settings
    logging_config_func(settings.LOGGING)
  File "/usr/lib/python2.7/logging/config.py", line 803, in dictConfig
    dictConfigClass(config).configure()
  File "/usr/lib/python2.7/logging/config.py", line 509, in configure
    raise ValueError("dictionary doesn't specify a version")
ValueError: dictionary doesn't specify a version
2014-01-31 04:58:21 [15821] [INFO] Worker exiting (pid: 15821)
2014-01-31 04:58:21 [15822] [INFO] Booting worker with pid: 15822
2014-01-31 04:58:21 [15822] [ERROR] Exception in worker process:
Traceback (most recent call last):
  File "/home/comunidad/local/lib/python2.7/site-packages/gunicorn/arbiter.py", line 495, in spawn_worker
    worker.init_process()
  File "/home/comunidad/local/lib/python2.7/site-packages/gunicorn/workers/base.py", line 106, in init_process
    self.wsgi = self.app.wsgi()
  File "/home/comunidad/local/lib/python2.7/site-packages/gunicorn/app/base.py", line 114, in wsgi
    self.callable = self.load()
  File "/home/comunidad/local/lib/python2.7/site-packages/gunicorn/app/djangoapp.py", line 142, in load
    return mod.make_command_wsgi_application(self.admin_media_path)
  File "/home/comunidad/local/lib/python2.7/site-packages/gunicorn/app/django_wsgi.py", line 113, in make_command_wsgi_application
    reload_django_settings()
  File "/home/comunidad/local/lib/python2.7/site-packages/gunicorn/app/django_wsgi.py", line 109, in reload_django_settings
    logging_config_func(settings.LOGGING)
  File "/usr/lib/python2.7/logging/config.py", line 803, in dictConfig
    dictConfigClass(config).configure()
  File "/usr/lib/python2.7/logging/config.py", line 509, in configure
    raise ValueError("dictionary doesn't specify a version")
ValueError: dictionary doesn't specify a version
Traceback (most recent call last):
  File "/home/comunidad/local/lib/python2.7/site-packages/gunicorn/arbiter.py", line 495, in spawn_worker
    worker.init_process()
  File "/home/comunidad/local/lib/python2.7/site-packages/gunicorn/workers/base.py", line 106, in init_process
    self.wsgi = self.app.wsgi()
  File "/home/comunidad/local/lib/python2.7/site-packages/gunicorn/app/base.py", line 114, in wsgi
    self.callable = self.load()
  File "/home/comunidad/local/lib/python2.7/site-packages/gunicorn/app/djangoapp.py", line 142, in load
    return mod.make_command_wsgi_application(self.admin_media_path)
  File "/home/comunidad/local/lib/python2.7/site-packages/gunicorn/app/django_wsgi.py", line 113, in make_command_wsgi_application
    reload_django_settings()
  File "/home/comunidad/local/lib/python2.7/site-packages/gunicorn/app/django_wsgi.py", line 109, in reload_django_settings
    logging_config_func(settings.LOGGING)
  File "/usr/lib/python2.7/logging/config.py", line 803, in dictConfig
    dictConfigClass(config).configure()
  File "/usr/lib/python2.7/logging/config.py", line 509, in configure
    raise ValueError("dictionary doesn't specify a version")
ValueError: dictionary doesn't specify a version
2014-01-31 04:58:21 [15822] [INFO] Worker exiting (pid: 15822)
Traceback (most recent call last):
  File "/home/comunidad/django-node.js-nginx/website/manage.py", line 10, in <module>
    execute_from_command_line(sys.argv)
  File "/home/comunidad/local/lib/python2.7/site-packages/django/core/management/__init__.py", line 399, in execute_from_command_line
    utility.execute()
  File "/home/comunidad/local/lib/python2.7/site-packages/django/core/management/__init__.py", line 392, in execute
    self.fetch_command(subcommand).run_from_argv(self.argv)
  File "/home/comunidad/local/lib/python2.7/site-packages/django/core/management/base.py", line 242, in run_from_argv
    self.execute(*args, **options.__dict__)
  File "/home/comunidad/local/lib/python2.7/site-packages/django/core/management/base.py", line 285, in execute
    output = self.handle(*args, **options)
  File "/home/comunidad/local/lib/python2.7/site-packages/gunicorn/management/commands/run_gunicorn.py", line 101, in handle
    DjangoApplicationCommand(options, admin_media_path).run()
  File "/home/comunidad/local/lib/python2.7/site-packages/gunicorn/app/base.py", line 143, in run
    Arbiter(self).run()
  File "/home/comunidad/local/lib/python2.7/site-packages/gunicorn/arbiter.py", line 203, in run
    self.halt(reason=inst.reason, exit_status=inst.exit_status)
  File "/home/comunidad/local/lib/python2.7/site-packages/gunicorn/arbiter.py", line 298, in halt
    self.stop()
  File "/home/comunidad/local/lib/python2.7/site-packages/gunicorn/arbiter.py", line 341, in stop
    self.reap_workers()
  File "/home/comunidad/local/lib/python2.7/site-packages/gunicorn/arbiter.py", line 452, in reap_workers
    raise HaltServer(reason, self.WORKER_BOOT_ERROR)
gunicorn.errors.HaltServer: <HaltServer 'Worker failed to boot.' 3>
2014-01-31 04:58:22 [15823] [INFO] Starting gunicorn 18.0
2014-01-31 04:58:22 [15823] [INFO] Listening at: http://127.0.0.1:8008 (15823)
2014-01-31 04:58:22 [15823] [INFO] Using worker: sync
2014-01-31 04:58:22 [15828] [INFO] Booting worker with pid: 15828
2014-01-31 04:58:22 [15828] [ERROR] Exception in worker process:
Traceback (most recent call last):
  File "/home/comunidad/local/lib/python2.7/site-packages/gunicorn/arbiter.py", line 495, in spawn_worker
    worker.init_process()
  File "/home/comunidad/local/lib/python2.7/site-packages/gunicorn/workers/base.py", line 106, in init_process
    self.wsgi = self.app.wsgi()
  File "/home/comunidad/local/lib/python2.7/site-packages/gunicorn/app/base.py", line 114, in wsgi
    self.callable = self.load()
  File "/home/comunidad/local/lib/python2.7/site-packages/gunicorn/app/djangoapp.py", line 142, in load
    return mod.make_command_wsgi_application(self.admin_media_path)
  File "/home/comunidad/local/lib/python2.7/site-packages/gunicorn/app/django_wsgi.py", line 113, in make_command_wsgi_application
    reload_django_settings()
  File "/home/comunidad/local/lib/python2.7/site-packages/gunicorn/app/django_wsgi.py", line 109, in reload_django_settings
    logging_config_func(settings.LOGGING)
  File "/usr/lib/python2.7/logging/config.py", line 803, in dictConfig
    dictConfigClass(config).configure()
  File "/usr/lib/python2.7/logging/config.py", line 509, in configure
    raise ValueError("dictionary doesn't specify a version")
ValueError: dictionary doesn't specify a version
Traceback (most recent call last):
  File "/home/comunidad/local/lib/python2.7/site-packages/gunicorn/arbiter.py", line 495, in spawn_worker
    worker.init_process()
  File "/home/comunidad/local/lib/python2.7/site-packages/gunicorn/workers/base.py", line 106, in init_process
    self.wsgi = self.app.wsgi()
  File "/home/comunidad/local/lib/python2.7/site-packages/gunicorn/app/base.py", line 114, in wsgi
    self.callable = self.load()
  File "/home/comunidad/local/lib/python2.7/site-packages/gunicorn/app/djangoapp.py", line 142, in load
    return mod.make_command_wsgi_application(self.admin_media_path)
  File "/home/comunidad/local/lib/python2.7/site-packages/gunicorn/app/django_wsgi.py", line 113, in make_command_wsgi_application
    reload_django_settings()
  File "/home/comunidad/local/lib/python2.7/site-packages/gunicorn/app/django_wsgi.py", line 109, in reload_django_settings
    logging_config_func(settings.LOGGING)
  File "/usr/lib/python2.7/logging/config.py", line 803, in dictConfig
    dictConfigClass(config).configure()
  File "/usr/lib/python2.7/logging/config.py", line 509, in configure
    raise ValueError("dictionary doesn't specify a version")
ValueError: dictionary doesn't specify a version
2014-01-31 04:58:22 [15828] [INFO] Worker exiting (pid: 15828)
2014-01-31 04:58:23 [15829] [INFO] Booting worker with pid: 15829
2014-01-31 04:58:23 [15829] [ERROR] Exception in worker process:
Traceback (most recent call last):
  File "/home/comunidad/local/lib/python2.7/site-packages/gunicorn/arbiter.py", line 495, in spawn_worker
    worker.init_process()
  File "/home/comunidad/local/lib/python2.7/site-packages/gunicorn/workers/base.py", line 106, in init_process
    self.wsgi = self.app.wsgi()
  File "/home/comunidad/local/lib/python2.7/site-packages/gunicorn/app/base.py", line 114, in wsgi
    self.callable = self.load()
  File "/home/comunidad/local/lib/python2.7/site-packages/gunicorn/app/djangoapp.py", line 142, in load
    return mod.make_command_wsgi_application(self.admin_media_path)
  File "/home/comunidad/local/lib/python2.7/site-packages/gunicorn/app/django_wsgi.py", line 113, in make_command_wsgi_application
    reload_django_settings()
  File "/home/comunidad/local/lib/python2.7/site-packages/gunicorn/app/django_wsgi.py", line 109, in reload_django_settings
    logging_config_func(settings.LOGGING)
  File "/usr/lib/python2.7/logging/config.py", line 803, in dictConfig
    dictConfigClass(config).configure()
  File "/usr/lib/python2.7/logging/config.py", line 509, in configure
    raise ValueError("dictionary doesn't specify a version")
ValueError: dictionary doesn't specify a version
Traceback (most recent call last):
  File "/home/comunidad/local/lib/python2.7/site-packages/gunicorn/arbiter.py", line 495, in spawn_worker
    worker.init_process()
  File "/home/comunidad/local/lib/python2.7/site-packages/gunicorn/workers/base.py", line 106, in init_process
    self.wsgi = self.app.wsgi()
  File "/home/comunidad/local/lib/python2.7/site-packages/gunicorn/app/base.py", line 114, in wsgi
    self.callable = self.load()
  File "/home/comunidad/local/lib/python2.7/site-packages/gunicorn/app/djangoapp.py", line 142, in load
    return mod.make_command_wsgi_application(self.admin_media_path)
  File "/home/comunidad/local/lib/python2.7/site-packages/gunicorn/app/django_wsgi.py", line 113, in make_command_wsgi_application
    reload_django_settings()
  File "/home/comunidad/local/lib/python2.7/site-packages/gunicorn/app/django_wsgi.py", line 109, in reload_django_settings
    logging_config_func(settings.LOGGING)
  File "/usr/lib/python2.7/logging/config.py", line 803, in dictConfig
    dictConfigClass(config).configure()
  File "/usr/lib/python2.7/logging/config.py", line 509, in configure
    raise ValueError("dictionary doesn't specify a version")
ValueError: dictionary doesn't specify a version
2014-01-31 04:58:23 [15829] [INFO] Worker exiting (pid: 15829)
2014-01-31 04:58:23 [15830] [INFO] Booting worker with pid: 15830
2014-01-31 04:58:23 [15830] [ERROR] Exception in worker process:
Traceback (most recent call last):
  File "/home/comunidad/local/lib/python2.7/site-packages/gunicorn/arbiter.py", line 495, in spawn_worker
    worker.init_process()
  File "/home/comunidad/local/lib/python2.7/site-packages/gunicorn/workers/base.py", line 106, in init_process
    self.wsgi = self.app.wsgi()
  File "/home/comunidad/local/lib/python2.7/site-packages/gunicorn/app/base.py", line 114, in wsgi
    self.callable = self.load()
  File "/home/comunidad/local/lib/python2.7/site-packages/gunicorn/app/djangoapp.py", line 142, in load
    return mod.make_command_wsgi_application(self.admin_media_path)
  File "/home/comunidad/local/lib/python2.7/site-packages/gunicorn/app/django_wsgi.py", line 113, in make_command_wsgi_application
    reload_django_settings()
  File "/home/comunidad/local/lib/python2.7/site-packages/gunicorn/app/django_wsgi.py", line 109, in reload_django_settings
    logging_config_func(settings.LOGGING)
  File "/usr/lib/python2.7/logging/config.py", line 803, in dictConfig
    dictConfigClass(config).configure()
  File "/usr/lib/python2.7/logging/config.py", line 509, in configure
    raise ValueError("dictionary doesn't specify a version")
ValueError: dictionary doesn't specify a version
Traceback (most recent call last):
  File "/home/comunidad/local/lib/python2.7/site-packages/gunicorn/arbiter.py", line 495, in spawn_worker
    worker.init_process()
  File "/home/comunidad/local/lib/python2.7/site-packages/gunicorn/workers/base.py", line 106, in init_process
    self.wsgi = self.app.wsgi()
  File "/home/comunidad/local/lib/python2.7/site-packages/gunicorn/app/base.py", line 114, in wsgi
    self.callable = self.load()
  File "/home/comunidad/local/lib/python2.7/site-packages/gunicorn/app/djangoapp.py", line 142, in load
    return mod.make_command_wsgi_application(self.admin_media_path)
  File "/home/comunidad/local/lib/python2.7/site-packages/gunicorn/app/django_wsgi.py", line 113, in make_command_wsgi_application
    reload_django_settings()
  File "/home/comunidad/local/lib/python2.7/site-packages/gunicorn/app/django_wsgi.py", line 109, in reload_django_settings
    logging_config_func(settings.LOGGING)
  File "/usr/lib/python2.7/logging/config.py", line 803, in dictConfig
    dictConfigClass(config).configure()
  File "/usr/lib/python2.7/logging/config.py", line 509, in configure
    raise ValueError("dictionary doesn't specify a version")
ValueError: dictionary doesn't specify a version
2014-01-31 04:58:23 [15830] [INFO] Worker exiting (pid: 15830)
2014-01-31 04:58:23 [15831] [INFO] Booting worker with pid: 15831
2014-01-31 04:58:23 [15831] [ERROR] Exception in worker process:
Traceback (most recent call last):
  File "/home/comunidad/local/lib/python2.7/site-packages/gunicorn/arbiter.py", line 495, in spawn_worker
    worker.init_process()
  File "/home/comunidad/local/lib/python2.7/site-packages/gunicorn/workers/base.py", line 106, in init_process
    self.wsgi = self.app.wsgi()
  File "/home/comunidad/local/lib/python2.7/site-packages/gunicorn/app/base.py", line 114, in wsgi
    self.callable = self.load()
  File "/home/comunidad/local/lib/python2.7/site-packages/gunicorn/app/djangoapp.py", line 142, in load
    return mod.make_command_wsgi_application(self.admin_media_path)
  File "/home/comunidad/local/lib/python2.7/site-packages/gunicorn/app/django_wsgi.py", line 113, in make_command_wsgi_application
    reload_django_settings()
  File "/home/comunidad/local/lib/python2.7/site-packages/gunicorn/app/django_wsgi.py", line 109, in reload_django_settings
    logging_config_func(settings.LOGGING)
  File "/usr/lib/python2.7/logging/config.py", line 803, in dictConfig
    dictConfigClass(config).configure()
  File "/usr/lib/python2.7/logging/config.py", line 509, in configure
    raise ValueError("dictionary doesn't specify a version")
ValueError: dictionary doesn't specify a version
Traceback (most recent call last):
  File "/home/comunidad/local/lib/python2.7/site-packages/gunicorn/arbiter.py", line 495, in spawn_worker
    worker.init_process()
  File "/home/comunidad/local/lib/python2.7/site-packages/gunicorn/workers/base.py", line 106, in init_process
    self.wsgi = self.app.wsgi()
  File "/home/comunidad/local/lib/python2.7/site-packages/gunicorn/app/base.py", line 114, in wsgi
    self.callable = self.load()
  File "/home/comunidad/local/lib/python2.7/site-packages/gunicorn/app/djangoapp.py", line 142, in load
    return mod.make_command_wsgi_application(self.admin_media_path)
  File "/home/comunidad/local/lib/python2.7/site-packages/gunicorn/app/django_wsgi.py", line 113, in make_command_wsgi_application
    reload_django_settings()
  File "/home/comunidad/local/lib/python2.7/site-packages/gunicorn/app/django_wsgi.py", line 109, in reload_django_settings
    logging_config_func(settings.LOGGING)
  File "/usr/lib/python2.7/logging/config.py", line 803, in dictConfig
    dictConfigClass(config).configure()
  File "/usr/lib/python2.7/logging/config.py", line 509, in configure
    raise ValueError("dictionary doesn't specify a version")
ValueError: dictionary doesn't specify a version
2014-01-31 04:58:23 [15831] [INFO] Worker exiting (pid: 15831)
2014-01-31 04:58:23 [15832] [INFO] Booting worker with pid: 15832
2014-01-31 04:58:23 [15832] [ERROR] Exception in worker process:
Traceback (most recent call last):
  File "/home/comunidad/local/lib/python2.7/site-packages/gunicorn/arbiter.py", line 495, in spawn_worker
    worker.init_process()
  File "/home/comunidad/local/lib/python2.7/site-packages/gunicorn/workers/base.py", line 106, in init_process
    self.wsgi = self.app.wsgi()
  File "/home/comunidad/local/lib/python2.7/site-packages/gunicorn/app/base.py", line 114, in wsgi
    self.callable = self.load()
  File "/home/comunidad/local/lib/python2.7/site-packages/gunicorn/app/djangoapp.py", line 142, in load
    return mod.make_command_wsgi_application(self.admin_media_path)
  File "/home/comunidad/local/lib/python2.7/site-packages/gunicorn/app/django_wsgi.py", line 113, in make_command_wsgi_application
    reload_django_settings()
  File "/home/comunidad/local/lib/python2.7/site-packages/gunicorn/app/django_wsgi.py", line 109, in reload_django_settings
    logging_config_func(settings.LOGGING)
  File "/usr/lib/python2.7/logging/config.py", line 803, in dictConfig
    dictConfigClass(config).configure()
  File "/usr/lib/python2.7/logging/config.py", line 509, in configure
    raise ValueError("dictionary doesn't specify a version")
ValueError: dictionary doesn't specify a version
Traceback (most recent call last):
  File "/home/comunidad/local/lib/python2.7/site-packages/gunicorn/arbiter.py", line 495, in spawn_worker
    worker.init_process()
  File "/home/comunidad/local/lib/python2.7/site-packages/gunicorn/workers/base.py", line 106, in init_process
    self.wsgi = self.app.wsgi()
  File "/home/comunidad/local/lib/python2.7/site-packages/gunicorn/app/base.py", line 114, in wsgi
    self.callable = self.load()
  File "/home/comunidad/local/lib/python2.7/site-packages/gunicorn/app/djangoapp.py", line 142, in load
    return mod.make_command_wsgi_application(self.admin_media_path)
  File "/home/comunidad/local/lib/python2.7/site-packages/gunicorn/app/django_wsgi.py", line 113, in make_command_wsgi_application
    reload_django_settings()
  File "/home/comunidad/local/lib/python2.7/site-packages/gunicorn/app/django_wsgi.py", line 109, in reload_django_settings
    logging_config_func(settings.LOGGING)
  File "/usr/lib/python2.7/logging/config.py", line 803, in dictConfig
    dictConfigClass(config).configure()
  File "/usr/lib/python2.7/logging/config.py", line 509, in configure
    raise ValueError("dictionary doesn't specify a version")
ValueError: dictionary doesn't specify a version
2014-01-31 04:58:23 [15832] [INFO] Worker exiting (pid: 15832)
2014-01-31 04:58:23 [15833] [INFO] Booting worker with pid: 15833
2014-01-31 04:58:23 [15833] [ERROR] Exception in worker process:
Traceback (most recent call last):
  File "/home/comunidad/local/lib/python2.7/site-packages/gunicorn/arbiter.py", line 495, in spawn_worker
    worker.init_process()
  File "/home/comunidad/local/lib/python2.7/site-packages/gunicorn/workers/base.py", line 106, in init_process
    self.wsgi = self.app.wsgi()
  File "/home/comunidad/local/lib/python2.7/site-packages/gunicorn/app/base.py", line 114, in wsgi
    self.callable = self.load()
  File "/home/comunidad/local/lib/python2.7/site-packages/gunicorn/app/djangoapp.py", line 142, in load
    return mod.make_command_wsgi_application(self.admin_media_path)
  File "/home/comunidad/local/lib/python2.7/site-packages/gunicorn/app/django_wsgi.py", line 113, in make_command_wsgi_application
    reload_django_settings()
  File "/home/comunidad/local/lib/python2.7/site-packages/gunicorn/app/django_wsgi.py", line 109, in reload_django_settings
    logging_config_func(settings.LOGGING)
  File "/usr/lib/python2.7/logging/config.py", line 803, in dictConfig
    dictConfigClass(config).configure()
  File "/usr/lib/python2.7/logging/config.py", line 509, in configure
    raise ValueError("dictionary doesn't specify a version")
ValueError: dictionary doesn't specify a version
Traceback (most recent call last):
  File "/home/comunidad/local/lib/python2.7/site-packages/gunicorn/arbiter.py", line 495, in spawn_worker
    worker.init_process()
  File "/home/comunidad/local/lib/python2.7/site-packages/gunicorn/workers/base.py", line 106, in init_process
    self.wsgi = self.app.wsgi()
  File "/home/comunidad/local/lib/python2.7/site-packages/gunicorn/app/base.py", line 114, in wsgi
    self.callable = self.load()
  File "/home/comunidad/local/lib/python2.7/site-packages/gunicorn/app/djangoapp.py", line 142, in load
    return mod.make_command_wsgi_application(self.admin_media_path)
  File "/home/comunidad/local/lib/python2.7/site-packages/gunicorn/app/django_wsgi.py", line 113, in make_command_wsgi_application
    reload_django_settings()
  File "/home/comunidad/local/lib/python2.7/site-packages/gunicorn/app/django_wsgi.py", line 109, in reload_django_settings
    logging_config_func(settings.LOGGING)
  File "/usr/lib/python2.7/logging/config.py", line 803, in dictConfig
    dictConfigClass(config).configure()
  File "/usr/lib/python2.7/logging/config.py", line 509, in configure
    raise ValueError("dictionary doesn't specify a version")
ValueError: dictionary doesn't specify a version
2014-01-31 04:58:23 [15833] [INFO] Worker exiting (pid: 15833)
2014-01-31 04:58:23 [15834] [INFO] Booting worker with pid: 15834
2014-01-31 04:58:23 [15834] [ERROR] Exception in worker process:
Traceback (most recent call last):
  File "/home/comunidad/local/lib/python2.7/site-packages/gunicorn/arbiter.py", line 495, in spawn_worker
    worker.init_process()
  File "/home/comunidad/local/lib/python2.7/site-packages/gunicorn/workers/base.py", line 106, in init_process
    self.wsgi = self.app.wsgi()
  File "/home/comunidad/local/lib/python2.7/site-packages/gunicorn/app/base.py", line 114, in wsgi
    self.callable = self.load()
  File "/home/comunidad/local/lib/python2.7/site-packages/gunicorn/app/djangoapp.py", line 142, in load
    return mod.make_command_wsgi_application(self.admin_media_path)
  File "/home/comunidad/local/lib/python2.7/site-packages/gunicorn/app/django_wsgi.py", line 113, in make_command_wsgi_application
    reload_django_settings()
  File "/home/comunidad/local/lib/python2.7/site-packages/gunicorn/app/django_wsgi.py", line 109, in reload_django_settings
    logging_config_func(settings.LOGGING)
  File "/usr/lib/python2.7/logging/config.py", line 803, in dictConfig
    dictConfigClass(config).configure()
  File "/usr/lib/python2.7/logging/config.py", line 509, in configure
    raise ValueError("dictionary doesn't specify a version")
ValueError: dictionary doesn't specify a version
Traceback (most recent call last):
  File "/home/comunidad/local/lib/python2.7/site-packages/gunicorn/arbiter.py", line 495, in spawn_worker
    worker.init_process()
  File "/home/comunidad/local/lib/python2.7/site-packages/gunicorn/workers/base.py", line 106, in init_process
    self.wsgi = self.app.wsgi()
  File "/home/comunidad/local/lib/python2.7/site-packages/gunicorn/app/base.py", line 114, in wsgi
    self.callable = self.load()
  File "/home/comunidad/local/lib/python2.7/site-packages/gunicorn/app/djangoapp.py", line 142, in load
    return mod.make_command_wsgi_application(self.admin_media_path)
  File "/home/comunidad/local/lib/python2.7/site-packages/gunicorn/app/django_wsgi.py", line 113, in make_command_wsgi_application
    reload_django_settings()
  File "/home/comunidad/local/lib/python2.7/site-packages/gunicorn/app/django_wsgi.py", line 109, in reload_django_settings
    logging_config_func(settings.LOGGING)
  File "/usr/lib/python2.7/logging/config.py", line 803, in dictConfig
    dictConfigClass(config).configure()
  File "/usr/lib/python2.7/logging/config.py", line 509, in configure
    raise ValueError("dictionary doesn't specify a version")
ValueError: dictionary doesn't specify a version
2014-01-31 04:58:23 [15834] [INFO] Worker exiting (pid: 15834)
2014-01-31 04:58:23 [15835] [INFO] Booting worker with pid: 15835
2014-01-31 04:58:23 [15835] [ERROR] Exception in worker process:
Traceback (most recent call last):
  File "/home/comunidad/local/lib/python2.7/site-packages/gunicorn/arbiter.py", line 495, in spawn_worker
    worker.init_process()
  File "/home/comunidad/local/lib/python2.7/site-packages/gunicorn/workers/base.py", line 106, in init_process
    self.wsgi = self.app.wsgi()
  File "/home/comunidad/local/lib/python2.7/site-packages/gunicorn/app/base.py", line 114, in wsgi
    self.callable = self.load()
  File "/home/comunidad/local/lib/python2.7/site-packages/gunicorn/app/djangoapp.py", line 142, in load
    return mod.make_command_wsgi_application(self.admin_media_path)
  File "/home/comunidad/local/lib/python2.7/site-packages/gunicorn/app/django_wsgi.py", line 113, in make_command_wsgi_application
    reload_django_settings()
  File "/home/comunidad/local/lib/python2.7/site-packages/gunicorn/app/django_wsgi.py", line 109, in reload_django_settings
    logging_config_func(settings.LOGGING)
  File "/usr/lib/python2.7/logging/config.py", line 803, in dictConfig
    dictConfigClass(config).configure()
  File "/usr/lib/python2.7/logging/config.py", line 509, in configure
    raise ValueError("dictionary doesn't specify a version")
ValueError: dictionary doesn't specify a version
Traceback (most recent call last):
  File "/home/comunidad/local/lib/python2.7/site-packages/gunicorn/arbiter.py", line 495, in spawn_worker
    worker.init_process()
  File "/home/comunidad/local/lib/python2.7/site-packages/gunicorn/workers/base.py", line 106, in init_process
    self.wsgi = self.app.wsgi()
  File "/home/comunidad/local/lib/python2.7/site-packages/gunicorn/app/base.py", line 114, in wsgi
    self.callable = self.load()
  File "/home/comunidad/local/lib/python2.7/site-packages/gunicorn/app/djangoapp.py", line 142, in load
    return mod.make_command_wsgi_application(self.admin_media_path)
  File "/home/comunidad/local/lib/python2.7/site-packages/gunicorn/app/django_wsgi.py", line 113, in make_command_wsgi_application
    reload_django_settings()
  File "/home/comunidad/local/lib/python2.7/site-packages/gunicorn/app/django_wsgi.py", line 109, in reload_django_settings
    logging_config_func(settings.LOGGING)
  File "/usr/lib/python2.7/logging/config.py", line 803, in dictConfig
    dictConfigClass(config).configure()
  File "/usr/lib/python2.7/logging/config.py", line 509, in configure
    raise ValueError("dictionary doesn't specify a version")
ValueError: dictionary doesn't specify a version
2014-01-31 04:58:23 [15835] [INFO] Worker exiting (pid: 15835)
Traceback (most recent call last):
  File "/home/comunidad/django-node.js-nginx/website/manage.py", line 10, in <module>
    execute_from_command_line(sys.argv)
  File "/home/comunidad/local/lib/python2.7/site-packages/django/core/management/__init__.py", line 399, in execute_from_command_line
    utility.execute()
  File "/home/comunidad/local/lib/python2.7/site-packages/django/core/management/__init__.py", line 392, in execute
    self.fetch_command(subcommand).run_from_argv(self.argv)
  File "/home/comunidad/local/lib/python2.7/site-packages/django/core/management/base.py", line 242, in run_from_argv
    self.execute(*args, **options.__dict__)
  File "/home/comunidad/local/lib/python2.7/site-packages/django/core/management/base.py", line 285, in execute
    output = self.handle(*args, **options)
  File "/home/comunidad/local/lib/python2.7/site-packages/gunicorn/management/commands/run_gunicorn.py", line 101, in handle
    DjangoApplicationCommand(options, admin_media_path).run()
  File "/home/comunidad/local/lib/python2.7/site-packages/gunicorn/app/base.py", line 143, in run
    Arbiter(self).run()
  File "/home/comunidad/local/lib/python2.7/site-packages/gunicorn/arbiter.py", line 203, in run
    self.halt(reason=inst.reason, exit_status=inst.exit_status)
  File "/home/comunidad/local/lib/python2.7/site-packages/gunicorn/arbiter.py", line 298, in halt
    self.stop()
  File "/home/comunidad/local/lib/python2.7/site-packages/gunicorn/arbiter.py", line 341, in stop
    self.reap_workers()
  File "/home/comunidad/local/lib/python2.7/site-packages/gunicorn/arbiter.py", line 452, in reap_workers
    raise HaltServer(reason, self.WORKER_BOOT_ERROR)
gunicorn.errors.HaltServer: <HaltServer 'Worker failed to boot.' 3>
2014-01-31 04:58:25 [15837] [INFO] Starting gunicorn 18.0
2014-01-31 04:58:25 [15837] [INFO] Listening at: http://127.0.0.1:8008 (15837)
2014-01-31 04:58:25 [15837] [INFO] Using worker: sync
2014-01-31 04:58:25 [15842] [INFO] Booting worker with pid: 15842
2014-01-31 04:58:25 [15842] [ERROR] Exception in worker process:
Traceback (most recent call last):
  File "/home/comunidad/local/lib/python2.7/site-packages/gunicorn/arbiter.py", line 495, in spawn_worker
    worker.init_process()
  File "/home/comunidad/local/lib/python2.7/site-packages/gunicorn/workers/base.py", line 106, in init_process
    self.wsgi = self.app.wsgi()
  File "/home/comunidad/local/lib/python2.7/site-packages/gunicorn/app/base.py", line 114, in wsgi
    self.callable = self.load()
  File "/home/comunidad/local/lib/python2.7/site-packages/gunicorn/app/djangoapp.py", line 142, in load
    return mod.make_command_wsgi_application(self.admin_media_path)
  File "/home/comunidad/local/lib/python2.7/site-packages/gunicorn/app/django_wsgi.py", line 113, in make_command_wsgi_application
    reload_django_settings()
  File "/home/comunidad/local/lib/python2.7/site-packages/gunicorn/app/django_wsgi.py", line 109, in reload_django_settings
    logging_config_func(settings.LOGGING)
  File "/usr/lib/python2.7/logging/config.py", line 803, in dictConfig
    dictConfigClass(config).configure()
  File "/usr/lib/python2.7/logging/config.py", line 509, in configure
    raise ValueError("dictionary doesn't specify a version")
ValueError: dictionary doesn't specify a version
Traceback (most recent call last):
  File "/home/comunidad/local/lib/python2.7/site-packages/gunicorn/arbiter.py", line 495, in spawn_worker
    worker.init_process()
  File "/home/comunidad/local/lib/python2.7/site-packages/gunicorn/workers/base.py", line 106, in init_process
    self.wsgi = self.app.wsgi()
  File "/home/comunidad/local/lib/python2.7/site-packages/gunicorn/app/base.py", line 114, in wsgi
    self.callable = self.load()
  File "/home/comunidad/local/lib/python2.7/site-packages/gunicorn/app/djangoapp.py", line 142, in load
    return mod.make_command_wsgi_application(self.admin_media_path)
  File "/home/comunidad/local/lib/python2.7/site-packages/gunicorn/app/django_wsgi.py", line 113, in make_command_wsgi_application
    reload_django_settings()
  File "/home/comunidad/local/lib/python2.7/site-packages/gunicorn/app/django_wsgi.py", line 109, in reload_django_settings
    logging_config_func(settings.LOGGING)
  File "/usr/lib/python2.7/logging/config.py", line 803, in dictConfig
    dictConfigClass(config).configure()
  File "/usr/lib/python2.7/logging/config.py", line 509, in configure
    raise ValueError("dictionary doesn't specify a version")
ValueError: dictionary doesn't specify a version
2014-01-31 04:58:25 [15843] [INFO] Booting worker with pid: 15843
2014-01-31 04:58:25 [15842] [INFO] Worker exiting (pid: 15842)
2014-01-31 04:58:25 [15843] [ERROR] Exception in worker process:
Traceback (most recent call last):
  File "/home/comunidad/local/lib/python2.7/site-packages/gunicorn/arbiter.py", line 495, in spawn_worker
    worker.init_process()
  File "/home/comunidad/local/lib/python2.7/site-packages/gunicorn/workers/base.py", line 106, in init_process
    self.wsgi = self.app.wsgi()
  File "/home/comunidad/local/lib/python2.7/site-packages/gunicorn/app/base.py", line 114, in wsgi
    self.callable = self.load()
  File "/home/comunidad/local/lib/python2.7/site-packages/gunicorn/app/djangoapp.py", line 142, in load
    return mod.make_command_wsgi_application(self.admin_media_path)
  File "/home/comunidad/local/lib/python2.7/site-packages/gunicorn/app/django_wsgi.py", line 113, in make_command_wsgi_application
    reload_django_settings()
  File "/home/comunidad/local/lib/python2.7/site-packages/gunicorn/app/django_wsgi.py", line 109, in reload_django_settings
    logging_config_func(settings.LOGGING)
  File "/usr/lib/python2.7/logging/config.py", line 803, in dictConfig
    dictConfigClass(config).configure()
  File "/usr/lib/python2.7/logging/config.py", line 509, in configure
    raise ValueError("dictionary doesn't specify a version")
ValueError: dictionary doesn't specify a version
Traceback (most recent call last):
  File "/home/comunidad/local/lib/python2.7/site-packages/gunicorn/arbiter.py", line 495, in spawn_worker
    worker.init_process()
  File "/home/comunidad/local/lib/python2.7/site-packages/gunicorn/workers/base.py", line 106, in init_process
    self.wsgi = self.app.wsgi()
  File "/home/comunidad/local/lib/python2.7/site-packages/gunicorn/app/base.py", line 114, in wsgi
    self.callable = self.load()
  File "/home/comunidad/local/lib/python2.7/site-packages/gunicorn/app/djangoapp.py", line 142, in load
    return mod.make_command_wsgi_application(self.admin_media_path)
  File "/home/comunidad/local/lib/python2.7/site-packages/gunicorn/app/django_wsgi.py", line 113, in make_command_wsgi_application
    reload_django_settings()
  File "/home/comunidad/local/lib/python2.7/site-packages/gunicorn/app/django_wsgi.py", line 109, in reload_django_settings
    logging_config_func(settings.LOGGING)
  File "/usr/lib/python2.7/logging/config.py", line 803, in dictConfig
    dictConfigClass(config).configure()
  File "/usr/lib/python2.7/logging/config.py", line 509, in configure
    raise ValueError("dictionary doesn't specify a version")
ValueError: dictionary doesn't specify a version
2014-01-31 04:58:25 [15843] [INFO] Worker exiting (pid: 15843)
2014-01-31 04:58:25 [15844] [INFO] Booting worker with pid: 15844
2014-01-31 04:58:25 [15844] [ERROR] Exception in worker process:
Traceback (most recent call last):
  File "/home/comunidad/local/lib/python2.7/site-packages/gunicorn/arbiter.py", line 495, in spawn_worker
    worker.init_process()
  File "/home/comunidad/local/lib/python2.7/site-packages/gunicorn/workers/base.py", line 106, in init_process
    self.wsgi = self.app.wsgi()
  File "/home/comunidad/local/lib/python2.7/site-packages/gunicorn/app/base.py", line 114, in wsgi
    self.callable = self.load()
  File "/home/comunidad/local/lib/python2.7/site-packages/gunicorn/app/djangoapp.py", line 142, in load
    return mod.make_command_wsgi_application(self.admin_media_path)
  File "/home/comunidad/local/lib/python2.7/site-packages/gunicorn/app/django_wsgi.py", line 113, in make_command_wsgi_application
    reload_django_settings()
  File "/home/comunidad/local/lib/python2.7/site-packages/gunicorn/app/django_wsgi.py", line 109, in reload_django_settings
    logging_config_func(settings.LOGGING)
  File "/usr/lib/python2.7/logging/config.py", line 803, in dictConfig
    dictConfigClass(config).configure()
  File "/usr/lib/python2.7/logging/config.py", line 509, in configure
    raise ValueError("dictionary doesn't specify a version")
ValueError: dictionary doesn't specify a version
Traceback (most recent call last):
  File "/home/comunidad/local/lib/python2.7/site-packages/gunicorn/arbiter.py", line 495, in spawn_worker
    worker.init_process()
  File "/home/comunidad/local/lib/python2.7/site-packages/gunicorn/workers/base.py", line 106, in init_process
    self.wsgi = self.app.wsgi()
  File "/home/comunidad/local/lib/python2.7/site-packages/gunicorn/app/base.py", line 114, in wsgi
    self.callable = self.load()
  File "/home/comunidad/local/lib/python2.7/site-packages/gunicorn/app/djangoapp.py", line 142, in load
    return mod.make_command_wsgi_application(self.admin_media_path)
  File "/home/comunidad/local/lib/python2.7/site-packages/gunicorn/app/django_wsgi.py", line 113, in make_command_wsgi_application
    reload_django_settings()
  File "/home/comunidad/local/lib/python2.7/site-packages/gunicorn/app/django_wsgi.py", line 109, in reload_django_settings
    logging_config_func(settings.LOGGING)
  File "/usr/lib/python2.7/logging/config.py", line 803, in dictConfig
    dictConfigClass(config).configure()
  File "/usr/lib/python2.7/logging/config.py", line 509, in configure
    raise ValueError("dictionary doesn't specify a version")
ValueError: dictionary doesn't specify a version
2014-01-31 04:58:25 [15844] [INFO] Worker exiting (pid: 15844)
2014-01-31 04:58:25 [15845] [INFO] Booting worker with pid: 15845
2014-01-31 04:58:25 [15846] [INFO] Booting worker with pid: 15846
2014-01-31 04:58:25 [15846] [ERROR] Exception in worker process:
Traceback (most recent call last):
  File "/home/comunidad/local/lib/python2.7/site-packages/gunicorn/arbiter.py", line 495, in spawn_worker
    worker.init_process()
  File "/home/comunidad/local/lib/python2.7/site-packages/gunicorn/workers/base.py", line 106, in init_process
    self.wsgi = self.app.wsgi()
  File "/home/comunidad/local/lib/python2.7/site-packages/gunicorn/app/base.py", line 114, in wsgi
    self.callable = self.load()
  File "/home/comunidad/local/lib/python2.7/site-packages/gunicorn/app/djangoapp.py", line 142, in load
    return mod.make_command_wsgi_application(self.admin_media_path)
  File "/home/comunidad/local/lib/python2.7/site-packages/gunicorn/app/django_wsgi.py", line 113, in make_command_wsgi_application
    reload_django_settings()
  File "/home/comunidad/local/lib/python2.7/site-packages/gunicorn/app/django_wsgi.py", line 109, in reload_django_settings
    logging_config_func(settings.LOGGING)
  File "/usr/lib/python2.7/logging/config.py", line 803, in dictConfig
    dictConfigClass(config).configure()
  File "/usr/lib/python2.7/logging/config.py", line 509, in configure
    raise ValueError("dictionary doesn't specify a version")
ValueError: dictionary doesn't specify a version
Traceback (most recent call last):
  File "/home/comunidad/local/lib/python2.7/site-packages/gunicorn/arbiter.py", line 495, in spawn_worker
    worker.init_process()
  File "/home/comunidad/local/lib/python2.7/site-packages/gunicorn/workers/base.py", line 106, in init_process
    self.wsgi = self.app.wsgi()
  File "/home/comunidad/local/lib/python2.7/site-packages/gunicorn/app/base.py", line 114, in wsgi
    self.callable = self.load()
  File "/home/comunidad/local/lib/python2.7/site-packages/gunicorn/app/djangoapp.py", line 142, in load
    return mod.make_command_wsgi_application(self.admin_media_path)
  File "/home/comunidad/local/lib/python2.7/site-packages/gunicorn/app/django_wsgi.py", line 113, in make_command_wsgi_application
    reload_django_settings()
  File "/home/comunidad/local/lib/python2.7/site-packages/gunicorn/app/django_wsgi.py", line 109, in reload_django_settings
    logging_config_func(settings.LOGGING)
  File "/usr/lib/python2.7/logging/config.py", line 803, in dictConfig
    dictConfigClass(config).configure()
  File "/usr/lib/python2.7/logging/config.py", line 509, in configure
    raise ValueError("dictionary doesn't specify a version")
ValueError: dictionary doesn't specify a version
2014-01-31 04:58:25 [15846] [INFO] Worker exiting (pid: 15846)
2014-01-31 04:58:25 [15845] [ERROR] Exception in worker process:
Traceback (most recent call last):
  File "/home/comunidad/local/lib/python2.7/site-packages/gunicorn/arbiter.py", line 495, in spawn_worker
    worker.init_process()
  File "/home/comunidad/local/lib/python2.7/site-packages/gunicorn/workers/base.py", line 106, in init_process
    self.wsgi = self.app.wsgi()
  File "/home/comunidad/local/lib/python2.7/site-packages/gunicorn/app/base.py", line 114, in wsgi
    self.callable = self.load()
  File "/home/comunidad/local/lib/python2.7/site-packages/gunicorn/app/djangoapp.py", line 142, in load
    return mod.make_command_wsgi_application(self.admin_media_path)
  File "/home/comunidad/local/lib/python2.7/site-packages/gunicorn/app/django_wsgi.py", line 113, in make_command_wsgi_application
    reload_django_settings()
  File "/home/comunidad/local/lib/python2.7/site-packages/gunicorn/app/django_wsgi.py", line 109, in reload_django_settings
    logging_config_func(settings.LOGGING)
  File "/usr/lib/python2.7/logging/config.py", line 803, in dictConfig
    dictConfigClass(config).configure()
  File "/usr/lib/python2.7/logging/config.py", line 509, in configure
    raise ValueError("dictionary doesn't specify a version")
ValueError: dictionary doesn't specify a version
Traceback (most recent call last):
  File "/home/comunidad/local/lib/python2.7/site-packages/gunicorn/arbiter.py", line 495, in spawn_worker
    worker.init_process()
  File "/home/comunidad/local/lib/python2.7/site-packages/gunicorn/workers/base.py", line 106, in init_process
    self.wsgi = self.app.wsgi()
  File "/home/comunidad/local/lib/python2.7/site-packages/gunicorn/app/base.py", line 114, in wsgi
    self.callable = self.load()
  File "/home/comunidad/local/lib/python2.7/site-packages/gunicorn/app/djangoapp.py", line 142, in load
    return mod.make_command_wsgi_application(self.admin_media_path)
  File "/home/comunidad/local/lib/python2.7/site-packages/gunicorn/app/django_wsgi.py", line 113, in make_command_wsgi_application
    reload_django_settings()
  File "/home/comunidad/local/lib/python2.7/site-packages/gunicorn/app/django_wsgi.py", line 109, in reload_django_settings
    logging_config_func(settings.LOGGING)
  File "/usr/lib/python2.7/logging/config.py", line 803, in dictConfig
    dictConfigClass(config).configure()
  File "/usr/lib/python2.7/logging/config.py", line 509, in configure
    raise ValueError("dictionary doesn't specify a version")
ValueError: dictionary doesn't specify a version
2014-01-31 04:58:25 [15845] [INFO] Worker exiting (pid: 15845)
2014-01-31 04:58:25 [15847] [INFO] Booting worker with pid: 15847
2014-01-31 04:58:25 [15847] [ERROR] Exception in worker process:
Traceback (most recent call last):
  File "/home/comunidad/local/lib/python2.7/site-packages/gunicorn/arbiter.py", line 495, in spawn_worker
    worker.init_process()
  File "/home/comunidad/local/lib/python2.7/site-packages/gunicorn/workers/base.py", line 106, in init_process
    self.wsgi = self.app.wsgi()
  File "/home/comunidad/local/lib/python2.7/site-packages/gunicorn/app/base.py", line 114, in wsgi
    self.callable = self.load()
  File "/home/comunidad/local/lib/python2.7/site-packages/gunicorn/app/djangoapp.py", line 142, in load
    return mod.make_command_wsgi_application(self.admin_media_path)
  File "/home/comunidad/local/lib/python2.7/site-packages/gunicorn/app/django_wsgi.py", line 113, in make_command_wsgi_application
    reload_django_settings()
  File "/home/comunidad/local/lib/python2.7/site-packages/gunicorn/app/django_wsgi.py", line 109, in reload_django_settings
    logging_config_func(settings.LOGGING)
  File "/usr/lib/python2.7/logging/config.py", line 803, in dictConfig
    dictConfigClass(config).configure()
  File "/usr/lib/python2.7/logging/config.py", line 509, in configure
    raise ValueError("dictionary doesn't specify a version")
ValueError: dictionary doesn't specify a version
Traceback (most recent call last):
  File "/home/comunidad/local/lib/python2.7/site-packages/gunicorn/arbiter.py", line 495, in spawn_worker
    worker.init_process()
  File "/home/comunidad/local/lib/python2.7/site-packages/gunicorn/workers/base.py", line 106, in init_process
    self.wsgi = self.app.wsgi()
  File "/home/comunidad/local/lib/python2.7/site-packages/gunicorn/app/base.py", line 114, in wsgi
    self.callable = self.load()
  File "/home/comunidad/local/lib/python2.7/site-packages/gunicorn/app/djangoapp.py", line 142, in load
    return mod.make_command_wsgi_application(self.admin_media_path)
  File "/home/comunidad/local/lib/python2.7/site-packages/gunicorn/app/django_wsgi.py", line 113, in make_command_wsgi_application
    reload_django_settings()
  File "/home/comunidad/local/lib/python2.7/site-packages/gunicorn/app/django_wsgi.py", line 109, in reload_django_settings
    logging_config_func(settings.LOGGING)
  File "/usr/lib/python2.7/logging/config.py", line 803, in dictConfig
    dictConfigClass(config).configure()
  File "/usr/lib/python2.7/logging/config.py", line 509, in configure
    raise ValueError("dictionary doesn't specify a version")
ValueError: dictionary doesn't specify a version
2014-01-31 04:58:25 [15847] [INFO] Worker exiting (pid: 15847)
2014-01-31 04:58:25 [15848] [INFO] Booting worker with pid: 15848
2014-01-31 04:58:25 [15848] [ERROR] Exception in worker process:
Traceback (most recent call last):
  File "/home/comunidad/local/lib/python2.7/site-packages/gunicorn/arbiter.py", line 495, in spawn_worker
    worker.init_process()
  File "/home/comunidad/local/lib/python2.7/site-packages/gunicorn/workers/base.py", line 106, in init_process
    self.wsgi = self.app.wsgi()
  File "/home/comunidad/local/lib/python2.7/site-packages/gunicorn/app/base.py", line 114, in wsgi
    self.callable = self.load()
  File "/home/comunidad/local/lib/python2.7/site-packages/gunicorn/app/djangoapp.py", line 142, in load
    return mod.make_command_wsgi_application(self.admin_media_path)
  File "/home/comunidad/local/lib/python2.7/site-packages/gunicorn/app/django_wsgi.py", line 113, in make_command_wsgi_application
    reload_django_settings()
  File "/home/comunidad/local/lib/python2.7/site-packages/gunicorn/app/django_wsgi.py", line 109, in reload_django_settings
    logging_config_func(settings.LOGGING)
  File "/usr/lib/python2.7/logging/config.py", line 803, in dictConfig
    dictConfigClass(config).configure()
  File "/usr/lib/python2.7/logging/config.py", line 509, in configure
    raise ValueError("dictionary doesn't specify a version")
ValueError: dictionary doesn't specify a version
Traceback (most recent call last):
  File "/home/comunidad/local/lib/python2.7/site-packages/gunicorn/arbiter.py", line 495, in spawn_worker
    worker.init_process()
  File "/home/comunidad/local/lib/python2.7/site-packages/gunicorn/workers/base.py", line 106, in init_process
    self.wsgi = self.app.wsgi()
  File "/home/comunidad/local/lib/python2.7/site-packages/gunicorn/app/base.py", line 114, in wsgi
    self.callable = self.load()
  File "/home/comunidad/local/lib/python2.7/site-packages/gunicorn/app/djangoapp.py", line 142, in load
    return mod.make_command_wsgi_application(self.admin_media_path)
  File "/home/comunidad/local/lib/python2.7/site-packages/gunicorn/app/django_wsgi.py", line 113, in make_command_wsgi_application
    reload_django_settings()
  File "/home/comunidad/local/lib/python2.7/site-packages/gunicorn/app/django_wsgi.py", line 109, in reload_django_settings
    logging_config_func(settings.LOGGING)
  File "/usr/lib/python2.7/logging/config.py", line 803, in dictConfig
    dictConfigClass(config).configure()
  File "/usr/lib/python2.7/logging/config.py", line 509, in configure
    raise ValueError("dictionary doesn't specify a version")
ValueError: dictionary doesn't specify a version
2014-01-31 04:58:25 [15848] [INFO] Worker exiting (pid: 15848)
2014-01-31 04:58:25 [15849] [INFO] Booting worker with pid: 15849
2014-01-31 04:58:25 [15849] [ERROR] Exception in worker process:
Traceback (most recent call last):
  File "/home/comunidad/local/lib/python2.7/site-packages/gunicorn/arbiter.py", line 495, in spawn_worker
    worker.init_process()
  File "/home/comunidad/local/lib/python2.7/site-packages/gunicorn/workers/base.py", line 106, in init_process
    self.wsgi = self.app.wsgi()
  File "/home/comunidad/local/lib/python2.7/site-packages/gunicorn/app/base.py", line 114, in wsgi
    self.callable = self.load()
  File "/home/comunidad/local/lib/python2.7/site-packages/gunicorn/app/djangoapp.py", line 142, in load
    return mod.make_command_wsgi_application(self.admin_media_path)
  File "/home/comunidad/local/lib/python2.7/site-packages/gunicorn/app/django_wsgi.py", line 113, in make_command_wsgi_application
    reload_django_settings()
  File "/home/comunidad/local/lib/python2.7/site-packages/gunicorn/app/django_wsgi.py", line 109, in reload_django_settings
    logging_config_func(settings.LOGGING)
  File "/usr/lib/python2.7/logging/config.py", line 803, in dictConfig
    dictConfigClass(config).configure()
  File "/usr/lib/python2.7/logging/config.py", line 509, in configure
    raise ValueError("dictionary doesn't specify a version")
ValueError: dictionary doesn't specify a version
Traceback (most recent call last):
  File "/home/comunidad/local/lib/python2.7/site-packages/gunicorn/arbiter.py", line 495, in spawn_worker
    worker.init_process()
  File "/home/comunidad/local/lib/python2.7/site-packages/gunicorn/workers/base.py", line 106, in init_process
    self.wsgi = self.app.wsgi()
  File "/home/comunidad/local/lib/python2.7/site-packages/gunicorn/app/base.py", line 114, in wsgi
    self.callable = self.load()
  File "/home/comunidad/local/lib/python2.7/site-packages/gunicorn/app/djangoapp.py", line 142, in load
    return mod.make_command_wsgi_application(self.admin_media_path)
  File "/home/comunidad/local/lib/python2.7/site-packages/gunicorn/app/django_wsgi.py", line 113, in make_command_wsgi_application
    reload_django_settings()
  File "/home/comunidad/local/lib/python2.7/site-packages/gunicorn/app/django_wsgi.py", line 109, in reload_django_settings
    logging_config_func(settings.LOGGING)
  File "/usr/lib/python2.7/logging/config.py", line 803, in dictConfig
    dictConfigClass(config).configure()
  File "/usr/lib/python2.7/logging/config.py", line 509, in configure
    raise ValueError("dictionary doesn't specify a version")
ValueError: dictionary doesn't specify a version
2014-01-31 04:58:25 [15849] [INFO] Worker exiting (pid: 15849)
Traceback (most recent call last):
  File "/home/comunidad/django-node.js-nginx/website/manage.py", line 10, in <module>
    execute_from_command_line(sys.argv)
  File "/home/comunidad/local/lib/python2.7/site-packages/django/core/management/__init__.py", line 399, in execute_from_command_line
    utility.execute()
  File "/home/comunidad/local/lib/python2.7/site-packages/django/core/management/__init__.py", line 392, in execute
    self.fetch_command(subcommand).run_from_argv(self.argv)
  File "/home/comunidad/local/lib/python2.7/site-packages/django/core/management/base.py", line 242, in run_from_argv
    self.execute(*args, **options.__dict__)
  File "/home/comunidad/local/lib/python2.7/site-packages/django/core/management/base.py", line 285, in execute
    output = self.handle(*args, **options)
  File "/home/comunidad/local/lib/python2.7/site-packages/gunicorn/management/commands/run_gunicorn.py", line 101, in handle
    DjangoApplicationCommand(options, admin_media_path).run()
  File "/home/comunidad/local/lib/python2.7/site-packages/gunicorn/app/base.py", line 143, in run
    Arbiter(self).run()
  File "/home/comunidad/local/lib/python2.7/site-packages/gunicorn/arbiter.py", line 203, in run
    self.halt(reason=inst.reason, exit_status=inst.exit_status)
  File "/home/comunidad/local/lib/python2.7/site-packages/gunicorn/arbiter.py", line 298, in halt
    self.stop()
  File "/home/comunidad/local/lib/python2.7/site-packages/gunicorn/arbiter.py", line 341, in stop
    self.reap_workers()
  File "/home/comunidad/local/lib/python2.7/site-packages/gunicorn/arbiter.py", line 452, in reap_workers
    raise HaltServer(reason, self.WORKER_BOOT_ERROR)
gunicorn.errors.HaltServer: <HaltServer 'Worker failed to boot.' 3>
2014-01-31 04:58:29 [15852] [INFO] Starting gunicorn 18.0
2014-01-31 04:58:29 [15852] [INFO] Listening at: http://127.0.0.1:8008 (15852)
2014-01-31 04:58:29 [15852] [INFO] Using worker: sync
2014-01-31 04:58:29 [15857] [INFO] Booting worker with pid: 15857
2014-01-31 04:58:29 [15857] [ERROR] Exception in worker process:
Traceback (most recent call last):
  File "/home/comunidad/local/lib/python2.7/site-packages/gunicorn/arbiter.py", line 495, in spawn_worker
    worker.init_process()
  File "/home/comunidad/local/lib/python2.7/site-packages/gunicorn/workers/base.py", line 106, in init_process
    self.wsgi = self.app.wsgi()
  File "/home/comunidad/local/lib/python2.7/site-packages/gunicorn/app/base.py", line 114, in wsgi
    self.callable = self.load()
  File "/home/comunidad/local/lib/python2.7/site-packages/gunicorn/app/djangoapp.py", line 142, in load
    return mod.make_command_wsgi_application(self.admin_media_path)
  File "/home/comunidad/local/lib/python2.7/site-packages/gunicorn/app/django_wsgi.py", line 113, in make_command_wsgi_application
    reload_django_settings()
  File "/home/comunidad/local/lib/python2.7/site-packages/gunicorn/app/django_wsgi.py", line 109, in reload_django_settings
    logging_config_func(settings.LOGGING)
  File "/usr/lib/python2.7/logging/config.py", line 803, in dictConfig
    dictConfigClass(config).configure()
  File "/usr/lib/python2.7/logging/config.py", line 509, in configure
    raise ValueError("dictionary doesn't specify a version")
ValueError: dictionary doesn't specify a version
Traceback (most recent call last):
  File "/home/comunidad/local/lib/python2.7/site-packages/gunicorn/arbiter.py", line 495, in spawn_worker
    worker.init_process()
  File "/home/comunidad/local/lib/python2.7/site-packages/gunicorn/workers/base.py", line 106, in init_process
    self.wsgi = self.app.wsgi()
  File "/home/comunidad/local/lib/python2.7/site-packages/gunicorn/app/base.py", line 114, in wsgi
    self.callable = self.load()
  File "/home/comunidad/local/lib/python2.7/site-packages/gunicorn/app/djangoapp.py", line 142, in load
    return mod.make_command_wsgi_application(self.admin_media_path)
  File "/home/comunidad/local/lib/python2.7/site-packages/gunicorn/app/django_wsgi.py", line 113, in make_command_wsgi_application
    reload_django_settings()
  File "/home/comunidad/local/lib/python2.7/site-packages/gunicorn/app/django_wsgi.py", line 109, in reload_django_settings
    logging_config_func(settings.LOGGING)
  File "/usr/lib/python2.7/logging/config.py", line 803, in dictConfig
    dictConfigClass(config).configure()
  File "/usr/lib/python2.7/logging/config.py", line 509, in configure
    raise ValueError("dictionary doesn't specify a version")
ValueError: dictionary doesn't specify a version
2014-01-31 04:58:29 [15857] [INFO] Worker exiting (pid: 15857)
2014-01-31 04:58:29 [15859] [INFO] Booting worker with pid: 15859
2014-01-31 04:58:29 [15859] [ERROR] Exception in worker process:
Traceback (most recent call last):
  File "/home/comunidad/local/lib/python2.7/site-packages/gunicorn/arbiter.py", line 495, in spawn_worker
    worker.init_process()
  File "/home/comunidad/local/lib/python2.7/site-packages/gunicorn/workers/base.py", line 106, in init_process
    self.wsgi = self.app.wsgi()
  File "/home/comunidad/local/lib/python2.7/site-packages/gunicorn/app/base.py", line 114, in wsgi
    self.callable = self.load()
  File "/home/comunidad/local/lib/python2.7/site-packages/gunicorn/app/djangoapp.py", line 142, in load
    return mod.make_command_wsgi_application(self.admin_media_path)
  File "/home/comunidad/local/lib/python2.7/site-packages/gunicorn/app/django_wsgi.py", line 113, in make_command_wsgi_application
    reload_django_settings()
  File "/home/comunidad/local/lib/python2.7/site-packages/gunicorn/app/django_wsgi.py", line 109, in reload_django_settings
    logging_config_func(settings.LOGGING)
  File "/usr/lib/python2.7/logging/config.py", line 803, in dictConfig
    dictConfigClass(config).configure()
  File "/usr/lib/python2.7/logging/config.py", line 509, in configure
    raise ValueError("dictionary doesn't specify a version")
ValueError: dictionary doesn't specify a version
Traceback (most recent call last):
  File "/home/comunidad/local/lib/python2.7/site-packages/gunicorn/arbiter.py", line 495, in spawn_worker
    worker.init_process()
  File "/home/comunidad/local/lib/python2.7/site-packages/gunicorn/workers/base.py", line 106, in init_process
    self.wsgi = self.app.wsgi()
  File "/home/comunidad/local/lib/python2.7/site-packages/gunicorn/app/base.py", line 114, in wsgi
    self.callable = self.load()
  File "/home/comunidad/local/lib/python2.7/site-packages/gunicorn/app/djangoapp.py", line 142, in load
    return mod.make_command_wsgi_application(self.admin_media_path)
  File "/home/comunidad/local/lib/python2.7/site-packages/gunicorn/app/django_wsgi.py", line 113, in make_command_wsgi_application
    reload_django_settings()
  File "/home/comunidad/local/lib/python2.7/site-packages/gunicorn/app/django_wsgi.py", line 109, in reload_django_settings
    logging_config_func(settings.LOGGING)
  File "/usr/lib/python2.7/logging/config.py", line 803, in dictConfig
    dictConfigClass(config).configure()
  File "/usr/lib/python2.7/logging/config.py", line 509, in configure
    raise ValueError("dictionary doesn't specify a version")
ValueError: dictionary doesn't specify a version
2014-01-31 04:58:29 [15859] [INFO] Worker exiting (pid: 15859)
2014-01-31 04:58:29 [15860] [INFO] Booting worker with pid: 15860
2014-01-31 04:58:29 [15860] [ERROR] Exception in worker process:
Traceback (most recent call last):
  File "/home/comunidad/local/lib/python2.7/site-packages/gunicorn/arbiter.py", line 495, in spawn_worker
    worker.init_process()
  File "/home/comunidad/local/lib/python2.7/site-packages/gunicorn/workers/base.py", line 106, in init_process
    self.wsgi = self.app.wsgi()
  File "/home/comunidad/local/lib/python2.7/site-packages/gunicorn/app/base.py", line 114, in wsgi
    self.callable = self.load()
  File "/home/comunidad/local/lib/python2.7/site-packages/gunicorn/app/djangoapp.py", line 142, in load
    return mod.make_command_wsgi_application(self.admin_media_path)
  File "/home/comunidad/local/lib/python2.7/site-packages/gunicorn/app/django_wsgi.py", line 113, in make_command_wsgi_application
    reload_django_settings()
  File "/home/comunidad/local/lib/python2.7/site-packages/gunicorn/app/django_wsgi.py", line 109, in reload_django_settings
    logging_config_func(settings.LOGGING)
  File "/usr/lib/python2.7/logging/config.py", line 803, in dictConfig
    dictConfigClass(config).configure()
  File "/usr/lib/python2.7/logging/config.py", line 509, in configure
    raise ValueError("dictionary doesn't specify a version")
ValueError: dictionary doesn't specify a version
Traceback (most recent call last):
  File "/home/comunidad/local/lib/python2.7/site-packages/gunicorn/arbiter.py", line 495, in spawn_worker
    worker.init_process()
  File "/home/comunidad/local/lib/python2.7/site-packages/gunicorn/workers/base.py", line 106, in init_process
    self.wsgi = self.app.wsgi()
  File "/home/comunidad/local/lib/python2.7/site-packages/gunicorn/app/base.py", line 114, in wsgi
    self.callable = self.load()
  File "/home/comunidad/local/lib/python2.7/site-packages/gunicorn/app/djangoapp.py", line 142, in load
    return mod.make_command_wsgi_application(self.admin_media_path)
  File "/home/comunidad/local/lib/python2.7/site-packages/gunicorn/app/django_wsgi.py", line 113, in make_command_wsgi_application
    reload_django_settings()
  File "/home/comunidad/local/lib/python2.7/site-packages/gunicorn/app/django_wsgi.py", line 109, in reload_django_settings
    logging_config_func(settings.LOGGING)
  File "/usr/lib/python2.7/logging/config.py", line 803, in dictConfig
    dictConfigClass(config).configure()
  File "/usr/lib/python2.7/logging/config.py", line 509, in configure
    raise ValueError("dictionary doesn't specify a version")
ValueError: dictionary doesn't specify a version
2014-01-31 04:58:29 [15860] [INFO] Worker exiting (pid: 15860)
2014-01-31 04:58:29 [15861] [INFO] Booting worker with pid: 15861
2014-01-31 04:58:29 [15861] [ERROR] Exception in worker process:
Traceback (most recent call last):
  File "/home/comunidad/local/lib/python2.7/site-packages/gunicorn/arbiter.py", line 495, in spawn_worker
    worker.init_process()
  File "/home/comunidad/local/lib/python2.7/site-packages/gunicorn/workers/base.py", line 106, in init_process
    self.wsgi = self.app.wsgi()
  File "/home/comunidad/local/lib/python2.7/site-packages/gunicorn/app/base.py", line 114, in wsgi
    self.callable = self.load()
  File "/home/comunidad/local/lib/python2.7/site-packages/gunicorn/app/djangoapp.py", line 142, in load
    return mod.make_command_wsgi_application(self.admin_media_path)
  File "/home/comunidad/local/lib/python2.7/site-packages/gunicorn/app/django_wsgi.py", line 113, in make_command_wsgi_application
    reload_django_settings()
  File "/home/comunidad/local/lib/python2.7/site-packages/gunicorn/app/django_wsgi.py", line 109, in reload_django_settings
    logging_config_func(settings.LOGGING)
  File "/usr/lib/python2.7/logging/config.py", line 803, in dictConfig
    dictConfigClass(config).configure()
  File "/usr/lib/python2.7/logging/config.py", line 509, in configure
    raise ValueError("dictionary doesn't specify a version")
ValueError: dictionary doesn't specify a version
Traceback (most recent call last):
  File "/home/comunidad/local/lib/python2.7/site-packages/gunicorn/arbiter.py", line 495, in spawn_worker
    worker.init_process()
  File "/home/comunidad/local/lib/python2.7/site-packages/gunicorn/workers/base.py", line 106, in init_process
    self.wsgi = self.app.wsgi()
  File "/home/comunidad/local/lib/python2.7/site-packages/gunicorn/app/base.py", line 114, in wsgi
    self.callable = self.load()
  File "/home/comunidad/local/lib/python2.7/site-packages/gunicorn/app/djangoapp.py", line 142, in load
    return mod.make_command_wsgi_application(self.admin_media_path)
  File "/home/comunidad/local/lib/python2.7/site-packages/gunicorn/app/django_wsgi.py", line 113, in make_command_wsgi_application
    reload_django_settings()
  File "/home/comunidad/local/lib/python2.7/site-packages/gunicorn/app/django_wsgi.py", line 109, in reload_django_settings
    logging_config_func(settings.LOGGING)
  File "/usr/lib/python2.7/logging/config.py", line 803, in dictConfig
    dictConfigClass(config).configure()
  File "/usr/lib/python2.7/logging/config.py", line 509, in configure
    raise ValueError("dictionary doesn't specify a version")
ValueError: dictionary doesn't specify a version
2014-01-31 04:58:29 [15861] [INFO] Worker exiting (pid: 15861)
2014-01-31 04:58:29 [15862] [INFO] Booting worker with pid: 15862
2014-01-31 04:58:29 [15862] [ERROR] Exception in worker process:
Traceback (most recent call last):
  File "/home/comunidad/local/lib/python2.7/site-packages/gunicorn/arbiter.py", line 495, in spawn_worker
    worker.init_process()
  File "/home/comunidad/local/lib/python2.7/site-packages/gunicorn/workers/base.py", line 106, in init_process
    self.wsgi = self.app.wsgi()
  File "/home/comunidad/local/lib/python2.7/site-packages/gunicorn/app/base.py", line 114, in wsgi
    self.callable = self.load()
  File "/home/comunidad/local/lib/python2.7/site-packages/gunicorn/app/djangoapp.py", line 142, in load
    return mod.make_command_wsgi_application(self.admin_media_path)
  File "/home/comunidad/local/lib/python2.7/site-packages/gunicorn/app/django_wsgi.py", line 113, in make_command_wsgi_application
    reload_django_settings()
  File "/home/comunidad/local/lib/python2.7/site-packages/gunicorn/app/django_wsgi.py", line 109, in reload_django_settings
    logging_config_func(settings.LOGGING)
  File "/usr/lib/python2.7/logging/config.py", line 803, in dictConfig
    dictConfigClass(config).configure()
  File "/usr/lib/python2.7/logging/config.py", line 509, in configure
    raise ValueError("dictionary doesn't specify a version")
ValueError: dictionary doesn't specify a version
Traceback (most recent call last):
  File "/home/comunidad/local/lib/python2.7/site-packages/gunicorn/arbiter.py", line 495, in spawn_worker
    worker.init_process()
  File "/home/comunidad/local/lib/python2.7/site-packages/gunicorn/workers/base.py", line 106, in init_process
    self.wsgi = self.app.wsgi()
  File "/home/comunidad/local/lib/python2.7/site-packages/gunicorn/app/base.py", line 114, in wsgi
    self.callable = self.load()
  File "/home/comunidad/local/lib/python2.7/site-packages/gunicorn/app/djangoapp.py", line 142, in load
    return mod.make_command_wsgi_application(self.admin_media_path)
  File "/home/comunidad/local/lib/python2.7/site-packages/gunicorn/app/django_wsgi.py", line 113, in make_command_wsgi_application
    reload_django_settings()
  File "/home/comunidad/local/lib/python2.7/site-packages/gunicorn/app/django_wsgi.py", line 109, in reload_django_settings
    logging_config_func(settings.LOGGING)
  File "/usr/lib/python2.7/logging/config.py", line 803, in dictConfig
    dictConfigClass(config).configure()
  File "/usr/lib/python2.7/logging/config.py", line 509, in configure
    raise ValueError("dictionary doesn't specify a version")
ValueError: dictionary doesn't specify a version
2014-01-31 04:58:29 [15862] [INFO] Worker exiting (pid: 15862)
2014-01-31 04:58:29 [15863] [INFO] Booting worker with pid: 15863
2014-01-31 04:58:29 [15863] [ERROR] Exception in worker process:
Traceback (most recent call last):
  File "/home/comunidad/local/lib/python2.7/site-packages/gunicorn/arbiter.py", line 495, in spawn_worker
    worker.init_process()
  File "/home/comunidad/local/lib/python2.7/site-packages/gunicorn/workers/base.py", line 106, in init_process
    self.wsgi = self.app.wsgi()
  File "/home/comunidad/local/lib/python2.7/site-packages/gunicorn/app/base.py", line 114, in wsgi
    self.callable = self.load()
  File "/home/comunidad/local/lib/python2.7/site-packages/gunicorn/app/djangoapp.py", line 142, in load
    return mod.make_command_wsgi_application(self.admin_media_path)
  File "/home/comunidad/local/lib/python2.7/site-packages/gunicorn/app/django_wsgi.py", line 113, in make_command_wsgi_application
    reload_django_settings()
  File "/home/comunidad/local/lib/python2.7/site-packages/gunicorn/app/django_wsgi.py", line 109, in reload_django_settings
    logging_config_func(settings.LOGGING)
  File "/usr/lib/python2.7/logging/config.py", line 803, in dictConfig
    dictConfigClass(config).configure()
  File "/usr/lib/python2.7/logging/config.py", line 509, in configure
    raise ValueError("dictionary doesn't specify a version")
ValueError: dictionary doesn't specify a version
Traceback (most recent call last):
  File "/home/comunidad/local/lib/python2.7/site-packages/gunicorn/arbiter.py", line 495, in spawn_worker
    worker.init_process()
  File "/home/comunidad/local/lib/python2.7/site-packages/gunicorn/workers/base.py", line 106, in init_process
    self.wsgi = self.app.wsgi()
  File "/home/comunidad/local/lib/python2.7/site-packages/gunicorn/app/base.py", line 114, in wsgi
    self.callable = self.load()
  File "/home/comunidad/local/lib/python2.7/site-packages/gunicorn/app/djangoapp.py", line 142, in load
    return mod.make_command_wsgi_application(self.admin_media_path)
  File "/home/comunidad/local/lib/python2.7/site-packages/gunicorn/app/django_wsgi.py", line 113, in make_command_wsgi_application
    reload_django_settings()
  File "/home/comunidad/local/lib/python2.7/site-packages/gunicorn/app/django_wsgi.py", line 109, in reload_django_settings
    logging_config_func(settings.LOGGING)
  File "/usr/lib/python2.7/logging/config.py", line 803, in dictConfig
    dictConfigClass(config).configure()
  File "/usr/lib/python2.7/logging/config.py", line 509, in configure
    raise ValueError("dictionary doesn't specify a version")
ValueError: dictionary doesn't specify a version
2014-01-31 04:58:29 [15863] [INFO] Worker exiting (pid: 15863)
2014-01-31 04:58:29 [15864] [INFO] Booting worker with pid: 15864
2014-01-31 04:58:29 [15864] [ERROR] Exception in worker process:
Traceback (most recent call last):
  File "/home/comunidad/local/lib/python2.7/site-packages/gunicorn/arbiter.py", line 495, in spawn_worker
    worker.init_process()
  File "/home/comunidad/local/lib/python2.7/site-packages/gunicorn/workers/base.py", line 106, in init_process
    self.wsgi = self.app.wsgi()
  File "/home/comunidad/local/lib/python2.7/site-packages/gunicorn/app/base.py", line 114, in wsgi
    self.callable = self.load()
  File "/home/comunidad/local/lib/python2.7/site-packages/gunicorn/app/djangoapp.py", line 142, in load
    return mod.make_command_wsgi_application(self.admin_media_path)
  File "/home/comunidad/local/lib/python2.7/site-packages/gunicorn/app/django_wsgi.py", line 113, in make_command_wsgi_application
    reload_django_settings()
  File "/home/comunidad/local/lib/python2.7/site-packages/gunicorn/app/django_wsgi.py", line 109, in reload_django_settings
    logging_config_func(settings.LOGGING)
  File "/usr/lib/python2.7/logging/config.py", line 803, in dictConfig
    dictConfigClass(config).configure()
  File "/usr/lib/python2.7/logging/config.py", line 509, in configure
    raise ValueError("dictionary doesn't specify a version")
ValueError: dictionary doesn't specify a version
Traceback (most recent call last):
  File "/home/comunidad/local/lib/python2.7/site-packages/gunicorn/arbiter.py", line 495, in spawn_worker
    worker.init_process()
  File "/home/comunidad/local/lib/python2.7/site-packages/gunicorn/workers/base.py", line 106, in init_process
    self.wsgi = self.app.wsgi()
  File "/home/comunidad/local/lib/python2.7/site-packages/gunicorn/app/base.py", line 114, in wsgi
    self.callable = self.load()
  File "/home/comunidad/local/lib/python2.7/site-packages/gunicorn/app/djangoapp.py", line 142, in load
    return mod.make_command_wsgi_application(self.admin_media_path)
  File "/home/comunidad/local/lib/python2.7/site-packages/gunicorn/app/django_wsgi.py", line 113, in make_command_wsgi_application
    reload_django_settings()
  File "/home/comunidad/local/lib/python2.7/site-packages/gunicorn/app/django_wsgi.py", line 109, in reload_django_settings
    logging_config_func(settings.LOGGING)
  File "/usr/lib/python2.7/logging/config.py", line 803, in dictConfig
    dictConfigClass(config).configure()
  File "/usr/lib/python2.7/logging/config.py", line 509, in configure
    raise ValueError("dictionary doesn't specify a version")
ValueError: dictionary doesn't specify a version
2014-01-31 04:58:29 [15864] [INFO] Worker exiting (pid: 15864)
2014-01-31 04:58:29 [15865] [INFO] Booting worker with pid: 15865
2014-01-31 04:58:29 [15865] [ERROR] Exception in worker process:
Traceback (most recent call last):
  File "/home/comunidad/local/lib/python2.7/site-packages/gunicorn/arbiter.py", line 495, in spawn_worker
    worker.init_process()
  File "/home/comunidad/local/lib/python2.7/site-packages/gunicorn/workers/base.py", line 106, in init_process
    self.wsgi = self.app.wsgi()
  File "/home/comunidad/local/lib/python2.7/site-packages/gunicorn/app/base.py", line 114, in wsgi
    self.callable = self.load()
  File "/home/comunidad/local/lib/python2.7/site-packages/gunicorn/app/djangoapp.py", line 142, in load
    return mod.make_command_wsgi_application(self.admin_media_path)
  File "/home/comunidad/local/lib/python2.7/site-packages/gunicorn/app/django_wsgi.py", line 113, in make_command_wsgi_application
    reload_django_settings()
  File "/home/comunidad/local/lib/python2.7/site-packages/gunicorn/app/django_wsgi.py", line 109, in reload_django_settings
    logging_config_func(settings.LOGGING)
  File "/usr/lib/python2.7/logging/config.py", line 803, in dictConfig
    dictConfigClass(config).configure()
  File "/usr/lib/python2.7/logging/config.py", line 509, in configure
    raise ValueError("dictionary doesn't specify a version")
ValueError: dictionary doesn't specify a version
Traceback (most recent call last):
  File "/home/comunidad/local/lib/python2.7/site-packages/gunicorn/arbiter.py", line 495, in spawn_worker
    worker.init_process()
  File "/home/comunidad/local/lib/python2.7/site-packages/gunicorn/workers/base.py", line 106, in init_process
    self.wsgi = self.app.wsgi()
  File "/home/comunidad/local/lib/python2.7/site-packages/gunicorn/app/base.py", line 114, in wsgi
    self.callable = self.load()
  File "/home/comunidad/local/lib/python2.7/site-packages/gunicorn/app/djangoapp.py", line 142, in load
    return mod.make_command_wsgi_application(self.admin_media_path)
  File "/home/comunidad/local/lib/python2.7/site-packages/gunicorn/app/django_wsgi.py", line 113, in make_command_wsgi_application
    reload_django_settings()
  File "/home/comunidad/local/lib/python2.7/site-packages/gunicorn/app/django_wsgi.py", line 109, in reload_django_settings
    logging_config_func(settings.LOGGING)
  File "/usr/lib/python2.7/logging/config.py", line 803, in dictConfig
    dictConfigClass(config).configure()
  File "/usr/lib/python2.7/logging/config.py", line 509, in configure
    raise ValueError("dictionary doesn't specify a version")
ValueError: dictionary doesn't specify a version
2014-01-31 04:58:29 [15865] [INFO] Worker exiting (pid: 15865)
Traceback (most recent call last):
  File "/home/comunidad/django-node.js-nginx/website/manage.py", line 10, in <module>
    execute_from_command_line(sys.argv)
  File "/home/comunidad/local/lib/python2.7/site-packages/django/core/management/__init__.py", line 399, in execute_from_command_line
    utility.execute()
  File "/home/comunidad/local/lib/python2.7/site-packages/django/core/management/__init__.py", line 392, in execute
    self.fetch_command(subcommand).run_from_argv(self.argv)
  File "/home/comunidad/local/lib/python2.7/site-packages/django/core/management/base.py", line 242, in run_from_argv
    self.execute(*args, **options.__dict__)
  File "/home/comunidad/local/lib/python2.7/site-packages/django/core/management/base.py", line 285, in execute
    output = self.handle(*args, **options)
  File "/home/comunidad/local/lib/python2.7/site-packages/gunicorn/management/commands/run_gunicorn.py", line 101, in handle
    DjangoApplicationCommand(options, admin_media_path).run()
  File "/home/comunidad/local/lib/python2.7/site-packages/gunicorn/app/base.py", line 143, in run
    Arbiter(self).run()
  File "/home/comunidad/local/lib/python2.7/site-packages/gunicorn/arbiter.py", line 203, in run
    self.halt(reason=inst.reason, exit_status=inst.exit_status)
  File "/home/comunidad/local/lib/python2.7/site-packages/gunicorn/arbiter.py", line 298, in halt
    self.stop()
  File "/home/comunidad/local/lib/python2.7/site-packages/gunicorn/arbiter.py", line 341, in stop
    self.reap_workers()
  File "/home/comunidad/local/lib/python2.7/site-packages/gunicorn/arbiter.py", line 452, in reap_workers
    raise HaltServer(reason, self.WORKER_BOOT_ERROR)
gunicorn.errors.HaltServer: <HaltServer 'Worker failed to boot.' 3>
2014-01-31 05:05:12 [15945] [INFO] Starting gunicorn 18.0
2014-01-31 05:05:12 [15945] [INFO] Listening at: http://127.0.0.1:8008 (15945)
2014-01-31 05:05:12 [15945] [INFO] Using worker: sync
2014-01-31 05:05:12 [15950] [INFO] Booting worker with pid: 15950
2014-01-31 05:05:12 [15951] [INFO] Booting worker with pid: 15951
2014-01-31 05:05:12 [15952] [INFO] Booting worker with pid: 15952
2014-01-31 05:05:12 [15953] [INFO] Booting worker with pid: 15953
2014-01-31 05:05:12 [15954] [INFO] Booting worker with pid: 15954
2014-01-31 05:05:12 [15955] [INFO] Booting worker with pid: 15955
2014-01-31 05:05:12 [15956] [INFO] Booting worker with pid: 15956
2014-01-31 05:05:12 [15957] [INFO] Booting worker with pid: 15957
2014-01-31 05:14:05 [15945] [INFO] Handling signal: term
2014-01-31 05:14:05 [15950] [INFO] Worker exiting (pid: 15950)
2014-01-31 05:14:05 [15952] [INFO] Worker exiting (pid: 15952)
2014-01-31 05:14:05 [15953] [INFO] Worker exiting (pid: 15953)
2014-01-31 05:14:05 [15957] [INFO] Worker exiting (pid: 15957)
2014-01-31 05:14:05 [15956] [INFO] Worker exiting (pid: 15956)
2014-01-31 05:14:05 [15955] [INFO] Worker exiting (pid: 15955)
2014-01-31 05:14:05 [15954] [INFO] Worker exiting (pid: 15954)
2014-01-31 05:14:05 [15951] [INFO] Worker exiting (pid: 15951)
2014-01-31 05:14:05 [15945] [INFO] Shutting down: Master
2014-01-31 05:14:06 [16008] [INFO] Starting gunicorn 18.0
2014-01-31 05:14:06 [16008] [INFO] Listening at: http://127.0.0.1:8008 (16008)
2014-01-31 05:14:06 [16008] [INFO] Using worker: sync
2014-01-31 05:14:06 [16015] [INFO] Booting worker with pid: 16015
2014-01-31 05:14:06 [16016] [INFO] Booting worker with pid: 16016
2014-01-31 05:23:39 [16008] [INFO] Handling signal: term
2014-01-31 05:23:39 [16015] [INFO] Worker exiting (pid: 16015)
2014-01-31 05:23:39 [16016] [INFO] Worker exiting (pid: 16016)
2014-01-31 05:23:39 [16008] [INFO] Shutting down: Master
2014-01-31 05:23:41 [16153] [INFO] Starting gunicorn 18.0
2014-01-31 05:23:41 [16153] [INFO] Listening at: http://127.0.0.1:8008 (16153)
2014-01-31 05:23:41 [16153] [INFO] Using worker: sync
2014-01-31 05:23:41 [16158] [INFO] Booting worker with pid: 16158
2014-01-31 05:23:41 [16159] [INFO] Booting worker with pid: 16159
2014-01-31 05:54:54 [16153] [INFO] Handling signal: term
2014-01-31 05:54:54 [16158] [INFO] Worker exiting (pid: 16158)
2014-01-31 05:54:54 [16159] [INFO] Worker exiting (pid: 16159)
2014-01-31 05:54:54 [16153] [INFO] Shutting down: Master
2014-01-31 05:54:55 [17020] [INFO] Starting gunicorn 18.0
2014-01-31 05:54:55 [17020] [INFO] Listening at: http://127.0.0.1:8001 (17020)
2014-01-31 05:54:55 [17020] [INFO] Using worker: sync
2014-01-31 05:54:55 [17025] [INFO] Booting worker with pid: 17025
2014-01-31 05:54:55 [17026] [INFO] Booting worker with pid: 17026
2014-01-31 06:45:40 [17020] [INFO] Handling signal: term
2014-01-31 06:45:40 [17026] [INFO] Worker exiting (pid: 17026)
2014-01-31 06:45:40 [17025] [INFO] Worker exiting (pid: 17025)
2014-01-31 06:45:40 [17020] [INFO] Shutting down: Master
2014-01-31 06:45:41 [18127] [INFO] Starting gunicorn 18.0
2014-01-31 06:45:41 [18127] [INFO] Listening at: http://127.0.0.1:8000 (18127)
2014-01-31 06:45:41 [18127] [INFO] Using worker: sync
2014-01-31 06:45:41 [18132] [INFO] Booting worker with pid: 18132
2014-01-31 06:45:41 [18133] [INFO] Booting worker with pid: 18133
2014-01-31 07:00:37 [18127] [INFO] Handling signal: term
2014-01-31 07:00:37 [18133] [INFO] Worker exiting (pid: 18133)
2014-01-31 07:00:37 [18132] [INFO] Worker exiting (pid: 18132)
2014-01-31 07:00:37 [18127] [INFO] Shutting down: Master
2014-01-31 13:51:55 [1451] [INFO] Starting gunicorn 18.0
2014-01-31 13:51:55 [1451] [INFO] Listening at: http://127.0.0.1:8000 (1451)
2014-01-31 13:51:55 [1451] [INFO] Using worker: sync
2014-01-31 13:51:55 [1736] [INFO] Booting worker with pid: 1736
2014-01-31 13:51:55 [1737] [INFO] Booting worker with pid: 1737
2014-01-31 15:07:50 [1451] [INFO] Handling signal: term
2014-01-31 15:07:50 [1737] [INFO] Worker exiting (pid: 1737)
2014-01-31 15:07:50 [1736] [INFO] Worker exiting (pid: 1736)
2014-01-31 15:07:50 [1451] [INFO] Shutting down: Master
2014-01-31 15:08:38 [1383] [INFO] Starting gunicorn 18.0
2014-01-31 15:08:38 [1383] [INFO] Listening at: http://127.0.0.1:8000 (1383)
2014-01-31 15:08:38 [1383] [INFO] Using worker: sync
2014-01-31 15:08:38 [1494] [INFO] Booting worker with pid: 1494
2014-01-31 15:08:38 [1495] [INFO] Booting worker with pid: 1495
2014-01-31 17:55:55 [1383] [INFO] Handling signal: term
2014-01-31 17:55:55 [1494] [INFO] Worker exiting (pid: 1494)
2014-01-31 17:55:55 [1495] [INFO] Worker exiting (pid: 1495)
2014-01-31 17:55:55 [1383] [INFO] Shutting down: Master
2014-01-31 20:06:43 [1510] [INFO] Starting gunicorn 18.0
2014-01-31 20:06:43 [1510] [INFO] Listening at: http://127.0.0.1:8000 (1510)
2014-01-31 20:06:43 [1510] [INFO] Using worker: sync
2014-01-31 20:06:43 [1622] [INFO] Booting worker with pid: 1622
2014-01-31 20:06:43 [1631] [INFO] Booting worker with pid: 1631
